Process A [NEW] (arrival time 0 ms) 5 CPU bursts
Process B [NEW] (arrival time 0 ms) 96 CPU bursts
Process C [NEW] (arrival time 0 ms) 22 CPU bursts
Process D [NEW] (arrival time 0 ms) 71 CPU bursts
Process E [NEW] (arrival time 0 ms) 8 CPU bursts
Process F [NEW] (arrival time 0 ms) 51 CPU bursts
Process G [NEW] (arrival time 0 ms) 41 CPU bursts
Process H [NEW] (arrival time 0 ms) 37 CPU bursts
time 0ms: Simulator started for FCFS [Q <empty>]
time 0ms: Process A arrived; added to ready queue [Q A]
time 2ms: Process A started using the CPU for 1ms burst [Q <empty>]
time 3ms: Process A completed a CPU burst; 4 bursts to go [Q <empty>]
time 3ms: Process A switching out of CPU; will block on I/O until time 6ms [Q <empty>]
time 6ms: Process A completed I/O; added to ready queue [Q A]
time 0ms: Process B arrived; added to ready queue [Q A B]
time 8ms: Process A started using the CPU for 1ms burst [Q B]
time 9ms: Process A completed a CPU burst; 3 bursts to go [Q B]
time 9ms: Process A switching out of CPU; will block on I/O until time 12ms [Q B]
time 0ms: Process C arrived; added to ready queue [Q B C]
time 12ms: Process A completed I/O; added to ready queue [Q C A]
time 13ms: Process B started using the CPU for 1ms burst [Q C A]
time 14ms: Process B completed a CPU burst; 95 bursts to go [Q C A]
time 14ms: Process B switching out of CPU; will block on I/O until time 17ms [Q C A]
time 0ms: Process D arrived; added to ready queue [Q C A D]
time 17ms: Process B completed I/O; added to ready queue [Q A D B]
time 18ms: Process C started using the CPU for 1ms burst [Q A D B]
time 19ms: Process C completed a CPU burst; 21 bursts to go [Q A D B]
time 19ms: Process C switching out of CPU; will block on I/O until time 22ms [Q A D B]
time 0ms: Process E arrived; added to ready queue [Q A D B E]
time 22ms: Process C completed I/O; added to ready queue [Q D B E C]
time 23ms: Process A started using the CPU for 1ms burst [Q D B E C]
time 24ms: Process A completed a CPU burst; 2 bursts to go [Q D B E C]
time 24ms: Process A switching out of CPU; will block on I/O until time 27ms [Q D B E C]
time 0ms: Process F arrived; added to ready queue [Q D B E C F]
time 27ms: Process A completed I/O; added to ready queue [Q B E C F A]
time 28ms: Process D started using the CPU for 1ms burst [Q B E C F A]
time 29ms: Process D completed a CPU burst; 70 bursts to go [Q B E C F A]
time 29ms: Process D switching out of CPU; will block on I/O until time 32ms [Q B E C F A]
time 0ms: Process G arrived; added to ready queue [Q B E C F A G]
time 32ms: Process D completed I/O; added to ready queue [Q E C F A G D]
time 33ms: Process B started using the CPU for 1ms burst [Q E C F A G D]
time 34ms: Process B completed a CPU burst; 94 bursts to go [Q E C F A G D]
time 34ms: Process B switching out of CPU; will block on I/O until time 37ms [Q E C F A G D]
time 0ms: Process H arrived; added to ready queue [Q E C F A G D H]
time 37ms: Process B completed I/O; added to ready queue [Q C F A G D H B]
time 38ms: Process E started using the CPU for 1ms burst [Q C F A G D H B]
time 39ms: Process E completed a CPU burst; 7 bursts to go [Q C F A G D H B]
time 39ms: Process E switching out of CPU; will block on I/O until time 42ms [Q C F A G D H B]
time 42ms: Process E completed I/O; added to ready queue [Q F A G D H B E]
time 43ms: Process C started using the CPU for 1ms burst [Q F A G D H B E]
time 44ms: Process C completed a CPU burst; 20 bursts to go [Q F A G D H B E]
time 44ms: Process C switching out of CPU; will block on I/O until time 47ms [Q F A G D H B E]
time 47ms: Process C completed I/O; added to ready queue [Q A G D H B E C]
time 48ms: Process F started using the CPU for 1ms burst [Q A G D H B E C]
time 49ms: Process F completed a CPU burst; 50 bursts to go [Q A G D H B E C]
time 49ms: Process F switching out of CPU; will block on I/O until time 52ms [Q A G D H B E C]
time 52ms: Process F completed I/O; added to ready queue [Q G D H B E C F]
time 53ms: Process A started using the CPU for 1ms burst [Q G D H B E C F]
time 54ms: Process A completed a CPU burst; 1 burst to go [Q G D H B E C F]
time 54ms: Process A switching out of CPU; will block on I/O until time 57ms [Q G D H B E C F]
time 57ms: Process A completed I/O; added to ready queue [Q D H B E C F A]
time 58ms: Process G started using the CPU for 1ms burst [Q D H B E C F A]
time 59ms: Process G completed a CPU burst; 40 bursts to go [Q D H B E C F A]
time 59ms: Process G switching out of CPU; will block on I/O until time 62ms [Q D H B E C F A]
time 62ms: Process G completed I/O; added to ready queue [Q H B E C F A G]
time 63ms: Process D started using the CPU for 1ms burst [Q H B E C F A G]
time 64ms: Process D completed a CPU burst; 69 bursts to go [Q H B E C F A G]
time 64ms: Process D switching out of CPU; will block on I/O until time 67ms [Q H B E C F A G]
time 67ms: Process D completed I/O; added to ready queue [Q B E C F A G D]
time 68ms: Process H started using the CPU for 1ms burst [Q B E C F A G D]
time 69ms: Process H completed a CPU burst; 36 bursts to go [Q B E C F A G D]
time 69ms: Process H switching out of CPU; will block on I/O until time 72ms [Q B E C F A G D]
time 72ms: Process H completed I/O; added to ready queue [Q E C F A G D H]
time 73ms: Process B started using the CPU for 1ms burst [Q E C F A G D H]
time 74ms: Process B completed a CPU burst; 93 bursts to go [Q E C F A G D H]
time 74ms: Process B switching out of CPU; will block on I/O until time 77ms [Q E C F A G D H]
time 77ms: Process B completed I/O; added to ready queue [Q C F A G D H B]
time 78ms: Process E started using the CPU for 1ms burst [Q C F A G D H B]
time 79ms: Process E completed a CPU burst; 6 bursts to go [Q C F A G D H B]
time 79ms: Process E switching out of CPU; will block on I/O until time 82ms [Q C F A G D H B]
time 82ms: Process E completed I/O; added to ready queue [Q F A G D H B E]
time 83ms: Process C started using the CPU for 1ms burst [Q F A G D H B E]
time 84ms: Process C completed a CPU burst; 19 bursts to go [Q F A G D H B E]
time 84ms: Process C switching out of CPU; will block on I/O until time 87ms [Q F A G D H B E]
time 87ms: Process C completed I/O; added to ready queue [Q A G D H B E C]
time 88ms: Process F started using the CPU for 1ms burst [Q A G D H B E C]
time 89ms: Process F completed a CPU burst; 49 bursts to go [Q A G D H B E C]
time 89ms: Process F switching out of CPU; will block on I/O until time 92ms [Q A G D H B E C]
time 92ms: Process F completed I/O; added to ready queue [Q G D H B E C F]
time 93ms: Process A started using the CPU for 1ms burst [Q G D H B E C F]
time 94ms: Process A terminated [Q G D H B E C F]
time 98ms: Process G started using the CPU for 1ms burst [Q D H B E C F]
time 99ms: Process G completed a CPU burst; 39 bursts to go [Q D H B E C F]
time 99ms: Process G switching out of CPU; will block on I/O until time 102ms [Q D H B E C F]
time 102ms: Process G completed I/O; added to ready queue [Q H B E C F G]
time 103ms: Process D started using the CPU for 1ms burst [Q H B E C F G]
time 104ms: Process D completed a CPU burst; 68 bursts to go [Q H B E C F G]
time 104ms: Process D switching out of CPU; will block on I/O until time 107ms [Q H B E C F G]
time 107ms: Process D completed I/O; added to ready queue [Q B E C F G D]
time 108ms: Process H started using the CPU for 1ms burst [Q B E C F G D]
time 109ms: Process H completed a CPU burst; 35 bursts to go [Q B E C F G D]
time 109ms: Process H switching out of CPU; will block on I/O until time 112ms [Q B E C F G D]
time 112ms: Process H completed I/O; added to ready queue [Q E C F G D H]
time 113ms: Process B started using the CPU for 1ms burst [Q E C F G D H]
time 114ms: Process B completed a CPU burst; 92 bursts to go [Q E C F G D H]
time 114ms: Process B switching out of CPU; will block on I/O until time 117ms [Q E C F G D H]
time 117ms: Process B completed I/O; added to ready queue [Q C F G D H B]
time 118ms: Process E started using the CPU for 1ms burst [Q C F G D H B]
time 119ms: Process E completed a CPU burst; 5 bursts to go [Q C F G D H B]
time 119ms: Process E switching out of CPU; will block on I/O until time 122ms [Q C F G D H B]
time 122ms: Process E completed I/O; added to ready queue [Q F G D H B E]
time 123ms: Process C started using the CPU for 1ms burst [Q F G D H B E]
time 124ms: Process C completed a CPU burst; 18 bursts to go [Q F G D H B E]
time 124ms: Process C switching out of CPU; will block on I/O until time 127ms [Q F G D H B E]
time 127ms: Process C completed I/O; added to ready queue [Q G D H B E C]
time 128ms: Process F started using the CPU for 1ms burst [Q G D H B E C]
time 129ms: Process F completed a CPU burst; 48 bursts to go [Q G D H B E C]
time 129ms: Process F switching out of CPU; will block on I/O until time 132ms [Q G D H B E C]
time 132ms: Process F completed I/O; added to ready queue [Q D H B E C F]
time 133ms: Process G started using the CPU for 1ms burst [Q D H B E C F]
time 134ms: Process G completed a CPU burst; 38 bursts to go [Q D H B E C F]
time 134ms: Process G switching out of CPU; will block on I/O until time 137ms [Q D H B E C F]
time 137ms: Process G completed I/O; added to ready queue [Q H B E C F G]
time 138ms: Process D started using the CPU for 1ms burst [Q H B E C F G]
time 139ms: Process D completed a CPU burst; 67 bursts to go [Q H B E C F G]
time 139ms: Process D switching out of CPU; will block on I/O until time 142ms [Q H B E C F G]
time 142ms: Process D completed I/O; added to ready queue [Q B E C F G D]
time 143ms: Process H started using the CPU for 1ms burst [Q B E C F G D]
time 144ms: Process H completed a CPU burst; 34 bursts to go [Q B E C F G D]
time 144ms: Process H switching out of CPU; will block on I/O until time 147ms [Q B E C F G D]
time 147ms: Process H completed I/O; added to ready queue [Q E C F G D H]
time 148ms: Process B started using the CPU for 1ms burst [Q E C F G D H]
time 149ms: Process B completed a CPU burst; 91 bursts to go [Q E C F G D H]
time 149ms: Process B switching out of CPU; will block on I/O until time 152ms [Q E C F G D H]
time 152ms: Process B completed I/O; added to ready queue [Q C F G D H B]
time 153ms: Process E started using the CPU for 1ms burst [Q C F G D H B]
time 154ms: Process E completed a CPU burst; 4 bursts to go [Q C F G D H B]
time 154ms: Process E switching out of CPU; will block on I/O until time 157ms [Q C F G D H B]
time 157ms: Process E completed I/O; added to ready queue [Q F G D H B E]
time 158ms: Process C started using the CPU for 1ms burst [Q F G D H B E]
time 159ms: Process C completed a CPU burst; 17 bursts to go [Q F G D H B E]
time 159ms: Process C switching out of CPU; will block on I/O until time 162ms [Q F G D H B E]
time 162ms: Process C completed I/O; added to ready queue [Q G D H B E C]
time 163ms: Process F started using the CPU for 1ms burst [Q G D H B E C]
time 164ms: Process F completed a CPU burst; 47 bursts to go [Q G D H B E C]
time 164ms: Process F switching out of CPU; will block on I/O until time 167ms [Q G D H B E C]
time 167ms: Process F completed I/O; added to ready queue [Q D H B E C F]
time 168ms: Process G started using the CPU for 1ms burst [Q D H B E C F]
time 169ms: Process G completed a CPU burst; 37 bursts to go [Q D H B E C F]
time 169ms: Process G switching out of CPU; will block on I/O until time 172ms [Q D H B E C F]
time 172ms: Process G completed I/O; added to ready queue [Q H B E C F G]
time 173ms: Process D started using the CPU for 1ms burst [Q H B E C F G]
time 174ms: Process D completed a CPU burst; 66 bursts to go [Q H B E C F G]
time 174ms: Process D switching out of CPU; will block on I/O until time 177ms [Q H B E C F G]
time 177ms: Process D completed I/O; added to ready queue [Q B E C F G D]
time 178ms: Process H started using the CPU for 1ms burst [Q B E C F G D]
time 179ms: Process H completed a CPU burst; 33 bursts to go [Q B E C F G D]
time 179ms: Process H switching out of CPU; will block on I/O until time 182ms [Q B E C F G D]
time 182ms: Process H completed I/O; added to ready queue [Q E C F G D H]
time 183ms: Process B started using the CPU for 1ms burst [Q E C F G D H]
time 184ms: Process B completed a CPU burst; 90 bursts to go [Q E C F G D H]
time 184ms: Process B switching out of CPU; will block on I/O until time 187ms [Q E C F G D H]
time 187ms: Process B completed I/O; added to ready queue [Q C F G D H B]
time 188ms: Process E started using the CPU for 1ms burst [Q C F G D H B]
time 189ms: Process E completed a CPU burst; 3 bursts to go [Q C F G D H B]
time 189ms: Process E switching out of CPU; will block on I/O until time 192ms [Q C F G D H B]
time 192ms: Process E completed I/O; added to ready queue [Q F G D H B E]
time 193ms: Process C started using the CPU for 1ms burst [Q F G D H B E]
time 194ms: Process C completed a CPU burst; 16 bursts to go [Q F G D H B E]
time 194ms: Process C switching out of CPU; will block on I/O until time 197ms [Q F G D H B E]
time 197ms: Process C completed I/O; added to ready queue [Q G D H B E C]
time 198ms: Process F started using the CPU for 1ms burst [Q G D H B E C]
time 199ms: Process F completed a CPU burst; 46 bursts to go [Q G D H B E C]
time 199ms: Process F switching out of CPU; will block on I/O until time 202ms [Q G D H B E C]
time 202ms: Process F completed I/O; added to ready queue [Q D H B E C F]
time 203ms: Process G started using the CPU for 1ms burst [Q D H B E C F]
time 204ms: Process G completed a CPU burst; 36 bursts to go [Q D H B E C F]
time 204ms: Process G switching out of CPU; will block on I/O until time 207ms [Q D H B E C F]
time 207ms: Process G completed I/O; added to ready queue [Q H B E C F G]
time 208ms: Process D started using the CPU for 1ms burst [Q H B E C F G]
time 209ms: Process D completed a CPU burst; 65 bursts to go [Q H B E C F G]
time 209ms: Process D switching out of CPU; will block on I/O until time 212ms [Q H B E C F G]
time 212ms: Process D completed I/O; added to ready queue [Q B E C F G D]
time 213ms: Process H started using the CPU for 1ms burst [Q B E C F G D]
time 214ms: Process H completed a CPU burst; 32 bursts to go [Q B E C F G D]
time 214ms: Process H switching out of CPU; will block on I/O until time 217ms [Q B E C F G D]
time 217ms: Process H completed I/O; added to ready queue [Q E C F G D H]
time 218ms: Process B started using the CPU for 1ms burst [Q E C F G D H]
time 219ms: Process B completed a CPU burst; 89 bursts to go [Q E C F G D H]
time 219ms: Process B switching out of CPU; will block on I/O until time 222ms [Q E C F G D H]
time 222ms: Process B completed I/O; added to ready queue [Q C F G D H B]
time 223ms: Process E started using the CPU for 1ms burst [Q C F G D H B]
time 224ms: Process E completed a CPU burst; 2 bursts to go [Q C F G D H B]
time 224ms: Process E switching out of CPU; will block on I/O until time 227ms [Q C F G D H B]
time 227ms: Process E completed I/O; added to ready queue [Q F G D H B E]
time 228ms: Process C started using the CPU for 1ms burst [Q F G D H B E]
time 229ms: Process C completed a CPU burst; 15 bursts to go [Q F G D H B E]
time 229ms: Process C switching out of CPU; will block on I/O until time 232ms [Q F G D H B E]
time 232ms: Process C completed I/O; added to ready queue [Q G D H B E C]
time 233ms: Process F started using the CPU for 1ms burst [Q G D H B E C]
time 234ms: Process F completed a CPU burst; 45 bursts to go [Q G D H B E C]
time 234ms: Process F switching out of CPU; will block on I/O until time 237ms [Q G D H B E C]
time 237ms: Process F completed I/O; added to ready queue [Q D H B E C F]
time 238ms: Process G started using the CPU for 1ms burst [Q D H B E C F]
time 239ms: Process G completed a CPU burst; 35 bursts to go [Q D H B E C F]
time 239ms: Process G switching out of CPU; will block on I/O until time 242ms [Q D H B E C F]
time 242ms: Process G completed I/O; added to ready queue [Q H B E C F G]
time 243ms: Process D started using the CPU for 1ms burst [Q H B E C F G]
time 244ms: Process D completed a CPU burst; 64 bursts to go [Q H B E C F G]
time 244ms: Process D switching out of CPU; will block on I/O until time 247ms [Q H B E C F G]
time 247ms: Process D completed I/O; added to ready queue [Q B E C F G D]
time 248ms: Process H started using the CPU for 1ms burst [Q B E C F G D]
time 249ms: Process H completed a CPU burst; 31 bursts to go [Q B E C F G D]
time 249ms: Process H switching out of CPU; will block on I/O until time 252ms [Q B E C F G D]
time 252ms: Process H completed I/O; added to ready queue [Q E C F G D H]
time 253ms: Process B started using the CPU for 1ms burst [Q E C F G D H]
time 254ms: Process B completed a CPU burst; 88 bursts to go [Q E C F G D H]
time 254ms: Process B switching out of CPU; will block on I/O until time 257ms [Q E C F G D H]
time 257ms: Process B completed I/O; added to ready queue [Q C F G D H B]
time 258ms: Process E started using the CPU for 1ms burst [Q C F G D H B]
time 259ms: Process E completed a CPU burst; 1 burst to go [Q C F G D H B]
time 259ms: Process E switching out of CPU; will block on I/O until time 262ms [Q C F G D H B]
time 262ms: Process E completed I/O; added to ready queue [Q F G D H B E]
time 263ms: Process C started using the CPU for 1ms burst [Q F G D H B E]
time 264ms: Process C completed a CPU burst; 14 bursts to go [Q F G D H B E]
time 264ms: Process C switching out of CPU; will block on I/O until time 267ms [Q F G D H B E]
time 267ms: Process C completed I/O; added to ready queue [Q G D H B E C]
time 268ms: Process F started using the CPU for 1ms burst [Q G D H B E C]
time 269ms: Process F completed a CPU burst; 44 bursts to go [Q G D H B E C]
time 269ms: Process F switching out of CPU; will block on I/O until time 272ms [Q G D H B E C]
time 272ms: Process F completed I/O; added to ready queue [Q D H B E C F]
time 273ms: Process G started using the CPU for 1ms burst [Q D H B E C F]
time 274ms: Process G completed a CPU burst; 34 bursts to go [Q D H B E C F]
time 274ms: Process G switching out of CPU; will block on I/O until time 277ms [Q D H B E C F]
time 277ms: Process G completed I/O; added to ready queue [Q H B E C F G]
time 278ms: Process D started using the CPU for 1ms burst [Q H B E C F G]
time 279ms: Process D completed a CPU burst; 63 bursts to go [Q H B E C F G]
time 279ms: Process D switching out of CPU; will block on I/O until time 282ms [Q H B E C F G]
time 282ms: Process D completed I/O; added to ready queue [Q B E C F G D]
time 283ms: Process H started using the CPU for 1ms burst [Q B E C F G D]
time 284ms: Process H completed a CPU burst; 30 bursts to go [Q B E C F G D]
time 284ms: Process H switching out of CPU; will block on I/O until time 287ms [Q B E C F G D]
time 287ms: Process H completed I/O; added to ready queue [Q E C F G D H]
time 288ms: Process B started using the CPU for 1ms burst [Q E C F G D H]
time 289ms: Process B completed a CPU burst; 87 bursts to go [Q E C F G D H]
time 289ms: Process B switching out of CPU; will block on I/O until time 292ms [Q E C F G D H]
time 292ms: Process B completed I/O; added to ready queue [Q C F G D H B]
time 293ms: Process E started using the CPU for 1ms burst [Q C F G D H B]
time 294ms: Process E terminated [Q C F G D H B]
time 298ms: Process C started using the CPU for 1ms burst [Q F G D H B]
time 299ms: Process C completed a CPU burst; 13 bursts to go [Q F G D H B]
time 299ms: Process C switching out of CPU; will block on I/O until time 302ms [Q F G D H B]
time 302ms: Process C completed I/O; added to ready queue [Q G D H B C]
time 303ms: Process F started using the CPU for 1ms burst [Q G D H B C]
time 304ms: Process F completed a CPU burst; 43 bursts to go [Q G D H B C]
time 304ms: Process F switching out of CPU; will block on I/O until time 307ms [Q G D H B C]
time 307ms: Process F completed I/O; added to ready queue [Q D H B C F]
time 308ms: Process G started using the CPU for 1ms burst [Q D H B C F]
time 309ms: Process G completed a CPU burst; 33 bursts to go [Q D H B C F]
time 309ms: Process G switching out of CPU; will block on I/O until time 312ms [Q D H B C F]
time 312ms: Process G completed I/O; added to ready queue [Q H B C F G]
time 313ms: Process D started using the CPU for 1ms burst [Q H B C F G]
time 314ms: Process D completed a CPU burst; 62 bursts to go [Q H B C F G]
time 314ms: Process D switching out of CPU; will block on I/O until time 317ms [Q H B C F G]
time 317ms: Process D completed I/O; added to ready queue [Q B C F G D]
time 318ms: Process H started using the CPU for 1ms burst [Q B C F G D]
time 319ms: Process H completed a CPU burst; 29 bursts to go [Q B C F G D]
time 319ms: Process H switching out of CPU; will block on I/O until time 322ms [Q B C F G D]
time 322ms: Process H completed I/O; added to ready queue [Q C F G D H]
time 323ms: Process B started using the CPU for 1ms burst [Q C F G D H]
time 324ms: Process B completed a CPU burst; 86 bursts to go [Q C F G D H]
time 324ms: Process B switching out of CPU; will block on I/O until time 327ms [Q C F G D H]
time 327ms: Process B completed I/O; added to ready queue [Q F G D H B]
time 328ms: Process C started using the CPU for 1ms burst [Q F G D H B]
time 329ms: Process C completed a CPU burst; 12 bursts to go [Q F G D H B]
time 329ms: Process C switching out of CPU; will block on I/O until time 332ms [Q F G D H B]
time 332ms: Process C completed I/O; added to ready queue [Q G D H B C]
time 333ms: Process F started using the CPU for 1ms burst [Q G D H B C]
time 334ms: Process F completed a CPU burst; 42 bursts to go [Q G D H B C]
time 334ms: Process F switching out of CPU; will block on I/O until time 337ms [Q G D H B C]
time 337ms: Process F completed I/O; added to ready queue [Q D H B C F]
time 338ms: Process G started using the CPU for 1ms burst [Q D H B C F]
time 339ms: Process G completed a CPU burst; 32 bursts to go [Q D H B C F]
time 339ms: Process G switching out of CPU; will block on I/O until time 342ms [Q D H B C F]
time 342ms: Process G completed I/O; added to ready queue [Q H B C F G]
time 343ms: Process D started using the CPU for 1ms burst [Q H B C F G]
time 344ms: Process D completed a CPU burst; 61 bursts to go [Q H B C F G]
time 344ms: Process D switching out of CPU; will block on I/O until time 347ms [Q H B C F G]
time 347ms: Process D completed I/O; added to ready queue [Q B C F G D]
time 348ms: Process H started using the CPU for 1ms burst [Q B C F G D]
time 349ms: Process H completed a CPU burst; 28 bursts to go [Q B C F G D]
time 349ms: Process H switching out of CPU; will block on I/O until time 352ms [Q B C F G D]
time 352ms: Process H completed I/O; added to ready queue [Q C F G D H]
time 353ms: Process B started using the CPU for 1ms burst [Q C F G D H]
time 354ms: Process B completed a CPU burst; 85 bursts to go [Q C F G D H]
time 354ms: Process B switching out of CPU; will block on I/O until time 357ms [Q C F G D H]
time 357ms: Process B completed I/O; added to ready queue [Q F G D H B]
time 358ms: Process C started using the CPU for 1ms burst [Q F G D H B]
time 359ms: Process C completed a CPU burst; 11 bursts to go [Q F G D H B]
time 359ms: Process C switching out of CPU; will block on I/O until time 362ms [Q F G D H B]
time 362ms: Process C completed I/O; added to ready queue [Q G D H B C]
time 363ms: Process F started using the CPU for 1ms burst [Q G D H B C]
time 364ms: Process F completed a CPU burst; 41 bursts to go [Q G D H B C]
time 364ms: Process F switching out of CPU; will block on I/O until time 367ms [Q G D H B C]
time 367ms: Process F completed I/O; added to ready queue [Q D H B C F]
time 368ms: Process G started using the CPU for 1ms burst [Q D H B C F]
time 369ms: Process G completed a CPU burst; 31 bursts to go [Q D H B C F]
time 369ms: Process G switching out of CPU; will block on I/O until time 372ms [Q D H B C F]
time 372ms: Process G completed I/O; added to ready queue [Q H B C F G]
time 373ms: Process D started using the CPU for 1ms burst [Q H B C F G]
time 374ms: Process D completed a CPU burst; 60 bursts to go [Q H B C F G]
time 374ms: Process D switching out of CPU; will block on I/O until time 377ms [Q H B C F G]
time 377ms: Process D completed I/O; added to ready queue [Q B C F G D]
time 378ms: Process H started using the CPU for 1ms burst [Q B C F G D]
time 379ms: Process H completed a CPU burst; 27 bursts to go [Q B C F G D]
time 379ms: Process H switching out of CPU; will block on I/O until time 382ms [Q B C F G D]
time 382ms: Process H completed I/O; added to ready queue [Q C F G D H]
time 383ms: Process B started using the CPU for 1ms burst [Q C F G D H]
time 384ms: Process B completed a CPU burst; 84 bursts to go [Q C F G D H]
time 384ms: Process B switching out of CPU; will block on I/O until time 387ms [Q C F G D H]
time 387ms: Process B completed I/O; added to ready queue [Q F G D H B]
time 388ms: Process C started using the CPU for 1ms burst [Q F G D H B]
time 389ms: Process C completed a CPU burst; 10 bursts to go [Q F G D H B]
time 389ms: Process C switching out of CPU; will block on I/O until time 392ms [Q F G D H B]
time 392ms: Process C completed I/O; added to ready queue [Q G D H B C]
time 393ms: Process F started using the CPU for 1ms burst [Q G D H B C]
time 394ms: Process F completed a CPU burst; 40 bursts to go [Q G D H B C]
time 394ms: Process F switching out of CPU; will block on I/O until time 397ms [Q G D H B C]
time 397ms: Process F completed I/O; added to ready queue [Q D H B C F]
time 398ms: Process G started using the CPU for 1ms burst [Q D H B C F]
time 399ms: Process G completed a CPU burst; 30 bursts to go [Q D H B C F]
time 399ms: Process G switching out of CPU; will block on I/O until time 402ms [Q D H B C F]
time 402ms: Process G completed I/O; added to ready queue [Q H B C F G]
time 403ms: Process D started using the CPU for 1ms burst [Q H B C F G]
time 404ms: Process D completed a CPU burst; 59 bursts to go [Q H B C F G]
time 404ms: Process D switching out of CPU; will block on I/O until time 407ms [Q H B C F G]
time 407ms: Process D completed I/O; added to ready queue [Q B C F G D]
time 408ms: Process H started using the CPU for 1ms burst [Q B C F G D]
time 409ms: Process H completed a CPU burst; 26 bursts to go [Q B C F G D]
time 409ms: Process H switching out of CPU; will block on I/O until time 412ms [Q B C F G D]
time 412ms: Process H completed I/O; added to ready queue [Q C F G D H]
time 413ms: Process B started using the CPU for 1ms burst [Q C F G D H]
time 414ms: Process B completed a CPU burst; 83 bursts to go [Q C F G D H]
time 414ms: Process B switching out of CPU; will block on I/O until time 417ms [Q C F G D H]
time 417ms: Process B completed I/O; added to ready queue [Q F G D H B]
time 418ms: Process C started using the CPU for 1ms burst [Q F G D H B]
time 419ms: Process C completed a CPU burst; 9 bursts to go [Q F G D H B]
time 419ms: Process C switching out of CPU; will block on I/O until time 422ms [Q F G D H B]
time 422ms: Process C completed I/O; added to ready queue [Q G D H B C]
time 423ms: Process F started using the CPU for 1ms burst [Q G D H B C]
time 424ms: Process F completed a CPU burst; 39 bursts to go [Q G D H B C]
time 424ms: Process F switching out of CPU; will block on I/O until time 427ms [Q G D H B C]
time 427ms: Process F completed I/O; added to ready queue [Q D H B C F]
time 428ms: Process G started using the CPU for 1ms burst [Q D H B C F]
time 429ms: Process G completed a CPU burst; 29 bursts to go [Q D H B C F]
time 429ms: Process G switching out of CPU; will block on I/O until time 432ms [Q D H B C F]
time 432ms: Process G completed I/O; added to ready queue [Q H B C F G]
time 433ms: Process D started using the CPU for 1ms burst [Q H B C F G]
time 434ms: Process D completed a CPU burst; 58 bursts to go [Q H B C F G]
time 434ms: Process D switching out of CPU; will block on I/O until time 437ms [Q H B C F G]
time 437ms: Process D completed I/O; added to ready queue [Q B C F G D]
time 438ms: Process H started using the CPU for 1ms burst [Q B C F G D]
time 439ms: Process H completed a CPU burst; 25 bursts to go [Q B C F G D]
time 439ms: Process H switching out of CPU; will block on I/O until time 442ms [Q B C F G D]
time 442ms: Process H completed I/O; added to ready queue [Q C F G D H]
time 443ms: Process B started using the CPU for 1ms burst [Q C F G D H]
time 444ms: Process B completed a CPU burst; 82 bursts to go [Q C F G D H]
time 444ms: Process B switching out of CPU; will block on I/O until time 447ms [Q C F G D H]
time 447ms: Process B completed I/O; added to ready queue [Q F G D H B]
time 448ms: Process C started using the CPU for 1ms burst [Q F G D H B]
time 449ms: Process C completed a CPU burst; 8 bursts to go [Q F G D H B]
time 449ms: Process C switching out of CPU; will block on I/O until time 452ms [Q F G D H B]
time 452ms: Process C completed I/O; added to ready queue [Q G D H B C]
time 453ms: Process F started using the CPU for 1ms burst [Q G D H B C]
time 454ms: Process F completed a CPU burst; 38 bursts to go [Q G D H B C]
time 454ms: Process F switching out of CPU; will block on I/O until time 457ms [Q G D H B C]
time 457ms: Process F completed I/O; added to ready queue [Q D H B C F]
time 458ms: Process G started using the CPU for 1ms burst [Q D H B C F]
time 459ms: Process G completed a CPU burst; 28 bursts to go [Q D H B C F]
time 459ms: Process G switching out of CPU; will block on I/O until time 462ms [Q D H B C F]
time 462ms: Process G completed I/O; added to ready queue [Q H B C F G]
time 463ms: Process D started using the CPU for 1ms burst [Q H B C F G]
time 464ms: Process D completed a CPU burst; 57 bursts to go [Q H B C F G]
time 464ms: Process D switching out of CPU; will block on I/O until time 467ms [Q H B C F G]
time 467ms: Process D completed I/O; added to ready queue [Q B C F G D]
time 468ms: Process H started using the CPU for 1ms burst [Q B C F G D]
time 469ms: Process H completed a CPU burst; 24 bursts to go [Q B C F G D]
time 469ms: Process H switching out of CPU; will block on I/O until time 472ms [Q B C F G D]
time 472ms: Process H completed I/O; added to ready queue [Q C F G D H]
time 473ms: Process B started using the CPU for 1ms burst [Q C F G D H]
time 474ms: Process B completed a CPU burst; 81 bursts to go [Q C F G D H]
time 474ms: Process B switching out of CPU; will block on I/O until time 477ms [Q C F G D H]
time 477ms: Process B completed I/O; added to ready queue [Q F G D H B]
time 478ms: Process C started using the CPU for 1ms burst [Q F G D H B]
time 479ms: Process C completed a CPU burst; 7 bursts to go [Q F G D H B]
time 479ms: Process C switching out of CPU; will block on I/O until time 482ms [Q F G D H B]
time 482ms: Process C completed I/O; added to ready queue [Q G D H B C]
time 483ms: Process F started using the CPU for 1ms burst [Q G D H B C]
time 484ms: Process F completed a CPU burst; 37 bursts to go [Q G D H B C]
time 484ms: Process F switching out of CPU; will block on I/O until time 487ms [Q G D H B C]
time 487ms: Process F completed I/O; added to ready queue [Q D H B C F]
time 488ms: Process G started using the CPU for 1ms burst [Q D H B C F]
time 489ms: Process G completed a CPU burst; 27 bursts to go [Q D H B C F]
time 489ms: Process G switching out of CPU; will block on I/O until time 492ms [Q D H B C F]
time 492ms: Process G completed I/O; added to ready queue [Q H B C F G]
time 493ms: Process D started using the CPU for 1ms burst [Q H B C F G]
time 494ms: Process D completed a CPU burst; 56 bursts to go [Q H B C F G]
time 494ms: Process D switching out of CPU; will block on I/O until time 497ms [Q H B C F G]
time 497ms: Process D completed I/O; added to ready queue [Q B C F G D]
time 498ms: Process H started using the CPU for 1ms burst [Q B C F G D]
time 499ms: Process H completed a CPU burst; 23 bursts to go [Q B C F G D]
time 499ms: Process H switching out of CPU; will block on I/O until time 502ms [Q B C F G D]
time 502ms: Process H completed I/O; added to ready queue [Q C F G D H]
time 503ms: Process B started using the CPU for 1ms burst [Q C F G D H]
time 504ms: Process B completed a CPU burst; 80 bursts to go [Q C F G D H]
time 504ms: Process B switching out of CPU; will block on I/O until time 507ms [Q C F G D H]
time 507ms: Process B completed I/O; added to ready queue [Q F G D H B]
time 508ms: Process C started using the CPU for 1ms burst [Q F G D H B]
time 509ms: Process C completed a CPU burst; 6 bursts to go [Q F G D H B]
time 509ms: Process C switching out of CPU; will block on I/O until time 512ms [Q F G D H B]
time 512ms: Process C completed I/O; added to ready queue [Q G D H B C]
time 513ms: Process F started using the CPU for 1ms burst [Q G D H B C]
time 514ms: Process F completed a CPU burst; 36 bursts to go [Q G D H B C]
time 514ms: Process F switching out of CPU; will block on I/O until time 517ms [Q G D H B C]
time 517ms: Process F completed I/O; added to ready queue [Q D H B C F]
time 518ms: Process G started using the CPU for 1ms burst [Q D H B C F]
time 519ms: Process G completed a CPU burst; 26 bursts to go [Q D H B C F]
time 519ms: Process G switching out of CPU; will block on I/O until time 522ms [Q D H B C F]
time 522ms: Process G completed I/O; added to ready queue [Q H B C F G]
time 523ms: Process D started using the CPU for 1ms burst [Q H B C F G]
time 524ms: Process D completed a CPU burst; 55 bursts to go [Q H B C F G]
time 524ms: Process D switching out of CPU; will block on I/O until time 527ms [Q H B C F G]
time 527ms: Process D completed I/O; added to ready queue [Q B C F G D]
time 528ms: Process H started using the CPU for 1ms burst [Q B C F G D]
time 529ms: Process H completed a CPU burst; 22 bursts to go [Q B C F G D]
time 529ms: Process H switching out of CPU; will block on I/O until time 532ms [Q B C F G D]
time 532ms: Process H completed I/O; added to ready queue [Q C F G D H]
time 533ms: Process B started using the CPU for 1ms burst [Q C F G D H]
time 534ms: Process B completed a CPU burst; 79 bursts to go [Q C F G D H]
time 534ms: Process B switching out of CPU; will block on I/O until time 537ms [Q C F G D H]
time 537ms: Process B completed I/O; added to ready queue [Q F G D H B]
time 538ms: Process C started using the CPU for 1ms burst [Q F G D H B]
time 539ms: Process C completed a CPU burst; 5 bursts to go [Q F G D H B]
time 539ms: Process C switching out of CPU; will block on I/O until time 542ms [Q F G D H B]
time 542ms: Process C completed I/O; added to ready queue [Q G D H B C]
time 543ms: Process F started using the CPU for 1ms burst [Q G D H B C]
time 544ms: Process F completed a CPU burst; 35 bursts to go [Q G D H B C]
time 544ms: Process F switching out of CPU; will block on I/O until time 547ms [Q G D H B C]
time 547ms: Process F completed I/O; added to ready queue [Q D H B C F]
time 548ms: Process G started using the CPU for 1ms burst [Q D H B C F]
time 549ms: Process G completed a CPU burst; 25 bursts to go [Q D H B C F]
time 549ms: Process G switching out of CPU; will block on I/O until time 552ms [Q D H B C F]
time 552ms: Process G completed I/O; added to ready queue [Q H B C F G]
time 553ms: Process D started using the CPU for 1ms burst [Q H B C F G]
time 554ms: Process D completed a CPU burst; 54 bursts to go [Q H B C F G]
time 554ms: Process D switching out of CPU; will block on I/O until time 557ms [Q H B C F G]
time 557ms: Process D completed I/O; added to ready queue [Q B C F G D]
time 558ms: Process H started using the CPU for 1ms burst [Q B C F G D]
time 559ms: Process H completed a CPU burst; 21 bursts to go [Q B C F G D]
time 559ms: Process H switching out of CPU; will block on I/O until time 562ms [Q B C F G D]
time 562ms: Process H completed I/O; added to ready queue [Q C F G D H]
time 563ms: Process B started using the CPU for 1ms burst [Q C F G D H]
time 564ms: Process B completed a CPU burst; 78 bursts to go [Q C F G D H]
time 564ms: Process B switching out of CPU; will block on I/O until time 567ms [Q C F G D H]
time 567ms: Process B completed I/O; added to ready queue [Q F G D H B]
time 568ms: Process C started using the CPU for 1ms burst [Q F G D H B]
time 569ms: Process C completed a CPU burst; 4 bursts to go [Q F G D H B]
time 569ms: Process C switching out of CPU; will block on I/O until time 572ms [Q F G D H B]
time 572ms: Process C completed I/O; added to ready queue [Q G D H B C]
time 573ms: Process F started using the CPU for 1ms burst [Q G D H B C]
time 574ms: Process F completed a CPU burst; 34 bursts to go [Q G D H B C]
time 574ms: Process F switching out of CPU; will block on I/O until time 577ms [Q G D H B C]
time 577ms: Process F completed I/O; added to ready queue [Q D H B C F]
time 578ms: Process G started using the CPU for 1ms burst [Q D H B C F]
time 579ms: Process G completed a CPU burst; 24 bursts to go [Q D H B C F]
time 579ms: Process G switching out of CPU; will block on I/O until time 582ms [Q D H B C F]
time 582ms: Process G completed I/O; added to ready queue [Q H B C F G]
time 583ms: Process D started using the CPU for 1ms burst [Q H B C F G]
time 584ms: Process D completed a CPU burst; 53 bursts to go [Q H B C F G]
time 584ms: Process D switching out of CPU; will block on I/O until time 587ms [Q H B C F G]
time 587ms: Process D completed I/O; added to ready queue [Q B C F G D]
time 588ms: Process H started using the CPU for 1ms burst [Q B C F G D]
time 589ms: Process H completed a CPU burst; 20 bursts to go [Q B C F G D]
time 589ms: Process H switching out of CPU; will block on I/O until time 592ms [Q B C F G D]
time 592ms: Process H completed I/O; added to ready queue [Q C F G D H]
time 593ms: Process B started using the CPU for 1ms burst [Q C F G D H]
time 594ms: Process B completed a CPU burst; 77 bursts to go [Q C F G D H]
time 594ms: Process B switching out of CPU; will block on I/O until time 597ms [Q C F G D H]
time 597ms: Process B completed I/O; added to ready queue [Q F G D H B]
time 598ms: Process C started using the CPU for 1ms burst [Q F G D H B]
time 599ms: Process C completed a CPU burst; 3 bursts to go [Q F G D H B]
time 599ms: Process C switching out of CPU; will block on I/O until time 602ms [Q F G D H B]
time 602ms: Process C completed I/O; added to ready queue [Q G D H B C]
time 603ms: Process F started using the CPU for 1ms burst [Q G D H B C]
time 604ms: Process F completed a CPU burst; 33 bursts to go [Q G D H B C]
time 604ms: Process F switching out of CPU; will block on I/O until time 607ms [Q G D H B C]
time 607ms: Process F completed I/O; added to ready queue [Q D H B C F]
time 608ms: Process G started using the CPU for 1ms burst [Q D H B C F]
time 609ms: Process G completed a CPU burst; 23 bursts to go [Q D H B C F]
time 609ms: Process G switching out of CPU; will block on I/O until time 612ms [Q D H B C F]
time 612ms: Process G completed I/O; added to ready queue [Q H B C F G]
time 613ms: Process D started using the CPU for 1ms burst [Q H B C F G]
time 614ms: Process D completed a CPU burst; 52 bursts to go [Q H B C F G]
time 614ms: Process D switching out of CPU; will block on I/O until time 617ms [Q H B C F G]
time 617ms: Process D completed I/O; added to ready queue [Q B C F G D]
time 618ms: Process H started using the CPU for 1ms burst [Q B C F G D]
time 619ms: Process H completed a CPU burst; 19 bursts to go [Q B C F G D]
time 619ms: Process H switching out of CPU; will block on I/O until time 622ms [Q B C F G D]
time 622ms: Process H completed I/O; added to ready queue [Q C F G D H]
time 623ms: Process B started using the CPU for 1ms burst [Q C F G D H]
time 624ms: Process B completed a CPU burst; 76 bursts to go [Q C F G D H]
time 624ms: Process B switching out of CPU; will block on I/O until time 627ms [Q C F G D H]
time 627ms: Process B completed I/O; added to ready queue [Q F G D H B]
time 628ms: Process C started using the CPU for 1ms burst [Q F G D H B]
time 629ms: Process C completed a CPU burst; 2 bursts to go [Q F G D H B]
time 629ms: Process C switching out of CPU; will block on I/O until time 632ms [Q F G D H B]
time 632ms: Process C completed I/O; added to ready queue [Q G D H B C]
time 633ms: Process F started using the CPU for 1ms burst [Q G D H B C]
time 634ms: Process F completed a CPU burst; 32 bursts to go [Q G D H B C]
time 634ms: Process F switching out of CPU; will block on I/O until time 637ms [Q G D H B C]
time 637ms: Process F completed I/O; added to ready queue [Q D H B C F]
time 638ms: Process G started using the CPU for 1ms burst [Q D H B C F]
time 639ms: Process G completed a CPU burst; 22 bursts to go [Q D H B C F]
time 639ms: Process G switching out of CPU; will block on I/O until time 642ms [Q D H B C F]
time 642ms: Process G completed I/O; added to ready queue [Q H B C F G]
time 643ms: Process D started using the CPU for 1ms burst [Q H B C F G]
time 644ms: Process D completed a CPU burst; 51 bursts to go [Q H B C F G]
time 644ms: Process D switching out of CPU; will block on I/O until time 647ms [Q H B C F G]
time 647ms: Process D completed I/O; added to ready queue [Q B C F G D]
time 648ms: Process H started using the CPU for 1ms burst [Q B C F G D]
time 649ms: Process H completed a CPU burst; 18 bursts to go [Q B C F G D]
time 649ms: Process H switching out of CPU; will block on I/O until time 652ms [Q B C F G D]
time 652ms: Process H completed I/O; added to ready queue [Q C F G D H]
time 653ms: Process B started using the CPU for 1ms burst [Q C F G D H]
time 654ms: Process B completed a CPU burst; 75 bursts to go [Q C F G D H]
time 654ms: Process B switching out of CPU; will block on I/O until time 657ms [Q C F G D H]
time 657ms: Process B completed I/O; added to ready queue [Q F G D H B]
time 658ms: Process C started using the CPU for 1ms burst [Q F G D H B]
time 659ms: Process C completed a CPU burst; 1 burst to go [Q F G D H B]
time 659ms: Process C switching out of CPU; will block on I/O until time 662ms [Q F G D H B]
time 662ms: Process C completed I/O; added to ready queue [Q G D H B C]
time 663ms: Process F started using the CPU for 1ms burst [Q G D H B C]
time 664ms: Process F completed a CPU burst; 31 bursts to go [Q G D H B C]
time 664ms: Process F switching out of CPU; will block on I/O until time 667ms [Q G D H B C]
time 667ms: Process F completed I/O; added to ready queue [Q D H B C F]
time 668ms: Process G started using the CPU for 1ms burst [Q D H B C F]
time 669ms: Process G completed a CPU burst; 21 bursts to go [Q D H B C F]
time 669ms: Process G switching out of CPU; will block on I/O until time 672ms [Q D H B C F]
time 672ms: Process G completed I/O; added to ready queue [Q H B C F G]
time 673ms: Process D started using the CPU for 1ms burst [Q H B C F G]
time 674ms: Process D completed a CPU burst; 50 bursts to go [Q H B C F G]
time 674ms: Process D switching out of CPU; will block on I/O until time 677ms [Q H B C F G]
time 677ms: Process D completed I/O; added to ready queue [Q B C F G D]
time 678ms: Process H started using the CPU for 1ms burst [Q B C F G D]
time 679ms: Process H completed a CPU burst; 17 bursts to go [Q B C F G D]
time 679ms: Process H switching out of CPU; will block on I/O until time 682ms [Q B C F G D]
time 682ms: Process H completed I/O; added to ready queue [Q C F G D H]
time 683ms: Process B started using the CPU for 1ms burst [Q C F G D H]
time 684ms: Process B completed a CPU burst; 74 bursts to go [Q C F G D H]
time 684ms: Process B switching out of CPU; will block on I/O until time 687ms [Q C F G D H]
time 687ms: Process B completed I/O; added to ready queue [Q F G D H B]
time 688ms: Process C started using the CPU for 1ms burst [Q F G D H B]
time 689ms: Process C terminated [Q F G D H B]
time 693ms: Process F started using the CPU for 1ms burst [Q G D H B]
time 694ms: Process F completed a CPU burst; 30 bursts to go [Q G D H B]
time 694ms: Process F switching out of CPU; will block on I/O until time 697ms [Q G D H B]
time 697ms: Process F completed I/O; added to ready queue [Q D H B F]
time 698ms: Process G started using the CPU for 1ms burst [Q D H B F]
time 699ms: Process G completed a CPU burst; 20 bursts to go [Q D H B F]
time 699ms: Process G switching out of CPU; will block on I/O until time 702ms [Q D H B F]
time 702ms: Process G completed I/O; added to ready queue [Q H B F G]
time 703ms: Process D started using the CPU for 1ms burst [Q H B F G]
time 704ms: Process D completed a CPU burst; 49 bursts to go [Q H B F G]
time 704ms: Process D switching out of CPU; will block on I/O until time 707ms [Q H B F G]
time 707ms: Process D completed I/O; added to ready queue [Q B F G D]
time 708ms: Process H started using the CPU for 1ms burst [Q B F G D]
time 709ms: Process H completed a CPU burst; 16 bursts to go [Q B F G D]
time 709ms: Process H switching out of CPU; will block on I/O until time 712ms [Q B F G D]
time 712ms: Process H completed I/O; added to ready queue [Q F G D H]
time 713ms: Process B started using the CPU for 1ms burst [Q F G D H]
time 714ms: Process B completed a CPU burst; 73 bursts to go [Q F G D H]
time 714ms: Process B switching out of CPU; will block on I/O until time 717ms [Q F G D H]
time 717ms: Process B completed I/O; added to ready queue [Q G D H B]
time 718ms: Process F started using the CPU for 1ms burst [Q G D H B]
time 719ms: Process F completed a CPU burst; 29 bursts to go [Q G D H B]
time 719ms: Process F switching out of CPU; will block on I/O until time 722ms [Q G D H B]
time 722ms: Process F completed I/O; added to ready queue [Q D H B F]
time 723ms: Process G started using the CPU for 1ms burst [Q D H B F]
time 724ms: Process G completed a CPU burst; 19 bursts to go [Q D H B F]
time 724ms: Process G switching out of CPU; will block on I/O until time 727ms [Q D H B F]
time 727ms: Process G completed I/O; added to ready queue [Q H B F G]
time 728ms: Process D started using the CPU for 1ms burst [Q H B F G]
time 729ms: Process D completed a CPU burst; 48 bursts to go [Q H B F G]
time 729ms: Process D switching out of CPU; will block on I/O until time 732ms [Q H B F G]
time 732ms: Process D completed I/O; added to ready queue [Q B F G D]
time 733ms: Process H started using the CPU for 1ms burst [Q B F G D]
time 734ms: Process H completed a CPU burst; 15 bursts to go [Q B F G D]
time 734ms: Process H switching out of CPU; will block on I/O until time 737ms [Q B F G D]
time 737ms: Process H completed I/O; added to ready queue [Q F G D H]
time 738ms: Process B started using the CPU for 1ms burst [Q F G D H]
time 739ms: Process B completed a CPU burst; 72 bursts to go [Q F G D H]
time 739ms: Process B switching out of CPU; will block on I/O until time 742ms [Q F G D H]
time 742ms: Process B completed I/O; added to ready queue [Q G D H B]
time 743ms: Process F started using the CPU for 1ms burst [Q G D H B]
time 744ms: Process F completed a CPU burst; 28 bursts to go [Q G D H B]
time 744ms: Process F switching out of CPU; will block on I/O until time 747ms [Q G D H B]
time 747ms: Process F completed I/O; added to ready queue [Q D H B F]
time 748ms: Process G started using the CPU for 1ms burst [Q D H B F]
time 749ms: Process G completed a CPU burst; 18 bursts to go [Q D H B F]
time 749ms: Process G switching out of CPU; will block on I/O until time 752ms [Q D H B F]
time 752ms: Process G completed I/O; added to ready queue [Q H B F G]
time 753ms: Process D started using the CPU for 1ms burst [Q H B F G]
time 754ms: Process D completed a CPU burst; 47 bursts to go [Q H B F G]
time 754ms: Process D switching out of CPU; will block on I/O until time 757ms [Q H B F G]
time 757ms: Process D completed I/O; added to ready queue [Q B F G D]
time 758ms: Process H started using the CPU for 1ms burst [Q B F G D]
time 759ms: Process H completed a CPU burst; 14 bursts to go [Q B F G D]
time 759ms: Process H switching out of CPU; will block on I/O until time 762ms [Q B F G D]
time 762ms: Process H completed I/O; added to ready queue [Q F G D H]
time 763ms: Process B started using the CPU for 1ms burst [Q F G D H]
time 764ms: Process B completed a CPU burst; 71 bursts to go [Q F G D H]
time 764ms: Process B switching out of CPU; will block on I/O until time 767ms [Q F G D H]
time 767ms: Process B completed I/O; added to ready queue [Q G D H B]
time 768ms: Process F started using the CPU for 1ms burst [Q G D H B]
time 769ms: Process F completed a CPU burst; 27 bursts to go [Q G D H B]
time 769ms: Process F switching out of CPU; will block on I/O until time 772ms [Q G D H B]
time 772ms: Process F completed I/O; added to ready queue [Q D H B F]
time 773ms: Process G started using the CPU for 1ms burst [Q D H B F]
time 774ms: Process G completed a CPU burst; 17 bursts to go [Q D H B F]
time 774ms: Process G switching out of CPU; will block on I/O until time 777ms [Q D H B F]
time 777ms: Process G completed I/O; added to ready queue [Q H B F G]
time 778ms: Process D started using the CPU for 1ms burst [Q H B F G]
time 779ms: Process D completed a CPU burst; 46 bursts to go [Q H B F G]
time 779ms: Process D switching out of CPU; will block on I/O until time 782ms [Q H B F G]
time 782ms: Process D completed I/O; added to ready queue [Q B F G D]
time 783ms: Process H started using the CPU for 1ms burst [Q B F G D]
time 784ms: Process H completed a CPU burst; 13 bursts to go [Q B F G D]
time 784ms: Process H switching out of CPU; will block on I/O until time 787ms [Q B F G D]
time 787ms: Process H completed I/O; added to ready queue [Q F G D H]
time 788ms: Process B started using the CPU for 1ms burst [Q F G D H]
time 789ms: Process B completed a CPU burst; 70 bursts to go [Q F G D H]
time 789ms: Process B switching out of CPU; will block on I/O until time 792ms [Q F G D H]
time 792ms: Process B completed I/O; added to ready queue [Q G D H B]
time 793ms: Process F started using the CPU for 1ms burst [Q G D H B]
time 794ms: Process F completed a CPU burst; 26 bursts to go [Q G D H B]
time 794ms: Process F switching out of CPU; will block on I/O until time 797ms [Q G D H B]
time 797ms: Process F completed I/O; added to ready queue [Q D H B F]
time 798ms: Process G started using the CPU for 1ms burst [Q D H B F]
time 799ms: Process G completed a CPU burst; 16 bursts to go [Q D H B F]
time 799ms: Process G switching out of CPU; will block on I/O until time 802ms [Q D H B F]
time 802ms: Process G completed I/O; added to ready queue [Q H B F G]
time 803ms: Process D started using the CPU for 1ms burst [Q H B F G]
time 804ms: Process D completed a CPU burst; 45 bursts to go [Q H B F G]
time 804ms: Process D switching out of CPU; will block on I/O until time 807ms [Q H B F G]
time 807ms: Process D completed I/O; added to ready queue [Q B F G D]
time 808ms: Process H started using the CPU for 1ms burst [Q B F G D]
time 809ms: Process H completed a CPU burst; 12 bursts to go [Q B F G D]
time 809ms: Process H switching out of CPU; will block on I/O until time 812ms [Q B F G D]
time 812ms: Process H completed I/O; added to ready queue [Q F G D H]
time 813ms: Process B started using the CPU for 1ms burst [Q F G D H]
time 814ms: Process B completed a CPU burst; 69 bursts to go [Q F G D H]
time 814ms: Process B switching out of CPU; will block on I/O until time 817ms [Q F G D H]
time 817ms: Process B completed I/O; added to ready queue [Q G D H B]
time 818ms: Process F started using the CPU for 1ms burst [Q G D H B]
time 819ms: Process F completed a CPU burst; 25 bursts to go [Q G D H B]
time 819ms: Process F switching out of CPU; will block on I/O until time 822ms [Q G D H B]
time 822ms: Process F completed I/O; added to ready queue [Q D H B F]
time 823ms: Process G started using the CPU for 1ms burst [Q D H B F]
time 824ms: Process G completed a CPU burst; 15 bursts to go [Q D H B F]
time 824ms: Process G switching out of CPU; will block on I/O until time 827ms [Q D H B F]
time 827ms: Process G completed I/O; added to ready queue [Q H B F G]
time 828ms: Process D started using the CPU for 1ms burst [Q H B F G]
time 829ms: Process D completed a CPU burst; 44 bursts to go [Q H B F G]
time 829ms: Process D switching out of CPU; will block on I/O until time 832ms [Q H B F G]
time 832ms: Process D completed I/O; added to ready queue [Q B F G D]
time 833ms: Process H started using the CPU for 1ms burst [Q B F G D]
time 834ms: Process H completed a CPU burst; 11 bursts to go [Q B F G D]
time 834ms: Process H switching out of CPU; will block on I/O until time 837ms [Q B F G D]
time 837ms: Process H completed I/O; added to ready queue [Q F G D H]
time 838ms: Process B started using the CPU for 1ms burst [Q F G D H]
time 839ms: Process B completed a CPU burst; 68 bursts to go [Q F G D H]
time 839ms: Process B switching out of CPU; will block on I/O until time 842ms [Q F G D H]
time 842ms: Process B completed I/O; added to ready queue [Q G D H B]
time 843ms: Process F started using the CPU for 1ms burst [Q G D H B]
time 844ms: Process F completed a CPU burst; 24 bursts to go [Q G D H B]
time 844ms: Process F switching out of CPU; will block on I/O until time 847ms [Q G D H B]
time 847ms: Process F completed I/O; added to ready queue [Q D H B F]
time 848ms: Process G started using the CPU for 1ms burst [Q D H B F]
time 849ms: Process G completed a CPU burst; 14 bursts to go [Q D H B F]
time 849ms: Process G switching out of CPU; will block on I/O until time 852ms [Q D H B F]
time 852ms: Process G completed I/O; added to ready queue [Q H B F G]
time 853ms: Process D started using the CPU for 1ms burst [Q H B F G]
time 854ms: Process D completed a CPU burst; 43 bursts to go [Q H B F G]
time 854ms: Process D switching out of CPU; will block on I/O until time 857ms [Q H B F G]
time 857ms: Process D completed I/O; added to ready queue [Q B F G D]
time 858ms: Process H started using the CPU for 1ms burst [Q B F G D]
time 859ms: Process H completed a CPU burst; 10 bursts to go [Q B F G D]
time 859ms: Process H switching out of CPU; will block on I/O until time 862ms [Q B F G D]
time 862ms: Process H completed I/O; added to ready queue [Q F G D H]
time 863ms: Process B started using the CPU for 1ms burst [Q F G D H]
time 864ms: Process B completed a CPU burst; 67 bursts to go [Q F G D H]
time 864ms: Process B switching out of CPU; will block on I/O until time 867ms [Q F G D H]
time 867ms: Process B completed I/O; added to ready queue [Q G D H B]
time 868ms: Process F started using the CPU for 1ms burst [Q G D H B]
time 869ms: Process F completed a CPU burst; 23 bursts to go [Q G D H B]
time 869ms: Process F switching out of CPU; will block on I/O until time 872ms [Q G D H B]
time 872ms: Process F completed I/O; added to ready queue [Q D H B F]
time 873ms: Process G started using the CPU for 1ms burst [Q D H B F]
time 874ms: Process G completed a CPU burst; 13 bursts to go [Q D H B F]
time 874ms: Process G switching out of CPU; will block on I/O until time 877ms [Q D H B F]
time 877ms: Process G completed I/O; added to ready queue [Q H B F G]
time 878ms: Process D started using the CPU for 1ms burst [Q H B F G]
time 879ms: Process D completed a CPU burst; 42 bursts to go [Q H B F G]
time 879ms: Process D switching out of CPU; will block on I/O until time 882ms [Q H B F G]
time 882ms: Process D completed I/O; added to ready queue [Q B F G D]
time 883ms: Process H started using the CPU for 1ms burst [Q B F G D]
time 884ms: Process H completed a CPU burst; 9 bursts to go [Q B F G D]
time 884ms: Process H switching out of CPU; will block on I/O until time 887ms [Q B F G D]
time 887ms: Process H completed I/O; added to ready queue [Q F G D H]
time 888ms: Process B started using the CPU for 1ms burst [Q F G D H]
time 889ms: Process B completed a CPU burst; 66 bursts to go [Q F G D H]
time 889ms: Process B switching out of CPU; will block on I/O until time 892ms [Q F G D H]
time 892ms: Process B completed I/O; added to ready queue [Q G D H B]
time 893ms: Process F started using the CPU for 1ms burst [Q G D H B]
time 894ms: Process F completed a CPU burst; 22 bursts to go [Q G D H B]
time 894ms: Process F switching out of CPU; will block on I/O until time 897ms [Q G D H B]
time 897ms: Process F completed I/O; added to ready queue [Q D H B F]
time 898ms: Process G started using the CPU for 1ms burst [Q D H B F]
time 899ms: Process G completed a CPU burst; 12 bursts to go [Q D H B F]
time 899ms: Process G switching out of CPU; will block on I/O until time 902ms [Q D H B F]
time 902ms: Process G completed I/O; added to ready queue [Q H B F G]
time 903ms: Process D started using the CPU for 1ms burst [Q H B F G]
time 904ms: Process D completed a CPU burst; 41 bursts to go [Q H B F G]
time 904ms: Process D switching out of CPU; will block on I/O until time 907ms [Q H B F G]
time 907ms: Process D completed I/O; added to ready queue [Q B F G D]
time 908ms: Process H started using the CPU for 1ms burst [Q B F G D]
time 909ms: Process H completed a CPU burst; 8 bursts to go [Q B F G D]
time 909ms: Process H switching out of CPU; will block on I/O until time 912ms [Q B F G D]
time 912ms: Process H completed I/O; added to ready queue [Q F G D H]
time 913ms: Process B started using the CPU for 1ms burst [Q F G D H]
time 914ms: Process B completed a CPU burst; 65 bursts to go [Q F G D H]
time 914ms: Process B switching out of CPU; will block on I/O until time 917ms [Q F G D H]
time 917ms: Process B completed I/O; added to ready queue [Q G D H B]
time 918ms: Process F started using the CPU for 1ms burst [Q G D H B]
time 919ms: Process F completed a CPU burst; 21 bursts to go [Q G D H B]
time 919ms: Process F switching out of CPU; will block on I/O until time 922ms [Q G D H B]
time 922ms: Process F completed I/O; added to ready queue [Q D H B F]
time 923ms: Process G started using the CPU for 1ms burst [Q D H B F]
time 924ms: Process G completed a CPU burst; 11 bursts to go [Q D H B F]
time 924ms: Process G switching out of CPU; will block on I/O until time 927ms [Q D H B F]
time 927ms: Process G completed I/O; added to ready queue [Q H B F G]
time 928ms: Process D started using the CPU for 1ms burst [Q H B F G]
time 929ms: Process D completed a CPU burst; 40 bursts to go [Q H B F G]
time 929ms: Process D switching out of CPU; will block on I/O until time 932ms [Q H B F G]
time 932ms: Process D completed I/O; added to ready queue [Q B F G D]
time 933ms: Process H started using the CPU for 1ms burst [Q B F G D]
time 934ms: Process H completed a CPU burst; 7 bursts to go [Q B F G D]
time 934ms: Process H switching out of CPU; will block on I/O until time 937ms [Q B F G D]
time 937ms: Process H completed I/O; added to ready queue [Q F G D H]
time 938ms: Process B started using the CPU for 1ms burst [Q F G D H]
time 939ms: Process B completed a CPU burst; 64 bursts to go [Q F G D H]
time 939ms: Process B switching out of CPU; will block on I/O until time 942ms [Q F G D H]
time 942ms: Process B completed I/O; added to ready queue [Q G D H B]
time 943ms: Process F started using the CPU for 1ms burst [Q G D H B]
time 944ms: Process F completed a CPU burst; 20 bursts to go [Q G D H B]
time 944ms: Process F switching out of CPU; will block on I/O until time 947ms [Q G D H B]
time 947ms: Process F completed I/O; added to ready queue [Q D H B F]
time 948ms: Process G started using the CPU for 1ms burst [Q D H B F]
time 949ms: Process G completed a CPU burst; 10 bursts to go [Q D H B F]
time 949ms: Process G switching out of CPU; will block on I/O until time 952ms [Q D H B F]
time 952ms: Process G completed I/O; added to ready queue [Q H B F G]
time 953ms: Process D started using the CPU for 1ms burst [Q H B F G]
time 954ms: Process D completed a CPU burst; 39 bursts to go [Q H B F G]
time 954ms: Process D switching out of CPU; will block on I/O until time 957ms [Q H B F G]
time 957ms: Process D completed I/O; added to ready queue [Q B F G D]
time 958ms: Process H started using the CPU for 1ms burst [Q B F G D]
time 959ms: Process H completed a CPU burst; 6 bursts to go [Q B F G D]
time 959ms: Process H switching out of CPU; will block on I/O until time 962ms [Q B F G D]
time 962ms: Process H completed I/O; added to ready queue [Q F G D H]
time 963ms: Process B started using the CPU for 1ms burst [Q F G D H]
time 964ms: Process B completed a CPU burst; 63 bursts to go [Q F G D H]
time 964ms: Process B switching out of CPU; will block on I/O until time 967ms [Q F G D H]
time 967ms: Process B completed I/O; added to ready queue [Q G D H B]
time 968ms: Process F started using the CPU for 1ms burst [Q G D H B]
time 969ms: Process F completed a CPU burst; 19 bursts to go [Q G D H B]
time 969ms: Process F switching out of CPU; will block on I/O until time 972ms [Q G D H B]
time 972ms: Process F completed I/O; added to ready queue [Q D H B F]
time 973ms: Process G started using the CPU for 1ms burst [Q D H B F]
time 974ms: Process G completed a CPU burst; 9 bursts to go [Q D H B F]
time 974ms: Process G switching out of CPU; will block on I/O until time 977ms [Q D H B F]
time 977ms: Process G completed I/O; added to ready queue [Q H B F G]
time 978ms: Process D started using the CPU for 1ms burst [Q H B F G]
time 979ms: Process D completed a CPU burst; 38 bursts to go [Q H B F G]
time 979ms: Process D switching out of CPU; will block on I/O until time 982ms [Q H B F G]
time 982ms: Process D completed I/O; added to ready queue [Q B F G D]
time 983ms: Process H started using the CPU for 1ms burst [Q B F G D]
time 984ms: Process H completed a CPU burst; 5 bursts to go [Q B F G D]
time 984ms: Process H switching out of CPU; will block on I/O until time 987ms [Q B F G D]
time 987ms: Process H completed I/O; added to ready queue [Q F G D H]
time 988ms: Process B started using the CPU for 1ms burst [Q F G D H]
time 989ms: Process B completed a CPU burst; 62 bursts to go [Q F G D H]
time 989ms: Process B switching out of CPU; will block on I/O until time 992ms [Q F G D H]
time 992ms: Process B completed I/O; added to ready queue [Q G D H B]
time 993ms: Process F started using the CPU for 1ms burst [Q G D H B]
time 994ms: Process F completed a CPU burst; 18 bursts to go [Q G D H B]
time 994ms: Process F switching out of CPU; will block on I/O until time 997ms [Q G D H B]
time 997ms: Process F completed I/O; added to ready queue [Q D H B F]
time 998ms: Process G started using the CPU for 1ms burst [Q D H B F]
time 999ms: Process G completed a CPU burst; 8 bursts to go [Q D H B F]
time 999ms: Process G switching out of CPU; will block on I/O until time 1002ms [Q D H B F]
time 1109ms: Process H terminated [Q B F G D]
time 1184ms: Process G terminated [Q D B F]
time 1334ms: Process F terminated [Q D B]
time 1529ms: Process D terminated [Q B]
time 1678ms: Process B terminated [Q <empty>]
time 1680ms: Simulator ended for FCFS [Q <empty>]

Process A [NEW] (arrival time 0 ms) 5 CPU bursts (tau 1000ms)
Process B [NEW] (arrival time 0 ms) 96 CPU bursts (tau 1000ms)
Process C [NEW] (arrival time 0 ms) 22 CPU bursts (tau 1000ms)
Process D [NEW] (arrival time 0 ms) 71 CPU bursts (tau 1000ms)
Process E [NEW] (arrival time 0 ms) 8 CPU bursts (tau 1000ms)
Process F [NEW] (arrival time 0 ms) 51 CPU bursts (tau 1000ms)
Process G [NEW] (arrival time 0 ms) 41 CPU bursts (tau 1000ms)
Process H [NEW] (arrival time 0 ms) 37 CPU bursts (tau 1000ms)
time 0ms: Simulator started for SJF [Q <empty>]
time 0ms: Process A (tau 1000ms) arrived; added to ready queue [Q A]
time 2ms: Process A (tau 1000ms) started using the CPU for 1ms burst [Q <empty>]
time 3ms: Process A (tau 1000ms) completed a CPU burst; 4 bursts to go [Q <empty>]
time 3ms: Recalculated tau = 501ms for process A [Q <empty>]
time 3ms: Process A switching out of CPU; will block on I/O until time 6ms [Q <empty>]
time 6ms: Process A (tau 501ms) completed I/O; added to ready queue [Q A]
time 6ms: Process B (tau 1000ms) arrived; added to ready queue [Q A B]
time 8ms: Process A (tau 501ms) started using the CPU for 1ms burst [Q B]
time 9ms: Process A (tau 501ms) completed a CPU burst; 3 bursts to go [Q B]
time 9ms: Recalculated tau = 251ms for process A [Q B]
time 9ms: Process A switching out of CPU; will block on I/O until time 12ms [Q B]
time 11ms: Process C (tau 1000ms) arrived; added to ready queue [Q B C]
time 12ms: Process A (tau 251ms) completed I/O; added to ready queue [Q A C]
time 13ms: Process B (tau 1000ms) started using the CPU for 1ms burst [Q A C]
time 14ms: Process B (tau 1000ms) completed a CPU burst; 95 bursts to go [Q A C]
time 14ms: Recalculated tau = 501ms for process B [Q A C]
time 14ms: Process B switching out of CPU; will block on I/O until time 17ms [Q A C]
time 16ms: Process D (tau 1000ms) arrived; added to ready queue [Q A C D]
time 17ms: Process B (tau 501ms) completed I/O; added to ready queue [Q B C D]
time 18ms: Process A (tau 251ms) started using the CPU for 1ms burst [Q B C D]
time 19ms: Process A (tau 251ms) completed a CPU burst; 2 bursts to go [Q B C D]
time 19ms: Recalculated tau = 126ms for process A [Q B C D]
time 19ms: Process A switching out of CPU; will block on I/O until time 22ms [Q B C D]
time 21ms: Process E (tau 1000ms) arrived; added to ready queue [Q B C D E]
time 22ms: Process A (tau 126ms) completed I/O; added to ready queue [Q A C D E]
time 23ms: Process B (tau 501ms) started using the CPU for 1ms burst [Q A C D E]
time 24ms: Process B (tau 501ms) completed a CPU burst; 94 bursts to go [Q A C D E]
time 24ms: Recalculated tau = 251ms for process B [Q A C D E]
time 24ms: Process B switching out of CPU; will block on I/O until time 27ms [Q A C D E]
time 26ms: Process F (tau 1000ms) arrived; added to ready queue [Q A C D E F]
time 27ms: Process B (tau 251ms) completed I/O; added to ready queue [Q B C D E F]
time 28ms: Process A (tau 126ms) started using the CPU for 1ms burst [Q B C D E F]
time 29ms: Process A (tau 126ms) completed a CPU burst; 1 burst to go [Q B C D E F]
time 29ms: Recalculated tau = 64ms for process A [Q B C D E F]
time 29ms: Process A switching out of CPU; will block on I/O until time 32ms [Q B C D E F]
time 31ms: Process G (tau 1000ms) arrived; added to ready queue [Q B C D E F G]
time 32ms: Process A (tau 64ms) completed I/O; added to ready queue [Q A C D E F G]
time 33ms: Process B (tau 251ms) started using the CPU for 1ms burst [Q A C D E F G]
time 34ms: Process B (tau 251ms) completed a CPU burst; 93 bursts to go [Q A C D E F G]
time 34ms: Recalculated tau = 126ms for process B [Q A C D E F G]
time 34ms: Process B switching out of CPU; will block on I/O until time 37ms [Q A C D E F G]
time 36ms: Process H (tau 1000ms) arrived; added to ready queue [Q A C D E F G H]
time 37ms: Process B (tau 126ms) completed I/O; added to ready queue [Q B C D E F G H]
time 38ms: Process A (tau 64ms) started using the CPU for 1ms burst [Q B C D E F G H]
time 39ms: Process A terminated [Q B C D E F G H]
time 43ms: Process B (tau 126ms) started using the CPU for 1ms burst [Q C D E F G H]
time 44ms: Process B (tau 126ms) completed a CPU burst; 92 bursts to go [Q C D E F G H]
time 44ms: Recalculated tau = 64ms for process B [Q C D E F G H]
time 44ms: Process B switching out of CPU; will block on I/O until time 47ms [Q C D E F G H]
time 47ms: Process B (tau 64ms) completed I/O; added to ready queue [Q B D E F G H]
time 48ms: Process C (tau 1000ms) started using the CPU for 1ms burst [Q B D E F G H]
time 49ms: Process C (tau 1000ms) completed a CPU burst; 21 bursts to go [Q B D E F G H]
time 49ms: Recalculated tau = 501ms for process C [Q B D E F G H]
time 49ms: Process C switching out of CPU; will block on I/O until time 52ms [Q B D E F G H]
time 52ms: Process C (tau 501ms) completed I/O; added to ready queue [Q C D E F G H]
time 53ms: Process B (tau 64ms) started using the CPU for 1ms burst [Q C D E F G H]
time 54ms: Process B (tau 64ms) completed a CPU burst; 91 bursts to go [Q C D E F G H]
time 54ms: Recalculated tau = 33ms for process B [Q C D E F G H]
time 54ms: Process B switching out of CPU; will block on I/O until time 57ms [Q C D E F G H]
time 57ms: Process B (tau 33ms) completed I/O; added to ready queue [Q B D E F G H]
time 58ms: Process C (tau 501ms) started using the CPU for 1ms burst [Q B D E F G H]
time 59ms: Process C (tau 501ms) completed a CPU burst; 20 bursts to go [Q B D E F G H]
time 59ms: Recalculated tau = 251ms for process C [Q B D E F G H]
time 59ms: Process C switching out of CPU; will block on I/O until time 62ms [Q B D E F G H]
time 62ms: Process C (tau 251ms) completed I/O; added to ready queue [Q C D E F G H]
time 63ms: Process B (tau 33ms) started using the CPU for 1ms burst [Q C D E F G H]
time 64ms: Process B (tau 33ms) completed a CPU burst; 90 bursts to go [Q C D E F G H]
time 64ms: Recalculated tau = 17ms for process B [Q C D E F G H]
time 64ms: Process B switching out of CPU; will block on I/O until time 67ms [Q C D E F G H]
time 67ms: Process B (tau 17ms) completed I/O; added to ready queue [Q B D E F G H]
time 68ms: Process C (tau 251ms) started using the CPU for 1ms burst [Q B D E F G H]
time 69ms: Process C (tau 251ms) completed a CPU burst; 19 bursts to go [Q B D E F G H]
time 69ms: Recalculated tau = 126ms for process C [Q B D E F G H]
time 69ms: Process C switching out of CPU; will block on I/O until time 72ms [Q B D E F G H]
time 72ms: Process C (tau 126ms) completed I/O; added to ready queue [Q C D E F G H]
time 73ms: Process B (tau 17ms) started using the CPU for 1ms burst [Q C D E F G H]
time 74ms: Process B (tau 17ms) completed a CPU burst; 89 bursts to go [Q C D E F G H]
time 74ms: Recalculated tau = 9ms for process B [Q C D E F G H]
time 74ms: Process B switching out of CPU; will block on I/O until time 77ms [Q C D E F G H]
time 77ms: Process B (tau 9ms) completed I/O; added to ready queue [Q B D E F G H]
time 78ms: Process C (tau 126ms) started using the CPU for 1ms burst [Q B D E F G H]
time 79ms: Process C (tau 126ms) completed a CPU burst; 18 bursts to go [Q B D E F G H]
time 79ms: Recalculated tau = 64ms for process C [Q B D E F G H]
time 79ms: Process C switching out of CPU; will block on I/O until time 82ms [Q B D E F G H]
time 82ms: Process C (tau 64ms) completed I/O; added to ready queue [Q C D E F G H]
time 83ms: Process B (tau 9ms) started using the CPU for 1ms burst [Q C D E F G H]
time 84ms: Process B (tau 9ms) completed a CPU burst; 88 bursts to go [Q C D E F G H]
time 84ms: Recalculated tau = 5ms for process B [Q C D E F G H]
time 84ms: Process B switching out of CPU; will block on I/O until time 87ms [Q C D E F G H]
time 87ms: Process B (tau 5ms) completed I/O; added to ready queue [Q B D E F G H]
time 88ms: Process C (tau 64ms) started using the CPU for 1ms burst [Q B D E F G H]
time 89ms: Process C (tau 64ms) completed a CPU burst; 17 bursts to go [Q B D E F G H]
time 89ms: Recalculated tau = 33ms for process C [Q B D E F G H]
time 89ms: Process C switching out of CPU; will block on I/O until time 92ms [Q B D E F G H]
time 92ms: Process C (tau 33ms) completed I/O; added to ready queue [Q C D E F G H]
time 93ms: Process B (tau 5ms) started using the CPU for 1ms burst [Q C D E F G H]
time 94ms: Process B (tau 5ms) completed a CPU burst; 87 bursts to go [Q C D E F G H]
time 94ms: Recalculated tau = 3ms for process B [Q C D E F G H]
time 94ms: Process B switching out of CPU; will block on I/O until time 97ms [Q C D E F G H]
time 97ms: Process B (tau 3ms) completed I/O; added to ready queue [Q B D E F G H]
time 98ms: Process C (tau 33ms) started using the CPU for 1ms burst [Q B D E F G H]
time 99ms: Process C (tau 33ms) completed a CPU burst; 16 bursts to go [Q B D E F G H]
time 99ms: Recalculated tau = 17ms for process C [Q B D E F G H]
time 99ms: Process C switching out of CPU; will block on I/O until time 102ms [Q B D E F G H]
time 102ms: Process C (tau 17ms) completed I/O; added to ready queue [Q C D E F G H]
time 103ms: Process B (tau 3ms) started using the CPU for 1ms burst [Q C D E F G H]
time 104ms: Process B (tau 3ms) completed a CPU burst; 86 bursts to go [Q C D E F G H]
time 104ms: Recalculated tau = 2ms for process B [Q C D E F G H]
time 104ms: Process B switching out of CPU; will block on I/O until time 107ms [Q C D E F G H]
time 107ms: Process B (tau 2ms) completed I/O; added to ready queue [Q B D E F G H]
time 108ms: Process C (tau 17ms) started using the CPU for 1ms burst [Q B D E F G H]
time 109ms: Process C (tau 17ms) completed a CPU burst; 15 bursts to go [Q B D E F G H]
time 109ms: Recalculated tau = 9ms for process C [Q B D E F G H]
time 109ms: Process C switching out of CPU; will block on I/O until time 112ms [Q B D E F G H]
time 112ms: Process C (tau 9ms) completed I/O; added to ready queue [Q C D E F G H]
time 113ms: Process B (tau 2ms) started using the CPU for 1ms burst [Q C D E F G H]
time 114ms: Process B (tau 2ms) completed a CPU burst; 85 bursts to go [Q C D E F G H]
time 114ms: Recalculated tau = 2ms for process B [Q C D E F G H]
time 114ms: Process B switching out of CPU; will block on I/O until time 117ms [Q C D E F G H]
time 117ms: Process B (tau 2ms) completed I/O; added to ready queue [Q B D E F G H]
time 118ms: Process C (tau 9ms) started using the CPU for 1ms burst [Q B D E F G H]
time 119ms: Process C (tau 9ms) completed a CPU burst; 14 bursts to go [Q B D E F G H]
time 119ms: Recalculated tau = 5ms for process C [Q B D E F G H]
time 119ms: Process C switching out of CPU; will block on I/O until time 122ms [Q B D E F G H]
time 122ms: Process C (tau 5ms) completed I/O; added to ready queue [Q C D E F G H]
time 123ms: Process B (tau 2ms) started using the CPU for 1ms burst [Q C D E F G H]
time 124ms: Process B (tau 2ms) completed a CPU burst; 84 bursts to go [Q C D E F G H]
time 124ms: Recalculated tau = 2ms for process B [Q C D E F G H]
time 124ms: Process B switching out of CPU; will block on I/O until time 127ms [Q C D E F G H]
time 127ms: Process B (tau 2ms) completed I/O; added to ready queue [Q B D E F G H]
time 128ms: Process C (tau 5ms) started using the CPU for 1ms burst [Q B D E F G H]
time 129ms: Process C (tau 5ms) completed a CPU burst; 13 bursts to go [Q B D E F G H]
time 129ms: Recalculated tau = 3ms for process C [Q B D E F G H]
time 129ms: Process C switching out of CPU; will block on I/O until time 132ms [Q B D E F G H]
time 132ms: Process C (tau 3ms) completed I/O; added to ready queue [Q C D E F G H]
time 133ms: Process B (tau 2ms) started using the CPU for 1ms burst [Q C D E F G H]
time 134ms: Process B (tau 2ms) completed a CPU burst; 83 bursts to go [Q C D E F G H]
time 134ms: Recalculated tau = 2ms for process B [Q C D E F G H]
time 134ms: Process B switching out of CPU; will block on I/O until time 137ms [Q C D E F G H]
time 137ms: Process B (tau 2ms) completed I/O; added to ready queue [Q B D E F G H]
time 138ms: Process C (tau 3ms) started using the CPU for 1ms burst [Q B D E F G H]
time 139ms: Process C (tau 3ms) completed a CPU burst; 12 bursts to go [Q B D E F G H]
time 139ms: Recalculated tau = 2ms for process C [Q B D E F G H]
time 139ms: Process C switching out of CPU; will block on I/O until time 142ms [Q B D E F G H]
time 142ms: Process C (tau 2ms) completed I/O; added to ready queue [Q C D E F G H]
time 143ms: Process B (tau 2ms) started using the CPU for 1ms burst [Q C D E F G H]
time 144ms: Process B (tau 2ms) completed a CPU burst; 82 bursts to go [Q C D E F G H]
time 144ms: Recalculated tau = 2ms for process B [Q C D E F G H]
time 144ms: Process B switching out of CPU; will block on I/O until time 147ms [Q C D E F G H]
time 147ms: Process B (tau 2ms) completed I/O; added to ready queue [Q B D E F G H]
time 148ms: Process C (tau 2ms) started using the CPU for 1ms burst [Q B D E F G H]
time 149ms: Process C (tau 2ms) completed a CPU burst; 11 bursts to go [Q B D E F G H]
time 149ms: Recalculated tau = 2ms for process C [Q B D E F G H]
time 149ms: Process C switching out of CPU; will block on I/O until time 152ms [Q B D E F G H]
time 152ms: Process C (tau 2ms) completed I/O; added to ready queue [Q C D E F G H]
time 153ms: Process B (tau 2ms) started using the CPU for 1ms burst [Q C D E F G H]
time 154ms: Process B (tau 2ms) completed a CPU burst; 81 bursts to go [Q C D E F G H]
time 154ms: Recalculated tau = 2ms for process B [Q C D E F G H]
time 154ms: Process B switching out of CPU; will block on I/O until time 157ms [Q C D E F G H]
time 157ms: Process B (tau 2ms) completed I/O; added to ready queue [Q B D E F G H]
time 158ms: Process C (tau 2ms) started using the CPU for 1ms burst [Q B D E F G H]
time 159ms: Process C (tau 2ms) completed a CPU burst; 10 bursts to go [Q B D E F G H]
time 159ms: Recalculated tau = 2ms for process C [Q B D E F G H]
time 159ms: Process C switching out of CPU; will block on I/O until time 162ms [Q B D E F G H]
time 162ms: Process C (tau 2ms) completed I/O; added to ready queue [Q C D E F G H]
time 163ms: Process B (tau 2ms) started using the CPU for 1ms burst [Q C D E F G H]
time 164ms: Process B (tau 2ms) completed a CPU burst; 80 bursts to go [Q C D E F G H]
time 164ms: Recalculated tau = 2ms for process B [Q C D E F G H]
time 164ms: Process B switching out of CPU; will block on I/O until time 167ms [Q C D E F G H]
time 167ms: Process B (tau 2ms) completed I/O; added to ready queue [Q B D E F G H]
time 168ms: Process C (tau 2ms) started using the CPU for 1ms burst [Q B D E F G H]
time 169ms: Process C (tau 2ms) completed a CPU burst; 9 bursts to go [Q B D E F G H]
time 169ms: Recalculated tau = 2ms for process C [Q B D E F G H]
time 169ms: Process C switching out of CPU; will block on I/O until time 172ms [Q B D E F G H]
time 172ms: Process C (tau 2ms) completed I/O; added to ready queue [Q C D E F G H]
time 173ms: Process B (tau 2ms) started using the CPU for 1ms burst [Q C D E F G H]
time 174ms: Process B (tau 2ms) completed a CPU burst; 79 bursts to go [Q C D E F G H]
time 174ms: Recalculated tau = 2ms for process B [Q C D E F G H]
time 174ms: Process B switching out of CPU; will block on I/O until time 177ms [Q C D E F G H]
time 177ms: Process B (tau 2ms) completed I/O; added to ready queue [Q B D E F G H]
time 178ms: Process C (tau 2ms) started using the CPU for 1ms burst [Q B D E F G H]
time 179ms: Process C (tau 2ms) completed a CPU burst; 8 bursts to go [Q B D E F G H]
time 179ms: Recalculated tau = 2ms for process C [Q B D E F G H]
time 179ms: Process C switching out of CPU; will block on I/O until time 182ms [Q B D E F G H]
time 182ms: Process C (tau 2ms) completed I/O; added to ready queue [Q C D E F G H]
time 183ms: Process B (tau 2ms) started using the CPU for 1ms burst [Q C D E F G H]
time 184ms: Process B (tau 2ms) completed a CPU burst; 78 bursts to go [Q C D E F G H]
time 184ms: Recalculated tau = 2ms for process B [Q C D E F G H]
time 184ms: Process B switching out of CPU; will block on I/O until time 187ms [Q C D E F G H]
time 187ms: Process B (tau 2ms) completed I/O; added to ready queue [Q B D E F G H]
time 188ms: Process C (tau 2ms) started using the CPU for 1ms burst [Q B D E F G H]
time 189ms: Process C (tau 2ms) completed a CPU burst; 7 bursts to go [Q B D E F G H]
time 189ms: Recalculated tau = 2ms for process C [Q B D E F G H]
time 189ms: Process C switching out of CPU; will block on I/O until time 192ms [Q B D E F G H]
time 192ms: Process C (tau 2ms) completed I/O; added to ready queue [Q C D E F G H]
time 193ms: Process B (tau 2ms) started using the CPU for 1ms burst [Q C D E F G H]
time 194ms: Process B (tau 2ms) completed a CPU burst; 77 bursts to go [Q C D E F G H]
time 194ms: Recalculated tau = 2ms for process B [Q C D E F G H]
time 194ms: Process B switching out of CPU; will block on I/O until time 197ms [Q C D E F G H]
time 197ms: Process B (tau 2ms) completed I/O; added to ready queue [Q B D E F G H]
time 198ms: Process C (tau 2ms) started using the CPU for 1ms burst [Q B D E F G H]
time 199ms: Process C (tau 2ms) completed a CPU burst; 6 bursts to go [Q B D E F G H]
time 199ms: Recalculated tau = 2ms for process C [Q B D E F G H]
time 199ms: Process C switching out of CPU; will block on I/O until time 202ms [Q B D E F G H]
time 202ms: Process C (tau 2ms) completed I/O; added to ready queue [Q C D E F G H]
time 203ms: Process B (tau 2ms) started using the CPU for 1ms burst [Q C D E F G H]
time 204ms: Process B (tau 2ms) completed a CPU burst; 76 bursts to go [Q C D E F G H]
time 204ms: Recalculated tau = 2ms for process B [Q C D E F G H]
time 204ms: Process B switching out of CPU; will block on I/O until time 207ms [Q C D E F G H]
time 207ms: Process B (tau 2ms) completed I/O; added to ready queue [Q B D E F G H]
time 208ms: Process C (tau 2ms) started using the CPU for 1ms burst [Q B D E F G H]
time 209ms: Process C (tau 2ms) completed a CPU burst; 5 bursts to go [Q B D E F G H]
time 209ms: Recalculated tau = 2ms for process C [Q B D E F G H]
time 209ms: Process C switching out of CPU; will block on I/O until time 212ms [Q B D E F G H]
time 212ms: Process C (tau 2ms) completed I/O; added to ready queue [Q C D E F G H]
time 213ms: Process B (tau 2ms) started using the CPU for 1ms burst [Q C D E F G H]
time 214ms: Process B (tau 2ms) completed a CPU burst; 75 bursts to go [Q C D E F G H]
time 214ms: Recalculated tau = 2ms for process B [Q C D E F G H]
time 214ms: Process B switching out of CPU; will block on I/O until time 217ms [Q C D E F G H]
time 217ms: Process B (tau 2ms) completed I/O; added to ready queue [Q B D E F G H]
time 218ms: Process C (tau 2ms) started using the CPU for 1ms burst [Q B D E F G H]
time 219ms: Process C (tau 2ms) completed a CPU burst; 4 bursts to go [Q B D E F G H]
time 219ms: Recalculated tau = 2ms for process C [Q B D E F G H]
time 219ms: Process C switching out of CPU; will block on I/O until time 222ms [Q B D E F G H]
time 222ms: Process C (tau 2ms) completed I/O; added to ready queue [Q C D E F G H]
time 223ms: Process B (tau 2ms) started using the CPU for 1ms burst [Q C D E F G H]
time 224ms: Process B (tau 2ms) completed a CPU burst; 74 bursts to go [Q C D E F G H]
time 224ms: Recalculated tau = 2ms for process B [Q C D E F G H]
time 224ms: Process B switching out of CPU; will block on I/O until time 227ms [Q C D E F G H]
time 227ms: Process B (tau 2ms) completed I/O; added to ready queue [Q B D E F G H]
time 228ms: Process C (tau 2ms) started using the CPU for 1ms burst [Q B D E F G H]
time 229ms: Process C (tau 2ms) completed a CPU burst; 3 bursts to go [Q B D E F G H]
time 229ms: Recalculated tau = 2ms for process C [Q B D E F G H]
time 229ms: Process C switching out of CPU; will block on I/O until time 232ms [Q B D E F G H]
time 232ms: Process C (tau 2ms) completed I/O; added to ready queue [Q C D E F G H]
time 233ms: Process B (tau 2ms) started using the CPU for 1ms burst [Q C D E F G H]
time 234ms: Process B (tau 2ms) completed a CPU burst; 73 bursts to go [Q C D E F G H]
time 234ms: Recalculated tau = 2ms for process B [Q C D E F G H]
time 234ms: Process B switching out of CPU; will block on I/O until time 237ms [Q C D E F G H]
time 237ms: Process B (tau 2ms) completed I/O; added to ready queue [Q B D E F G H]
time 238ms: Process C (tau 2ms) started using the CPU for 1ms burst [Q B D E F G H]
time 239ms: Process C (tau 2ms) completed a CPU burst; 2 bursts to go [Q B D E F G H]
time 239ms: Recalculated tau = 2ms for process C [Q B D E F G H]
time 239ms: Process C switching out of CPU; will block on I/O until time 242ms [Q B D E F G H]
time 242ms: Process C (tau 2ms) completed I/O; added to ready queue [Q C D E F G H]
time 243ms: Process B (tau 2ms) started using the CPU for 1ms burst [Q C D E F G H]
time 244ms: Process B (tau 2ms) completed a CPU burst; 72 bursts to go [Q C D E F G H]
time 244ms: Recalculated tau = 2ms for process B [Q C D E F G H]
time 244ms: Process B switching out of CPU; will block on I/O until time 247ms [Q C D E F G H]
time 247ms: Process B (tau 2ms) completed I/O; added to ready queue [Q B D E F G H]
time 248ms: Process C (tau 2ms) started using the CPU for 1ms burst [Q B D E F G H]
time 249ms: Process C (tau 2ms) completed a CPU burst; 1 burst to go [Q B D E F G H]
time 249ms: Recalculated tau = 2ms for process C [Q B D E F G H]
time 249ms: Process C switching out of CPU; will block on I/O until time 252ms [Q B D E F G H]
time 252ms: Process C (tau 2ms) completed I/O; added to ready queue [Q C D E F G H]
time 253ms: Process B (tau 2ms) started using the CPU for 1ms burst [Q C D E F G H]
time 254ms: Process B (tau 2ms) completed a CPU burst; 71 bursts to go [Q C D E F G H]
time 254ms: Recalculated tau = 2ms for process B [Q C D E F G H]
time 254ms: Process B switching out of CPU; will block on I/O until time 257ms [Q C D E F G H]
time 257ms: Process B (tau 2ms) completed I/O; added to ready queue [Q B D E F G H]
time 258ms: Process C (tau 2ms) started using the CPU for 1ms burst [Q B D E F G H]
time 259ms: Process C terminated [Q B D E F G H]
time 263ms: Process B (tau 2ms) started using the CPU for 1ms burst [Q D E F G H]
time 264ms: Process B (tau 2ms) completed a CPU burst; 70 bursts to go [Q D E F G H]
time 264ms: Recalculated tau = 2ms for process B [Q D E F G H]
time 264ms: Process B switching out of CPU; will block on I/O until time 267ms [Q D E F G H]
time 267ms: Process B (tau 2ms) completed I/O; added to ready queue [Q B E F G H]
time 268ms: Process D (tau 1000ms) started using the CPU for 1ms burst [Q B E F G H]
time 269ms: Process D (tau 1000ms) completed a CPU burst; 70 bursts to go [Q B E F G H]
time 269ms: Recalculated tau = 501ms for process D [Q B E F G H]
time 269ms: Process D switching out of CPU; will block on I/O until time 272ms [Q B E F G H]
time 272ms: Process D (tau 501ms) completed I/O; added to ready queue [Q D E F G H]
time 273ms: Process B (tau 2ms) started using the CPU for 1ms burst [Q D E F G H]
time 274ms: Process B (tau 2ms) completed a CPU burst; 69 bursts to go [Q D E F G H]
time 274ms: Recalculated tau = 2ms for process B [Q D E F G H]
time 274ms: Process B switching out of CPU; will block on I/O until time 277ms [Q D E F G H]
time 277ms: Process B (tau 2ms) completed I/O; added to ready queue [Q B E F G H]
time 278ms: Process D (tau 501ms) started using the CPU for 1ms burst [Q B E F G H]
time 279ms: Process D (tau 501ms) completed a CPU burst; 69 bursts to go [Q B E F G H]
time 279ms: Recalculated tau = 251ms for process D [Q B E F G H]
time 279ms: Process D switching out of CPU; will block on I/O until time 282ms [Q B E F G H]
time 282ms: Process D (tau 251ms) completed I/O; added to ready queue [Q D E F G H]
time 283ms: Process B (tau 2ms) started using the CPU for 1ms burst [Q D E F G H]
time 284ms: Process B (tau 2ms) completed a CPU burst; 68 bursts to go [Q D E F G H]
time 284ms: Recalculated tau = 2ms for process B [Q D E F G H]
time 284ms: Process B switching out of CPU; will block on I/O until time 287ms [Q D E F G H]
time 287ms: Process B (tau 2ms) completed I/O; added to ready queue [Q B E F G H]
time 288ms: Process D (tau 251ms) started using the CPU for 1ms burst [Q B E F G H]
time 289ms: Process D (tau 251ms) completed a CPU burst; 68 bursts to go [Q B E F G H]
time 289ms: Recalculated tau = 126ms for process D [Q B E F G H]
time 289ms: Process D switching out of CPU; will block on I/O until time 292ms [Q B E F G H]
time 292ms: Process D (tau 126ms) completed I/O; added to ready queue [Q D E F G H]
time 293ms: Process B (tau 2ms) started using the CPU for 1ms burst [Q D E F G H]
time 294ms: Process B (tau 2ms) completed a CPU burst; 67 bursts to go [Q D E F G H]
time 294ms: Recalculated tau = 2ms for process B [Q D E F G H]
time 294ms: Process B switching out of CPU; will block on I/O until time 297ms [Q D E F G H]
time 297ms: Process B (tau 2ms) completed I/O; added to ready queue [Q B E F G H]
time 298ms: Process D (tau 126ms) started using the CPU for 1ms burst [Q B E F G H]
time 299ms: Process D (tau 126ms) completed a CPU burst; 67 bursts to go [Q B E F G H]
time 299ms: Recalculated tau = 64ms for process D [Q B E F G H]
time 299ms: Process D switching out of CPU; will block on I/O until time 302ms [Q B E F G H]
time 302ms: Process D (tau 64ms) completed I/O; added to ready queue [Q D E F G H]
time 303ms: Process B (tau 2ms) started using the CPU for 1ms burst [Q D E F G H]
time 304ms: Process B (tau 2ms) completed a CPU burst; 66 bursts to go [Q D E F G H]
time 304ms: Recalculated tau = 2ms for process B [Q D E F G H]
time 304ms: Process B switching out of CPU; will block on I/O until time 307ms [Q D E F G H]
time 307ms: Process B (tau 2ms) completed I/O; added to ready queue [Q B E F G H]
time 308ms: Process D (tau 64ms) started using the CPU for 1ms burst [Q B E F G H]
time 309ms: Process D (tau 64ms) completed a CPU burst; 66 bursts to go [Q B E F G H]
time 309ms: Recalculated tau = 33ms for process D [Q B E F G H]
time 309ms: Process D switching out of CPU; will block on I/O until time 312ms [Q B E F G H]
time 312ms: Process D (tau 33ms) completed I/O; added to ready queue [Q D E F G H]
time 313ms: Process B (tau 2ms) started using the CPU for 1ms burst [Q D E F G H]
time 314ms: Process B (tau 2ms) completed a CPU burst; 65 bursts to go [Q D E F G H]
time 314ms: Recalculated tau = 2ms for process B [Q D E F G H]
time 314ms: Process B switching out of CPU; will block on I/O until time 317ms [Q D E F G H]
time 317ms: Process B (tau 2ms) completed I/O; added to ready queue [Q B E F G H]
time 318ms: Process D (tau 33ms) started using the CPU for 1ms burst [Q B E F G H]
time 319ms: Process D (tau 33ms) completed a CPU burst; 65 bursts to go [Q B E F G H]
time 319ms: Recalculated tau = 17ms for process D [Q B E F G H]
time 319ms: Process D switching out of CPU; will block on I/O until time 322ms [Q B E F G H]
time 322ms: Process D (tau 17ms) completed I/O; added to ready queue [Q D E F G H]
time 323ms: Process B (tau 2ms) started using the CPU for 1ms burst [Q D E F G H]
time 324ms: Process B (tau 2ms) completed a CPU burst; 64 bursts to go [Q D E F G H]
time 324ms: Recalculated tau = 2ms for process B [Q D E F G H]
time 324ms: Process B switching out of CPU; will block on I/O until time 327ms [Q D E F G H]
time 327ms: Process B (tau 2ms) completed I/O; added to ready queue [Q B E F G H]
time 328ms: Process D (tau 17ms) started using the CPU for 1ms burst [Q B E F G H]
time 329ms: Process D (tau 17ms) completed a CPU burst; 64 bursts to go [Q B E F G H]
time 329ms: Recalculated tau = 9ms for process D [Q B E F G H]
time 329ms: Process D switching out of CPU; will block on I/O until time 332ms [Q B E F G H]
time 332ms: Process D (tau 9ms) completed I/O; added to ready queue [Q D E F G H]
time 333ms: Process B (tau 2ms) started using the CPU for 1ms burst [Q D E F G H]
time 334ms: Process B (tau 2ms) completed a CPU burst; 63 bursts to go [Q D E F G H]
time 334ms: Recalculated tau = 2ms for process B [Q D E F G H]
time 334ms: Process B switching out of CPU; will block on I/O until time 337ms [Q D E F G H]
time 337ms: Process B (tau 2ms) completed I/O; added to ready queue [Q B E F G H]
time 338ms: Process D (tau 9ms) started using the CPU for 1ms burst [Q B E F G H]
time 339ms: Process D (tau 9ms) completed a CPU burst; 63 bursts to go [Q B E F G H]
time 339ms: Recalculated tau = 5ms for process D [Q B E F G H]
time 339ms: Process D switching out of CPU; will block on I/O until time 342ms [Q B E F G H]
time 342ms: Process D (tau 5ms) completed I/O; added to ready queue [Q D E F G H]
time 343ms: Process B (tau 2ms) started using the CPU for 1ms burst [Q D E F G H]
time 344ms: Process B (tau 2ms) completed a CPU burst; 62 bursts to go [Q D E F G H]
time 344ms: Recalculated tau = 2ms for process B [Q D E F G H]
time 344ms: Process B switching out of CPU; will block on I/O until time 347ms [Q D E F G H]
time 347ms: Process B (tau 2ms) completed I/O; added to ready queue [Q B E F G H]
time 348ms: Process D (tau 5ms) started using the CPU for 1ms burst [Q B E F G H]
time 349ms: Process D (tau 5ms) completed a CPU burst; 62 bursts to go [Q B E F G H]
time 349ms: Recalculated tau = 3ms for process D [Q B E F G H]
time 349ms: Process D switching out of CPU; will block on I/O until time 352ms [Q B E F G H]
time 352ms: Process D (tau 3ms) completed I/O; added to ready queue [Q D E F G H]
time 353ms: Process B (tau 2ms) started using the CPU for 1ms burst [Q D E F G H]
time 354ms: Process B (tau 2ms) completed a CPU burst; 61 bursts to go [Q D E F G H]
time 354ms: Recalculated tau = 2ms for process B [Q D E F G H]
time 354ms: Process B switching out of CPU; will block on I/O until time 357ms [Q D E F G H]
time 357ms: Process B (tau 2ms) completed I/O; added to ready queue [Q B E F G H]
time 358ms: Process D (tau 3ms) started using the CPU for 1ms burst [Q B E F G H]
time 359ms: Process D (tau 3ms) completed a CPU burst; 61 bursts to go [Q B E F G H]
time 359ms: Recalculated tau = 2ms for process D [Q B E F G H]
time 359ms: Process D switching out of CPU; will block on I/O until time 362ms [Q B E F G H]
time 362ms: Process D (tau 2ms) completed I/O; added to ready queue [Q D E F G H]
time 363ms: Process B (tau 2ms) started using the CPU for 1ms burst [Q D E F G H]
time 364ms: Process B (tau 2ms) completed a CPU burst; 60 bursts to go [Q D E F G H]
time 364ms: Recalculated tau = 2ms for process B [Q D E F G H]
time 364ms: Process B switching out of CPU; will block on I/O until time 367ms [Q D E F G H]
time 367ms: Process B (tau 2ms) completed I/O; added to ready queue [Q B E F G H]
time 368ms: Process D (tau 2ms) started using the CPU for 1ms burst [Q B E F G H]
time 369ms: Process D (tau 2ms) completed a CPU burst; 60 bursts to go [Q B E F G H]
time 369ms: Recalculated tau = 2ms for process D [Q B E F G H]
time 369ms: Process D switching out of CPU; will block on I/O until time 372ms [Q B E F G H]
time 372ms: Process D (tau 2ms) completed I/O; added to ready queue [Q D E F G H]
time 373ms: Process B (tau 2ms) started using the CPU for 1ms burst [Q D E F G H]
time 374ms: Process B (tau 2ms) completed a CPU burst; 59 bursts to go [Q D E F G H]
time 374ms: Recalculated tau = 2ms for process B [Q D E F G H]
time 374ms: Process B switching out of CPU; will block on I/O until time 377ms [Q D E F G H]
time 377ms: Process B (tau 2ms) completed I/O; added to ready queue [Q B E F G H]
time 378ms: Process D (tau 2ms) started using the CPU for 1ms burst [Q B E F G H]
time 379ms: Process D (tau 2ms) completed a CPU burst; 59 bursts to go [Q B E F G H]
time 379ms: Recalculated tau = 2ms for process D [Q B E F G H]
time 379ms: Process D switching out of CPU; will block on I/O until time 382ms [Q B E F G H]
time 382ms: Process D (tau 2ms) completed I/O; added to ready queue [Q D E F G H]
time 383ms: Process B (tau 2ms) started using the CPU for 1ms burst [Q D E F G H]
time 384ms: Process B (tau 2ms) completed a CPU burst; 58 bursts to go [Q D E F G H]
time 384ms: Recalculated tau = 2ms for process B [Q D E F G H]
time 384ms: Process B switching out of CPU; will block on I/O until time 387ms [Q D E F G H]
time 387ms: Process B (tau 2ms) completed I/O; added to ready queue [Q B E F G H]
time 388ms: Process D (tau 2ms) started using the CPU for 1ms burst [Q B E F G H]
time 389ms: Process D (tau 2ms) completed a CPU burst; 58 bursts to go [Q B E F G H]
time 389ms: Recalculated tau = 2ms for process D [Q B E F G H]
time 389ms: Process D switching out of CPU; will block on I/O until time 392ms [Q B E F G H]
time 392ms: Process D (tau 2ms) completed I/O; added to ready queue [Q D E F G H]
time 393ms: Process B (tau 2ms) started using the CPU for 1ms burst [Q D E F G H]
time 394ms: Process B (tau 2ms) completed a CPU burst; 57 bursts to go [Q D E F G H]
time 394ms: Recalculated tau = 2ms for process B [Q D E F G H]
time 394ms: Process B switching out of CPU; will block on I/O until time 397ms [Q D E F G H]
time 397ms: Process B (tau 2ms) completed I/O; added to ready queue [Q B E F G H]
time 398ms: Process D (tau 2ms) started using the CPU for 1ms burst [Q B E F G H]
time 399ms: Process D (tau 2ms) completed a CPU burst; 57 bursts to go [Q B E F G H]
time 399ms: Recalculated tau = 2ms for process D [Q B E F G H]
time 399ms: Process D switching out of CPU; will block on I/O until time 402ms [Q B E F G H]
time 402ms: Process D (tau 2ms) completed I/O; added to ready queue [Q D E F G H]
time 403ms: Process B (tau 2ms) started using the CPU for 1ms burst [Q D E F G H]
time 404ms: Process B (tau 2ms) completed a CPU burst; 56 bursts to go [Q D E F G H]
time 404ms: Recalculated tau = 2ms for process B [Q D E F G H]
time 404ms: Process B switching out of CPU; will block on I/O until time 407ms [Q D E F G H]
time 407ms: Process B (tau 2ms) completed I/O; added to ready queue [Q B E F G H]
time 408ms: Process D (tau 2ms) started using the CPU for 1ms burst [Q B E F G H]
time 409ms: Process D (tau 2ms) completed a CPU burst; 56 bursts to go [Q B E F G H]
time 409ms: Recalculated tau = 2ms for process D [Q B E F G H]
time 409ms: Process D switching out of CPU; will block on I/O until time 412ms [Q B E F G H]
time 412ms: Process D (tau 2ms) completed I/O; added to ready queue [Q D E F G H]
time 413ms: Process B (tau 2ms) started using the CPU for 1ms burst [Q D E F G H]
time 414ms: Process B (tau 2ms) completed a CPU burst; 55 bursts to go [Q D E F G H]
time 414ms: Recalculated tau = 2ms for process B [Q D E F G H]
time 414ms: Process B switching out of CPU; will block on I/O until time 417ms [Q D E F G H]
time 417ms: Process B (tau 2ms) completed I/O; added to ready queue [Q B E F G H]
time 418ms: Process D (tau 2ms) started using the CPU for 1ms burst [Q B E F G H]
time 419ms: Process D (tau 2ms) completed a CPU burst; 55 bursts to go [Q B E F G H]
time 419ms: Recalculated tau = 2ms for process D [Q B E F G H]
time 419ms: Process D switching out of CPU; will block on I/O until time 422ms [Q B E F G H]
time 422ms: Process D (tau 2ms) completed I/O; added to ready queue [Q D E F G H]
time 423ms: Process B (tau 2ms) started using the CPU for 1ms burst [Q D E F G H]
time 424ms: Process B (tau 2ms) completed a CPU burst; 54 bursts to go [Q D E F G H]
time 424ms: Recalculated tau = 2ms for process B [Q D E F G H]
time 424ms: Process B switching out of CPU; will block on I/O until time 427ms [Q D E F G H]
time 427ms: Process B (tau 2ms) completed I/O; added to ready queue [Q B E F G H]
time 428ms: Process D (tau 2ms) started using the CPU for 1ms burst [Q B E F G H]
time 429ms: Process D (tau 2ms) completed a CPU burst; 54 bursts to go [Q B E F G H]
time 429ms: Recalculated tau = 2ms for process D [Q B E F G H]
time 429ms: Process D switching out of CPU; will block on I/O until time 432ms [Q B E F G H]
time 432ms: Process D (tau 2ms) completed I/O; added to ready queue [Q D E F G H]
time 433ms: Process B (tau 2ms) started using the CPU for 1ms burst [Q D E F G H]
time 434ms: Process B (tau 2ms) completed a CPU burst; 53 bursts to go [Q D E F G H]
time 434ms: Recalculated tau = 2ms for process B [Q D E F G H]
time 434ms: Process B switching out of CPU; will block on I/O until time 437ms [Q D E F G H]
time 437ms: Process B (tau 2ms) completed I/O; added to ready queue [Q B E F G H]
time 438ms: Process D (tau 2ms) started using the CPU for 1ms burst [Q B E F G H]
time 439ms: Process D (tau 2ms) completed a CPU burst; 53 bursts to go [Q B E F G H]
time 439ms: Recalculated tau = 2ms for process D [Q B E F G H]
time 439ms: Process D switching out of CPU; will block on I/O until time 442ms [Q B E F G H]
time 442ms: Process D (tau 2ms) completed I/O; added to ready queue [Q D E F G H]
time 443ms: Process B (tau 2ms) started using the CPU for 1ms burst [Q D E F G H]
time 444ms: Process B (tau 2ms) completed a CPU burst; 52 bursts to go [Q D E F G H]
time 444ms: Recalculated tau = 2ms for process B [Q D E F G H]
time 444ms: Process B switching out of CPU; will block on I/O until time 447ms [Q D E F G H]
time 447ms: Process B (tau 2ms) completed I/O; added to ready queue [Q B E F G H]
time 448ms: Process D (tau 2ms) started using the CPU for 1ms burst [Q B E F G H]
time 449ms: Process D (tau 2ms) completed a CPU burst; 52 bursts to go [Q B E F G H]
time 449ms: Recalculated tau = 2ms for process D [Q B E F G H]
