Process A [NEW] (arrival time 102 ms) 85 CPU bursts
Process B [NEW] (arrival time 365 ms) 6 CPU bursts
Process C [NEW] (arrival time 246 ms) 95 CPU bursts
Process D [NEW] (arrival time 388 ms) 57 CPU bursts
Process E [NEW] (arrival time 1515 ms) 83 CPU bursts
Process F [NEW] (arrival time 1684 ms) 97 CPU bursts
Process G [NEW] (arrival time 669 ms) 1 CPU burst
Process H [NEW] (arrival time 376 ms) 49 CPU bursts
time 0ms: Simulator started for RR [Q <empty>]
time 102ms: Process A arrived; added to ready queue [Q A]
time 104ms: Process A started using the CPU for 1031ms burst [Q <empty>]
time 246ms: Process C arrived; added to ready queue [Q C]
time 365ms: Process B arrived; added to ready queue [Q C B]
time 376ms: Process H arrived; added to ready queue [Q C B H]
time 388ms: Process D arrived; added to ready queue [Q C B H D]
time 669ms: Process G arrived; added to ready queue [Q C B H D G]
time 1135ms: Process A completed a CPU burst; 84 bursts to go [Q C B H D G]
time 1135ms: Process A switching out of CPU; will block on I/O until time 1547ms [Q C B H D G]
time 1139ms: Process C started using the CPU for 3274ms burst [Q B H D G]
time 1515ms: Process E arrived; added to ready queue [Q B H D G E]
time 3563ms: Time slice expired; process C preempted with 850ms to go [Q B H D G E]
time 3563ms: Process A completed I/O; added to ready queue [Q B H D G E A]
time 1684ms: Process F arrived; added to ready queue [Q B H D G E A C F]
time 3567ms: Process B started using the CPU for 848ms burst [Q H D G E A C F]
time 4415ms: Process B completed a CPU burst; 5 bursts to go [Q H D G E A C F]
time 4415ms: Process B switching out of CPU; will block on I/O until time 5363ms [Q H D G E A C F]
time 4419ms: Process H started using the CPU for 340ms burst [Q D G E A C F]
time 4759ms: Process H completed a CPU burst; 48 bursts to go [Q D G E A C F]
time 4759ms: Process H switching out of CPU; will block on I/O until time 5377ms [Q D G E A C F]
time 4763ms: Process D started using the CPU for 722ms burst [Q G E A C F]
time 5363ms: Process B completed I/O; added to ready queue [Q G E A C F B]
time 5377ms: Process H completed I/O; added to ready queue [Q G E A C F B H]
time 5485ms: Process D completed a CPU burst; 56 bursts to go [Q G E A C F B H]
time 5485ms: Process D switching out of CPU; will block on I/O until time 6575ms [Q G E A C F B H]
time 5489ms: Process G started using the CPU for 543ms burst [Q E A C F B H]
time 6032ms: Process G terminated [Q E A C F B H]
time 6036ms: Process E started using the CPU for 391ms burst [Q A C F B H]
time 6427ms: Process E completed a CPU burst; 82 bursts to go [Q A C F B H]
time 6427ms: Process E switching out of CPU; will block on I/O until time 6990ms [Q A C F B H]
time 6431ms: Process A started using the CPU for 197ms burst [Q C F B H]
time 6575ms: Process D completed I/O; added to ready queue [Q C F B H D]
time 6628ms: Process A completed a CPU burst; 83 bursts to go [Q C F B H D]
time 6628ms: Process A switching out of CPU; will block on I/O until time 7129ms [Q C F B H D]
time 6632ms: Process C started using the CPU with 850ms burst remaining [Q F B H D]
time 6990ms: Process E completed I/O; added to ready queue [Q F B H D E]
time 7129ms: Process A completed I/O; added to ready queue [Q F B H D E A]
time 7482ms: Process C completed a CPU burst; 94 bursts to go [Q F B H D E A]
time 7482ms: Process C switching out of CPU; will block on I/O until time 7574ms [Q F B H D E A]
time 7486ms: Process F started using the CPU for 18ms burst [Q B H D E A]
time 7504ms: Process F completed a CPU burst; 96 bursts to go [Q B H D E A]
time 7504ms: Process F switching out of CPU; will block on I/O until time 9066ms [Q B H D E A]
time 7508ms: Process B started using the CPU for 859ms burst [Q H D E A]
time 7574ms: Process C completed I/O; added to ready queue [Q H D E A C]
time 8367ms: Process B completed a CPU burst; 4 bursts to go [Q H D E A C]
time 8367ms: Process B switching out of CPU; will block on I/O until time 9041ms [Q H D E A C]
time 8371ms: Process H started using the CPU for 264ms burst [Q D E A C]
time 8635ms: Process H completed a CPU burst; 47 bursts to go [Q D E A C]
time 8635ms: Process H switching out of CPU; will block on I/O until time 8774ms [Q D E A C]
time 8639ms: Process D started using the CPU for 293ms burst [Q E A C]
time 8774ms: Process H completed I/O; added to ready queue [Q E A C H]
time 8932ms: Process D completed a CPU burst; 55 bursts to go [Q E A C H]
time 8932ms: Process D switching out of CPU; will block on I/O until time 9247ms [Q E A C H]
time 8936ms: Process E started using the CPU for 1198ms burst [Q A C H]
time 9041ms: Process B completed I/O; added to ready queue [Q A C H B]
time 9066ms: Process F completed I/O; added to ready queue [Q A C H B F]
time 9247ms: Process D completed I/O; added to ready queue [Q A C H B F D]
time 10134ms: Process E completed a CPU burst; 81 bursts to go [Q A C H B F D]
time 10134ms: Process E switching out of CPU; will block on I/O until time 13307ms [Q A C H B F D]
time 10138ms: Process A started using the CPU for 923ms burst [Q C H B F D]
time 11061ms: Process A completed a CPU burst; 82 bursts to go [Q C H B F D]
time 11061ms: Process A switching out of CPU; will block on I/O until time 12925ms [Q C H B F D]
time 11065ms: Process C started using the CPU for 633ms burst [Q H B F D]
time 11698ms: Process C completed a CPU burst; 93 bursts to go [Q H B F D]
time 11698ms: Process C switching out of CPU; will block on I/O until time 11744ms [Q H B F D]
time 11702ms: Process H started using the CPU for 1555ms burst [Q B F D]
time 11744ms: Process C completed I/O; added to ready queue [Q B F D C]
time 12925ms: Process A completed I/O; added to ready queue [Q B F D C A]
time 13257ms: Process H completed a CPU burst; 46 bursts to go [Q B F D C A]
time 13257ms: Process H switching out of CPU; will block on I/O until time 13723ms [Q B F D C A]
time 13261ms: Process B started using the CPU for 2199ms burst [Q F D C A]
time 15355ms: Time slice expired; process B preempted with 105ms to go [Q F D C A E]
time 15355ms: Process E completed I/O; added to ready queue [Q F D C A E E]
time 15357ms: Process H completed I/O; added to ready queue [Q F D C A E E H]
time 15359ms: Process F started using the CPU for 1494ms burst [Q D C A E E H B]
time 16853ms: Process F completed a CPU burst; 95 bursts to go [Q D C A E E H B]
time 16853ms: Process F switching out of CPU; will block on I/O until time 16978ms [Q D C A E E H B]
time 16857ms: Process D started using the CPU for 375ms burst [Q C A E E H B]
time 16978ms: Process F completed I/O; added to ready queue [Q C A E E H B F]
time 17232ms: Process D completed a CPU burst; 54 bursts to go [Q C A E E H B F]
time 17232ms: Process D switching out of CPU; will block on I/O until time 18061ms [Q C A E E H B F]
time 17236ms: Process C started using the CPU for 512ms burst [Q A E E H B F]
time 17748ms: Process C completed a CPU burst; 92 bursts to go [Q A E E H B F]
time 17748ms: Process C switching out of CPU; will block on I/O until time 19342ms [Q A E E H B F]
time 17752ms: Process A started using the CPU for 25ms burst [Q E E H B F]
time 17777ms: Process A completed a CPU burst; 81 bursts to go [Q E E H B F]
time 17777ms: Process A switching out of CPU; will block on I/O until time 18472ms [Q E E H B F]
time 17781ms: Process E started using the CPU for 1339ms burst [Q E H B F]
time 18061ms: Process D completed I/O; added to ready queue [Q E H B F D]
time 18472ms: Process A completed I/O; added to ready queue [Q E H B F D A]
time 19120ms: Process E completed a CPU burst; 80 bursts to go [Q E H B F D A]
time 19120ms: Process E switching out of CPU; will block on I/O until time 20192ms [Q E H B F D A]
time 19124ms: Process E started using the CPU for 1339ms burst [Q H B F D A]
time 19342ms: Process C completed I/O; added to ready queue [Q H B F D A C]
time 20192ms: Process E completed I/O; added to ready queue [Q H B F D A C E]
time 20463ms: Process E completed a CPU burst; 80 bursts to go [Q H B F D A C E]
time 20463ms: Process E switching out of CPU; will block on I/O until time 21630ms [Q H B F D A C E]
time 20467ms: Process H started using the CPU for 2705ms burst [Q B F D A C E]
time 21630ms: Process E completed I/O; added to ready queue [Q B F D A C E E]
time 23172ms: Process H completed a CPU burst; 45 bursts to go [Q B F D A C E E]
time 23172ms: Process H switching out of CPU; will block on I/O until time 23575ms [Q B F D A C E E]
time 23176ms: Process B started using the CPU with 105ms burst remaining [Q F D A C E E]
time 23281ms: Process B completed a CPU burst; 3 bursts to go [Q F D A C E E]
time 23281ms: Process B switching out of CPU; will block on I/O until time 23670ms [Q F D A C E E]
time 23285ms: Process F started using the CPU for 315ms burst [Q D A C E E]
time 23575ms: Process H completed I/O; added to ready queue [Q D A C E E H]
time 23600ms: Process F completed a CPU burst; 94 bursts to go [Q D A C E E H]
time 23600ms: Process F switching out of CPU; will block on I/O until time 24069ms [Q D A C E E H]
time 23604ms: Process D started using the CPU for 245ms burst [Q A C E E H]
time 23670ms: Process B completed I/O; added to ready queue [Q A C E E H B]
time 23849ms: Process D completed a CPU burst; 53 bursts to go [Q A C E E H B]
time 23849ms: Process D switching out of CPU; will block on I/O until time 24155ms [Q A C E E H B]
time 23853ms: Process A started using the CPU for 977ms burst [Q C E E H B]
time 24069ms: Process F completed I/O; added to ready queue [Q C E E H B F]
time 24155ms: Process D completed I/O; added to ready queue [Q C E E H B F D]
time 24830ms: Process A completed a CPU burst; 80 bursts to go [Q C E E H B F D]
time 24830ms: Process A switching out of CPU; will block on I/O until time 25726ms [Q C E E H B F D]
time 24834ms: Process C started using the CPU for 102ms burst [Q E E H B F D]
time 24936ms: Process C completed a CPU burst; 91 bursts to go [Q E E H B F D]
time 24936ms: Process C switching out of CPU; will block on I/O until time 25077ms [Q E E H B F D]
time 24940ms: Process E started using the CPU for 136ms burst [Q E H B F D]
time 25076ms: Process E completed a CPU burst; 79 bursts to go [Q E H B F D]
time 25076ms: Process E switching out of CPU; will block on I/O until time 26243ms [Q E H B F D]
time 25077ms: Process C completed I/O; added to ready queue [Q E H B F D C]
time 25080ms: Process E started using the CPU for 136ms burst [Q H B F D C]
time 25216ms: Process E completed a CPU burst; 79 bursts to go [Q H B F D C]
time 25216ms: Process E switching out of CPU; will block on I/O until time 26276ms [Q H B F D C]
time 25220ms: Process H started using the CPU for 1716ms burst [Q B F D C]
time 25726ms: Process A completed I/O; added to ready queue [Q B F D C A]
time 26243ms: Process E completed I/O; added to ready queue [Q B F D C A E]
time 26276ms: Process E completed I/O; added to ready queue [Q B F D C A E E]
time 26936ms: Process H completed a CPU burst; 44 bursts to go [Q B F D C A E E]
time 26936ms: Process H switching out of CPU; will block on I/O until time 27383ms [Q B F D C A E E]
time 26940ms: Process B started using the CPU for 21ms burst [Q F D C A E E]
time 26961ms: Process B completed a CPU burst; 2 bursts to go [Q F D C A E E]
time 26961ms: Process B switching out of CPU; will block on I/O until time 27150ms [Q F D C A E E]
time 26965ms: Process F started using the CPU for 890ms burst [Q D C A E E]
time 27150ms: Process B completed I/O; added to ready queue [Q D C A E E B]
time 27383ms: Process H completed I/O; added to ready queue [Q D C A E E B H]
time 27855ms: Process F completed a CPU burst; 93 bursts to go [Q D C A E E B H]
time 27855ms: Process F switching out of CPU; will block on I/O until time 28239ms [Q D C A E E B H]
time 27859ms: Process D started using the CPU for 855ms burst [Q C A E E B H]
time 28239ms: Process F completed I/O; added to ready queue [Q C A E E B H F]
time 28714ms: Process D completed a CPU burst; 52 bursts to go [Q C A E E B H F]
time 28714ms: Process D switching out of CPU; will block on I/O until time 31056ms [Q C A E E B H F]
time 28718ms: Process C started using the CPU for 346ms burst [Q A E E B H F]
time 29064ms: Process C completed a CPU burst; 90 bursts to go [Q A E E B H F]
time 29064ms: Process C switching out of CPU; will block on I/O until time 30093ms [Q A E E B H F]
time 29068ms: Process A started using the CPU for 1095ms burst [Q E E B H F]
time 30093ms: Process C completed I/O; added to ready queue [Q E E B H F C]
time 30163ms: Process A completed a CPU burst; 79 bursts to go [Q E E B H F C]
time 30163ms: Process A switching out of CPU; will block on I/O until time 30504ms [Q E E B H F C]
time 30167ms: Process E started using the CPU for 2127ms burst [Q E B H F C]
time 30504ms: Process A completed I/O; added to ready queue [Q E B H F C A]
time 31056ms: Process D completed I/O; added to ready queue [Q E B H F C A D]
time 32294ms: Process E completed a CPU burst; 78 bursts to go [Q E B H F C A D]
time 32294ms: Process E switching out of CPU; will block on I/O until time 33354ms [Q E B H F C A D]
time 32298ms: Process E started using the CPU for 2127ms burst [Q B H F C A D]
time 33354ms: Process E completed I/O; added to ready queue [Q B H F C A D E]
time 34425ms: Process E completed a CPU burst; 78 bursts to go [Q B H F C A D E]
time 34425ms: Process E switching out of CPU; will block on I/O until time 34524ms [Q B H F C A D E]
time 34429ms: Process B started using the CPU for 909ms burst [Q H F C A D E]
time 34524ms: Process E completed I/O; added to ready queue [Q H F C A D E E]
time 35338ms: Process B completed a CPU burst; 1 burst to go [Q H F C A D E E]
time 35338ms: Process B switching out of CPU; will block on I/O until time 37727ms [Q H F C A D E E]
time 35342ms: Process H started using the CPU for 615ms burst [Q F C A D E E]
time 35957ms: Process H completed a CPU burst; 43 bursts to go [Q F C A D E E]
time 35957ms: Process H switching out of CPU; will block on I/O until time 36134ms [Q F C A D E E]
time 35961ms: Process F started using the CPU for 3843ms burst [Q C A D E E]
time 38182ms: Time slice expired; process F preempted with 1622ms to go [Q C A D E E H]
time 38182ms: Process H completed I/O; added to ready queue [Q C A D E E H H]
time 38184ms: Process B completed I/O; added to ready queue [Q C A D E E H H B]
time 38186ms: Process C started using the CPU for 81ms burst [Q A D E E H H B F]
time 38267ms: Process C completed a CPU burst; 89 bursts to go [Q A D E E H H B F]
time 38267ms: Process C switching out of CPU; will block on I/O until time 39515ms [Q A D E E H H B F]
time 38271ms: Process A started using the CPU for 117ms burst [Q D E E H H B F]
time 38388ms: Process A completed a CPU burst; 78 bursts to go [Q D E E H H B F]
time 38388ms: Process A switching out of CPU; will block on I/O until time 40103ms [Q D E E H H B F]
time 38392ms: Process D started using the CPU for 1730ms burst [Q E E H H B F]
time 39515ms: Process C completed I/O; added to ready queue [Q E E H H B F C]
time 40103ms: Process A completed I/O; added to ready queue [Q E E H H B F C A]
time 40122ms: Process D completed a CPU burst; 51 bursts to go [Q E E H H B F C A]
time 40122ms: Process D switching out of CPU; will block on I/O until time 40978ms [Q E E H H B F C A]
time 40126ms: Process E started using the CPU for 351ms burst [Q E H H B F C A]
time 40477ms: Process E completed a CPU burst; 77 bursts to go [Q E H H B F C A]
time 40477ms: Process E switching out of CPU; will block on I/O until time 40576ms [Q E H H B F C A]
time 40481ms: Process E started using the CPU for 351ms burst [Q H H B F C A]
time 40576ms: Process E completed I/O; added to ready queue [Q H H B F C A E]
time 40832ms: Process E completed a CPU burst; 77 bursts to go [Q H H B F C A E]
time 40832ms: Process E switching out of CPU; will block on I/O until time 41885ms [Q H H B F C A E]
time 40836ms: Process H started using the CPU for 828ms burst [Q H B F C A E]
time 40978ms: Process D completed I/O; added to ready queue [Q H B F C A E D]
time 41664ms: Process H completed a CPU burst; 42 bursts to go [Q H B F C A E D]
time 41664ms: Process H switching out of CPU; will block on I/O until time 43505ms [Q H B F C A E D]
time 41668ms: Process H started using the CPU for 828ms burst [Q B F C A E D]
time 41885ms: Process E completed I/O; added to ready queue [Q B F C A E D E]
time 42496ms: Process H completed a CPU burst; 42 bursts to go [Q B F C A E D E]
time 42496ms: Process H switching out of CPU; will block on I/O until time 43165ms [Q B F C A E D E]
time 42500ms: Process B started using the CPU for 70ms burst [Q F C A E D E]
time 42570ms: Process B terminated [Q F C A E D E]
time 42574ms: Process F started using the CPU with 1622ms burst remaining [Q C A E D E]
time 43165ms: Process H completed I/O; added to ready queue [Q C A E D E H]
time 43505ms: Process H completed I/O; added to ready queue [Q C A E D E H H]
time 44196ms: Process F completed a CPU burst; 92 bursts to go [Q C A E D E H H]
time 44196ms: Process F switching out of CPU; will block on I/O until time 46288ms [Q C A E D E H H]
time 44200ms: Process C started using the CPU for 1562ms burst [Q A E D E H H]
time 45762ms: Process C completed a CPU burst; 88 bursts to go [Q A E D E H H]
time 45762ms: Process C switching out of CPU; will block on I/O until time 46253ms [Q A E D E H H]
time 45766ms: Process A started using the CPU for 533ms burst [Q E D E H H]
time 46253ms: Process C completed I/O; added to ready queue [Q E D E H H C]
time 46288ms: Process F completed I/O; added to ready queue [Q E D E H H C F]
time 46299ms: Process A completed a CPU burst; 77 bursts to go [Q E D E H H C F]
time 46299ms: Process A switching out of CPU; will block on I/O until time 46923ms [Q E D E H H C F]
time 46303ms: Process E started using the CPU for 2531ms burst [Q D E H H C F]
time 46923ms: Process A completed I/O; added to ready queue [Q D E H H C F A]
time 48834ms: Process E completed a CPU burst; 76 bursts to go [Q D E H H C F A]
time 48834ms: Process E switching out of CPU; will block on I/O until time 49887ms [Q D E H H C F A]
time 48838ms: Process D started using the CPU for 601ms burst [Q E H H C F A]
time 49439ms: Process D completed a CPU burst; 50 bursts to go [Q E H H C F A]
time 49439ms: Process D switching out of CPU; will block on I/O until time 49677ms [Q E H H C F A]
time 49443ms: Process E started using the CPU for 2531ms burst [Q H H C F A]
time 51725ms: Time slice expired; process E preempted with 249ms to go [Q H H C F A D]
time 51725ms: Process D completed I/O; added to ready queue [Q H H C F A D D]
time 51727ms: Process E completed I/O; added to ready queue [Q H H C F A D D E]
time 51729ms: Process H started using the CPU for 863ms burst [Q H C F A D D E E]
time 52592ms: Process H completed a CPU burst; 41 bursts to go [Q H C F A D D E E]
time 52592ms: Process H switching out of CPU; will block on I/O until time 53293ms [Q H C F A D D E E]
time 52596ms: Process H started using the CPU for 863ms burst [Q C F A D D E E]
time 53293ms: Process H completed I/O; added to ready queue [Q C F A D D E E H]
time 53459ms: Process H completed a CPU burst; 41 bursts to go [Q C F A D D E E H]
time 53459ms: Process H switching out of CPU; will block on I/O until time 54128ms [Q C F A D D E E H]
time 53463ms: Process C started using the CPU for 280ms burst [Q F A D D E E H]
time 53743ms: Process C completed a CPU burst; 87 bursts to go [Q F A D D E E H]
time 53743ms: Process C switching out of CPU; will block on I/O until time 53755ms [Q F A D D E E H]
time 53747ms: Process F started using the CPU for 2701ms burst [Q A D D E E H]
time 55803ms: Time slice expired; process F preempted with 645ms to go [Q A D D E E H C]
time 55803ms: Process C completed I/O; added to ready queue [Q A D D E E H C C]
time 55805ms: Process H completed I/O; added to ready queue [Q A D D E E H C C H]
time 55807ms: Process A started using the CPU for 274ms burst [Q D D E E H C C H F]
time 56081ms: Process A completed a CPU burst; 76 bursts to go [Q D D E E H C C H F]
time 56081ms: Process A switching out of CPU; will block on I/O until time 58440ms [Q D D E E H C C H F]
time 56085ms: Process D started using the CPU for 2089ms burst [Q D E E H C C H F]
time 58133ms: Time slice expired; process D preempted with 41ms to go [Q D E E H C C H F]
time 58137ms: Process D started using the CPU for 2089ms burst [Q E E H C C H F D]
time 58440ms: Process A completed I/O; added to ready queue [Q E E H C C H F D A]
time 60226ms: Process D completed a CPU burst; 49 bursts to go [Q E E H C C H F D A]
time 60226ms: Process D switching out of CPU; will block on I/O until time 61271ms [Q E E H C C H F D A]
time 60230ms: Process E started using the CPU for 2079ms burst [Q E H C C H F D A]
time 61271ms: Process D completed I/O; added to ready queue [Q E H C C H F D A D]
time 62309ms: Process E completed a CPU burst; 75 bursts to go [Q E H C C H F D A D]
time 62309ms: Process E switching out of CPU; will block on I/O until time 63380ms [Q E H C C H F D A D]
time 62313ms: Process E started using the CPU with 249ms burst remaining [Q H C C H F D A D]
time 62562ms: Process E completed a CPU burst; 76 bursts to go [Q H C C H F D A D]
time 62562ms: Process E switching out of CPU; will block on I/O until time 63633ms [Q H C C H F D A D]
time 62566ms: Process H started using the CPU for 64ms burst [Q C C H F D A D]
time 62630ms: Process H completed a CPU burst; 40 bursts to go [Q C C H F D A D]
time 62630ms: Process H switching out of CPU; will block on I/O until time 63073ms [Q C C H F D A D]
time 62634ms: Process C started using the CPU for 348ms burst [Q C H F D A D]
time 62982ms: Process C completed a CPU burst; 86 bursts to go [Q C H F D A D]
time 62982ms: Process C switching out of CPU; will block on I/O until time 63940ms [Q C H F D A D]
time 62986ms: Process C started using the CPU for 348ms burst [Q H F D A D]
time 63073ms: Process H completed I/O; added to ready queue [Q H F D A D H]
time 63334ms: Process C completed a CPU burst; 86 bursts to go [Q H F D A D H]
time 63334ms: Process C switching out of CPU; will block on I/O until time 63349ms [Q H F D A D H]
time 63338ms: Process H started using the CPU for 64ms burst [Q F D A D H]
time 63349ms: Process C completed I/O; added to ready queue [Q F D A D H C]
time 63380ms: Process E completed I/O; added to ready queue [Q F D A D H C E]
time 63402ms: Process H completed a CPU burst; 40 bursts to go [Q F D A D H C E]
time 63402ms: Process H switching out of CPU; will block on I/O until time 64103ms [Q F D A D H C E]
time 63406ms: Process F started using the CPU with 645ms burst remaining [Q D A D H C E]
time 63633ms: Process E completed I/O; added to ready queue [Q D A D H C E E]
time 63940ms: Process C completed I/O; added to ready queue [Q D A D H C E E C]
time 64051ms: Process F completed a CPU burst; 91 bursts to go [Q D A D H C E E C]
time 64051ms: Process F switching out of CPU; will block on I/O until time 67664ms [Q D A D H C E E C]
time 64055ms: Process D started using the CPU with 41ms burst remaining [Q A D H C E E C]
time 64096ms: Process D completed a CPU burst; 49 bursts to go [Q A D H C E E C]
time 64096ms: Process D switching out of CPU; will block on I/O until time 64320ms [Q A D H C E E C]
time 64100ms: Process A started using the CPU for 562ms burst [Q D H C E E C]
time 64103ms: Process H completed I/O; added to ready queue [Q D H C E E C H]
time 64320ms: Process D completed I/O; added to ready queue [Q D H C E E C H D]
time 64662ms: Process A completed a CPU burst; 75 bursts to go [Q D H C E E C H D]
time 64662ms: Process A switching out of CPU; will block on I/O until time 67301ms [Q D H C E E C H D]
time 64666ms: Process D started using the CPU for 432ms burst [Q H C E E C H D]
time 65098ms: Process D completed a CPU burst; 48 bursts to go [Q H C E E C H D]
time 65098ms: Process D switching out of CPU; will block on I/O until time 65496ms [Q H C E E C H D]
time 65102ms: Process H started using the CPU for 1329ms burst [Q C E E C H D]
time 65496ms: Process D completed I/O; added to ready queue [Q C E E C H D D]
time 66431ms: Process H completed a CPU burst; 39 bursts to go [Q C E E C H D D]
time 66431ms: Process H switching out of CPU; will block on I/O until time 66774ms [Q C E E C H D D]
time 66435ms: Process C started using the CPU for 849ms burst [Q E E C H D D]
time 66774ms: Process H completed I/O; added to ready queue [Q E E C H D D H]
time 67284ms: Process C completed a CPU burst; 85 bursts to go [Q E E C H D D H]
time 67284ms: Process C switching out of CPU; will block on I/O until time 67621ms [Q E E C H D D H]
time 67288ms: Process E started using the CPU for 466ms burst [Q E C H D D H]
time 67301ms: Process A completed I/O; added to ready queue [Q E C H D D H A]
time 67621ms: Process C completed I/O; added to ready queue [Q E C H D D H A C]
time 67664ms: Process F completed I/O; added to ready queue [Q E C H D D H A C F]
time 67754ms: Process E completed a CPU burst; 74 bursts to go [Q E C H D D H A C F]
time 67754ms: Process E switching out of CPU; will block on I/O until time 69056ms [Q E C H D D H A C F]
time 67758ms: Process E started using the CPU for 2079ms burst [Q C H D D H A C F]
time 69056ms: Process E completed I/O; added to ready queue [Q C H D D H A C F E]
time 69837ms: Process E completed a CPU burst; 75 bursts to go [Q C H D D H A C F E]
time 69837ms: Process E switching out of CPU; will block on I/O until time 71139ms [Q C H D D H A C F E]
time 69841ms: Process C started using the CPU for 849ms burst [Q H D D H A C F E]
time 70690ms: Process C completed a CPU burst; 85 bursts to go [Q H D D H A C F E]
time 70690ms: Process C switching out of CPU; will block on I/O until time 70705ms [Q H D D H A C F E]
time 70694ms: Process H started using the CPU for 1329ms burst [Q D D H A C F E]
time 70705ms: Process C completed I/O; added to ready queue [Q D D H A C F E C]
time 71139ms: Process E completed I/O; added to ready queue [Q D D H A C F E C E]
time 72023ms: Process H completed a CPU burst; 39 bursts to go [Q D D H A C F E C E]
time 72023ms: Process H switching out of CPU; will block on I/O until time 72466ms [Q D D H A C F E C E]
time 72027ms: Process D started using the CPU for 432ms burst [Q D H A C F E C E]
time 72459ms: Process D completed a CPU burst; 48 bursts to go [Q D H A C F E C E]
time 72459ms: Process D switching out of CPU; will block on I/O until time 73504ms [Q D H A C F E C E]
time 72463ms: Process D started using the CPU for 812ms burst [Q H A C F E C E]
time 72466ms: Process H completed I/O; added to ready queue [Q H A C F E C E H]
time 73275ms: Process D completed a CPU burst; 47 bursts to go [Q H A C F E C E H]
time 73275ms: Process D switching out of CPU; will block on I/O until time 74202ms [Q H A C F E C E H]
time 73279ms: Process H started using the CPU for 2061ms burst [Q A C F E C E H]
time 73504ms: Process D completed I/O; added to ready queue [Q A C F E C E H D]
time 74202ms: Process D completed I/O; added to ready queue [Q A C F E C E H D D]
time 75340ms: Process H completed a CPU burst; 38 bursts to go [Q A C F E C E H D D]
time 75340ms: Process H switching out of CPU; will block on I/O until time 75369ms [Q A C F E C E H D D]
time 75344ms: Process A started using the CPU for 2553ms burst [Q C F E C E H D D]
time 77417ms: Time slice expired; process A preempted with 480ms to go [Q C F E C E H D D H]
time 77417ms: Process H completed I/O; added to ready queue [Q C F E C E H D D H H]
time 77421ms: Process C started using the CPU for 238ms burst [Q F E C E H D D H H A]
time 77659ms: Process C completed a CPU burst; 84 bursts to go [Q F E C E H D D H H A]
time 77659ms: Process C switching out of CPU; will block on I/O until time 78458ms [Q F E C E H D D H H A]
time 77663ms: Process F started using the CPU for 259ms burst [Q E C E H D D H H A]
time 77922ms: Process F completed a CPU burst; 90 bursts to go [Q E C E H D D H H A]
time 77922ms: Process F switching out of CPU; will block on I/O until time 78688ms [Q E C E H D D H H A]
time 77926ms: Process E started using the CPU for 564ms burst [Q C E H D D H H A]
time 78458ms: Process C completed I/O; added to ready queue [Q C E H D D H H A C]
time 78490ms: Process E completed a CPU burst; 73 bursts to go [Q C E H D D H H A C]
time 78490ms: Process E switching out of CPU; will block on I/O until time 80134ms [Q C E H D D H H A C]
time 78494ms: Process C started using the CPU for 238ms burst [Q E H D D H H A C]
time 78688ms: Process F completed I/O; added to ready queue [Q E H D D H H A C F]
time 78732ms: Process C completed a CPU burst; 84 bursts to go [Q E H D D H H A C F]
time 78732ms: Process C switching out of CPU; will block on I/O until time 79069ms [Q E H D D H H A C F]
time 78736ms: Process E started using the CPU for 466ms burst [Q H D D H H A C F]
time 79069ms: Process C completed I/O; added to ready queue [Q H D D H H A C F C]
time 79202ms: Process E completed a CPU burst; 74 bursts to go [Q H D D H H A C F C]
time 79202ms: Process E switching out of CPU; will block on I/O until time 80846ms [Q H D D H H A C F C]
time 79206ms: Process H started using the CPU for 2061ms burst [Q D D H H A C F C]
time 80134ms: Process E completed I/O; added to ready queue [Q D D H H A C F C E]
time 80846ms: Process E completed I/O; added to ready queue [Q D D H H A C F C E E]
time 81267ms: Process H completed a CPU burst; 38 bursts to go [Q D D H H A C F C E E]
time 81267ms: Process H switching out of CPU; will block on I/O until time 81610ms [Q D D H H A C F C E E]
time 81271ms: Process D started using the CPU for 812ms burst [Q D H H A C F C E E]
time 81610ms: Process H completed I/O; added to ready queue [Q D H H A C F C E E H]
time 82083ms: Process D completed a CPU burst; 47 bursts to go [Q D H H A C F C E E H]
time 82083ms: Process D switching out of CPU; will block on I/O until time 82481ms [Q D H H A C F C E E H]
time 82087ms: Process D started using the CPU for 1501ms burst [Q H H A C F C E E H]
time 82481ms: Process D completed I/O; added to ready queue [Q H H A C F C E E H D]
time 83588ms: Process D completed a CPU burst; 46 bursts to go [Q H H A C F C E E H D]
time 83588ms: Process D switching out of CPU; will block on I/O until time 83772ms [Q H H A C F C E E H D]
time 83592ms: Process H started using the CPU for 1088ms burst [Q H A C F C E E H D]
time 83772ms: Process D completed I/O; added to ready queue [Q H A C F C E E H D D]
time 84680ms: Process H completed a CPU burst; 37 bursts to go [Q H A C F C E E H D D]
time 84680ms: Process H switching out of CPU; will block on I/O until time 86062ms [Q H A C F C E E H D D]
time 84684ms: Process H started using the CPU for 1088ms burst [Q A C F C E E H D D]
time 85772ms: Process H completed a CPU burst; 37 bursts to go [Q A C F C E E H D D]
time 85772ms: Process H switching out of CPU; will block on I/O until time 86766ms [Q A C F C E E H D D]
time 85776ms: Process A started using the CPU with 480ms burst remaining [Q C F C E E H D D]
time 86062ms: Process H completed I/O; added to ready queue [Q C F C E E H D D H]
time 86256ms: Process A completed a CPU burst; 74 bursts to go [Q C F C E E H D D H]
time 86256ms: Process A switching out of CPU; will block on I/O until time 86398ms [Q C F C E E H D D H]
time 86260ms: Process C started using the CPU for 1698ms burst [Q F C E E H D D H]
time 86398ms: Process A completed I/O; added to ready queue [Q F C E E H D D H A]
time 86766ms: Process H completed I/O; added to ready queue [Q F C E E H D D H A H]
time 87958ms: Process C completed a CPU burst; 83 bursts to go [Q F C E E H D D H A H]
time 87958ms: Process C switching out of CPU; will block on I/O until time 88298ms [Q F C E E H D D H A H]
time 87962ms: Process F started using the CPU for 588ms burst [Q C E E H D D H A H]
time 88298ms: Process C completed I/O; added to ready queue [Q C E E H D D H A H C]
time 88550ms: Process F completed a CPU burst; 89 bursts to go [Q C E E H D D H A H C]
time 88550ms: Process F switching out of CPU; will block on I/O until time 89625ms [Q C E E H D D H A H C]
time 88554ms: Process C started using the CPU for 1698ms burst [Q E E H D D H A H C]
time 89625ms: Process F completed I/O; added to ready queue [Q E E H D D H A H C F]
time 90252ms: Process C completed a CPU burst; 83 bursts to go [Q E E H D D H A H C F]
time 90252ms: Process C switching out of CPU; will block on I/O until time 91051ms [Q E E H D D H A H C F]
time 90256ms: Process E started using the CPU for 1518ms burst [Q E H D D H A H C F]
time 91051ms: Process C completed I/O; added to ready queue [Q E H D D H A H C F C]
time 91774ms: Process E completed a CPU burst; 72 bursts to go [Q E H D D H A H C F C]
time 91774ms: Process E switching out of CPU; will block on I/O until time 92440ms [Q E H D D H A H C F C]
time 91778ms: Process E started using the CPU for 564ms burst [Q H D D H A H C F C]
time 92342ms: Process E completed a CPU burst; 73 bursts to go [Q H D D H A H C F C]
time 92342ms: Process E switching out of CPU; will block on I/O until time 93008ms [Q H D D H A H C F C]
time 92346ms: Process H started using the CPU for 1088ms burst [Q D D H A H C F C]
time 92440ms: Process E completed I/O; added to ready queue [Q D D H A H C F C E]
time 93008ms: Process E completed I/O; added to ready queue [Q D D H A H C F C E E]
time 93434ms: Process H completed a CPU burst; 37 bursts to go [Q D D H A H C F C E E]
time 93434ms: Process H switching out of CPU; will block on I/O until time 93463ms [Q D D H A H C F C E E]
time 93438ms: Process D started using the CPU for 1501ms burst [Q D H A H C F C E E]
time 93463ms: Process H completed I/O; added to ready queue [Q D H A H C F C E E H]
time 94939ms: Process D completed a CPU burst; 46 bursts to go [Q D H A H C F C E E H]
time 94939ms: Process D switching out of CPU; will block on I/O until time 95866ms [Q D H A H C F C E E H]
time 94943ms: Process D started using the CPU for 1717ms burst [Q H A H C F C E E H]
time 95866ms: Process D completed I/O; added to ready queue [Q H A H C F C E E H D]
time 96660ms: Process D completed a CPU burst; 45 bursts to go [Q H A H C F C E E H D]
time 96660ms: Process D switching out of CPU; will block on I/O until time 97021ms [Q H A H C F C E E H D]
time 96664ms: Process H started using the CPU for 92ms burst [Q A H C F C E E H D]
time 96756ms: Process H completed a CPU burst; 36 bursts to go [Q A H C F C E E H D]
time 96756ms: Process H switching out of CPU; will block on I/O until time 97750ms [Q A H C F C E E H D]
time 96760ms: Process A started using the CPU for 1023ms burst [Q H C F C E E H D]
time 97021ms: Process D completed I/O; added to ready queue [Q H C F C E E H D D]
time 97750ms: Process H completed I/O; added to ready queue [Q H C F C E E H D D H]
time 97783ms: Process A completed a CPU burst; 73 bursts to go [Q H C F C E E H D D H]
time 97783ms: Process A switching out of CPU; will block on I/O until time 98799ms [Q H C F C E E H D D H]
time 97787ms: Process H started using the CPU for 92ms burst [Q C F C E E H D D H]
time 97879ms: Process H completed a CPU burst; 36 bursts to go [Q C F C E E H D D H]
time 97879ms: Process H switching out of CPU; will block on I/O until time 98369ms [Q C F C E E H D D H]
time 97883ms: Process C started using the CPU for 1563ms burst [Q F C E E H D D H]
time 98369ms: Process H completed I/O; added to ready queue [Q F C E E H D D H H]
time 98799ms: Process A completed I/O; added to ready queue [Q F C E E H D D H H A]
time 99446ms: Process C completed a CPU burst; 82 bursts to go [Q F C E E H D D H H A]
time 99446ms: Process C switching out of CPU; will block on I/O until time 101133ms [Q F C E E H D D H H A]
time 99450ms: Process F started using the CPU for 1774ms burst [Q C E E H D D H H A]
time 101133ms: Process C completed I/O; added to ready queue [Q C E E H D D H H A C]
time 101224ms: Process F completed a CPU burst; 88 bursts to go [Q C E E H D D H H A C]
time 101224ms: Process F switching out of CPU; will block on I/O until time 101263ms [Q C E E H D D H H A C]
time 101228ms: Process C started using the CPU for 1563ms burst [Q E E H D D H H A C]
time 101263ms: Process F completed I/O; added to ready queue [Q E E H D D H H A C F]
time 102791ms: Process C completed a CPU burst; 82 bursts to go [Q E E H D D H H A C F]
time 102791ms: Process C switching out of CPU; will block on I/O until time 103131ms [Q E E H D D H H A C F]
time 102795ms: Process E started using the CPU for 740ms burst [Q E H D D H H A C F]
time 103131ms: Process C completed I/O; added to ready queue [Q E H D D H H A C F C]
time 103535ms: Process E completed a CPU burst; 71 bursts to go [Q E H D D H H A C F C]
time 103535ms: Process E switching out of CPU; will block on I/O until time 104236ms [Q E H D D H H A C F C]
time 103539ms: Process E started using the CPU for 1518ms burst [Q H D D H H A C F C]
time 104236ms: Process E completed I/O; added to ready queue [Q H D D H H A C F C E]
time 105057ms: Process E completed a CPU burst; 72 bursts to go [Q H D D H H A C F C E]
time 105057ms: Process E switching out of CPU; will block on I/O until time 105758ms [Q H D D H H A C F C E]
time 105061ms: Process H started using the CPU for 92ms burst [Q D D H H A C F C E]
time 105153ms: Process H completed a CPU burst; 36 bursts to go [Q D D H H A C F C E]
time 105153ms: Process H switching out of CPU; will block on I/O until time 106535ms [Q D D H H A C F C E]
time 105157ms: Process D started using the CPU for 1717ms burst [Q D H H A C F C E]
time 105758ms: Process E completed I/O; added to ready queue [Q D H H A C F C E E]
time 106535ms: Process H completed I/O; added to ready queue [Q D H H A C F C E E H]
time 106874ms: Process D completed a CPU burst; 45 bursts to go [Q D H H A C F C E E H]
time 106874ms: Process D switching out of CPU; will block on I/O until time 107058ms [Q D H H A C F C E E H]
time 106878ms: Process D started using the CPU for 1319ms burst [Q H H A C F C E E H]
time 107058ms: Process D completed I/O; added to ready queue [Q H H A C F C E E H D]
time 108197ms: Process D completed a CPU burst; 44 bursts to go [Q H H A C F C E E H D]
time 108197ms: Process D switching out of CPU; will block on I/O until time 109518ms [Q H H A C F C E E H D]
time 108201ms: Process H started using the CPU for 769ms burst [Q H A C F C E E H D]
time 108970ms: Process H completed a CPU burst; 35 bursts to go [Q H A C F C E E H D]
time 108970ms: Process H switching out of CPU; will block on I/O until time 109460ms [Q H A C F C E E H D]
time 108974ms: Process H started using the CPU for 769ms burst [Q A C F C E E H D]
time 109460ms: Process H completed I/O; added to ready queue [Q A C F C E E H D H]
time 109518ms: Process D completed I/O; added to ready queue [Q A C F C E E H D H D]
time 109743ms: Process H completed a CPU burst; 35 bursts to go [Q A C F C E E H D H D]
time 109743ms: Process H switching out of CPU; will block on I/O until time 111225ms [Q A C F C E E H D H D]
time 109747ms: Process A started using the CPU for 319ms burst [Q C F C E E H D H D]
time 110066ms: Process A completed a CPU burst; 72 bursts to go [Q C F C E E H D H D]
time 110066ms: Process A switching out of CPU; will block on I/O until time 110306ms [Q C F C E E H D H D]
time 110070ms: Process C started using the CPU for 1428ms burst [Q F C E E H D H D]
time 110306ms: Process A completed I/O; added to ready queue [Q F C E E H D H D A]
time 111225ms: Process H completed I/O; added to ready queue [Q F C E E H D H D A H]
time 111498ms: Process C completed a CPU burst; 81 bursts to go [Q F C E E H D H D A H]
time 111498ms: Process C switching out of CPU; will block on I/O until time 112277ms [Q F C E E H D H D A H]
time 111502ms: Process F started using the CPU for 902ms burst [Q C E E H D H D A H]
time 112277ms: Process C completed I/O; added to ready queue [Q C E E H D H D A H C]
time 112404ms: Process F completed a CPU burst; 87 bursts to go [Q C E E H D H D A H C]
time 112404ms: Process F switching out of CPU; will block on I/O until time 112696ms [Q C E E H D H D A H C]
time 112408ms: Process C started using the CPU for 1428ms burst [Q E E H D H D A H C]
time 112696ms: Process F completed I/O; added to ready queue [Q E E H D H D A H C F]
time 113836ms: Process C completed a CPU burst; 81 bursts to go [Q E E H D H D A H C F]
time 113836ms: Process C switching out of CPU; will block on I/O until time 115523ms [Q E E H D H D A H C F]
time 113840ms: Process E started using the CPU for 420ms burst [Q E H D H D A H C F]
time 114260ms: Process E completed a CPU burst; 70 bursts to go [Q E H D H D A H C F]
time 114260ms: Process E switching out of CPU; will block on I/O until time 114582ms [Q E H D H D A H C F]
time 114264ms: Process E started using the CPU for 740ms burst [Q H D H D A H C F]
time 114582ms: Process E completed I/O; added to ready queue [Q H D H D A H C F E]
time 115004ms: Process E completed a CPU burst; 71 bursts to go [Q H D H D A H C F E]
time 115004ms: Process E switching out of CPU; will block on I/O until time 115326ms [Q H D H D A H C F E]
time 115008ms: Process H started using the CPU for 769ms burst [Q D H D A H C F E]
time 115326ms: Process E completed I/O; added to ready queue [Q D H D A H C F E E]
time 115523ms: Process C completed I/O; added to ready queue [Q D H D A H C F E E C]
time 115777ms: Process H completed a CPU burst; 35 bursts to go [Q D H D A H C F E E C]
time 115777ms: Process H switching out of CPU; will block on I/O until time 116771ms [Q D H D A H C F E E C]
time 115781ms: Process D started using the CPU for 1319ms burst [Q H D A H C F E E C]
time 116771ms: Process H completed I/O; added to ready queue [Q H D A H C F E E C H]
time 117100ms: Process D completed a CPU burst; 44 bursts to go [Q H D A H C F E E C H]
time 117100ms: Process D switching out of CPU; will block on I/O until time 117461ms [Q H D A H C F E E C H]
time 117104ms: Process H started using the CPU for 2270ms burst [Q D A H C F E E C H]
time 117461ms: Process D completed I/O; added to ready queue [Q D A H C F E E C H D]
time 119374ms: Process H completed a CPU burst; 34 bursts to go [Q D A H C F E E C H D]
time 119374ms: Process H switching out of CPU; will block on I/O until time 120856ms [Q D A H C F E E C H D]
time 119378ms: Process D started using the CPU for 2816ms burst [Q A H C F E E C H D]
time 120856ms: Process H completed I/O; added to ready queue [Q A H C F E E C H D H]
time 122194ms: Process D completed a CPU burst; 43 bursts to go [Q A H C F E E C H D H]
time 122194ms: Process D switching out of CPU; will block on I/O until time 122808ms [Q A H C F E E C H D H]
time 122198ms: Process A started using the CPU for 1872ms burst [Q H C F E E C H D H]
time 122808ms: Process D completed I/O; added to ready queue [Q H C F E E C H D H D]
time 124070ms: Process A completed a CPU burst; 71 bursts to go [Q H C F E E C H D H D]
time 124070ms: Process A switching out of CPU; will block on I/O until time 125413ms [Q H C F E E C H D H D]
time 124074ms: Process H started using the CPU for 2270ms burst [Q C F E E C H D H D]
time 125413ms: Process A completed I/O; added to ready queue [Q C F E E C H D H D A]
time 126344ms: Process H completed a CPU burst; 34 bursts to go [Q C F E E C H D H D A]
time 126344ms: Process H switching out of CPU; will block on I/O until time 126688ms [Q C F E E C H D H D A]
time 126348ms: Process C started using the CPU for 1761ms burst [Q F E E C H D H D A]
time 126688ms: Process H completed I/O; added to ready queue [Q F E E C H D H D A H]
time 128109ms: Process C completed a CPU burst; 80 bursts to go [Q F E E C H D H D A H]
time 128109ms: Process C switching out of CPU; will block on I/O until time 128516ms [Q F E E C H D H D A H]
time 128113ms: Process F started using the CPU for 806ms burst [Q E E C H D H D A H]
time 128516ms: Process C completed I/O; added to ready queue [Q E E C H D H D A H C]
time 128919ms: Process F completed a CPU burst; 86 bursts to go [Q E E C H D H D A H C]
time 128919ms: Process F switching out of CPU; will block on I/O until time 129150ms [Q E E C H D H D A H C]
time 128923ms: Process E started using the CPU for 1497ms burst [Q E C H D H D A H C]
time 129150ms: Process F completed I/O; added to ready queue [Q E C H D H D A H C F]
time 130420ms: Process E completed a CPU burst; 69 bursts to go [Q E C H D H D A H C F]
time 130420ms: Process E switching out of CPU; will block on I/O until time 130913ms [Q E C H D H D A H C F]
time 130424ms: Process E started using the CPU for 420ms burst [Q C H D H D A H C F]
time 130844ms: Process E completed a CPU burst; 70 bursts to go [Q C H D H D A H C F]
time 130844ms: Process E switching out of CPU; will block on I/O until time 131337ms [Q C H D H D A H C F]
time 130848ms: Process C started using the CPU for 1761ms burst [Q H D H D A H C F]
time 130913ms: Process E completed I/O; added to ready queue [Q H D H D A H C F E]
time 131337ms: Process E completed I/O; added to ready queue [Q H D H D A H C F E E]
time 132609ms: Process C completed a CPU burst; 80 bursts to go [Q H D H D A H C F E E]
time 132609ms: Process C switching out of CPU; will block on I/O until time 133388ms [Q H D H D A H C F E E]
time 132613ms: Process H started using the CPU for 2270ms burst [Q D H D A H C F E E]
time 133388ms: Process C completed I/O; added to ready queue [Q D H D A H C F E E C]
time 134883ms: Process H completed a CPU burst; 34 bursts to go [Q D H D A H C F E E C]
time 134883ms: Process H switching out of CPU; will block on I/O until time 135373ms [Q D H D A H C F E E C]
time 134887ms: Process D started using the CPU for 2816ms burst [Q H D A H C F E E C]
time 137421ms: Time slice expired; process D preempted with 282ms to go [Q H D A H C F E E C H]
time 137421ms: Process H completed I/O; added to ready queue [Q H D A H C F E E C H H]
time 137425ms: Process H started using the CPU for 2381ms burst [Q D A H C F E E C H H D]
time 139473ms: Time slice expired; process H preempted with 333ms to go [Q D A H C F E E C H H D]
time 139477ms: Process D started using the CPU for 2717ms burst [Q A H C F E E C H H D H]
time 141525ms: Time slice expired; process D preempted with 669ms to go [Q A H C F E E C H H D H]
time 141529ms: Process A started using the CPU for 1788ms burst [Q H C F E E C H H D H D]
time 143317ms: Process A completed a CPU burst; 70 bursts to go [Q H C F E E C H H D H D]
time 143317ms: Process A switching out of CPU; will block on I/O until time 143469ms [Q H C F E E C H H D H D]
time 143321ms: Process H started using the CPU for 2381ms burst [Q C F E E C H H D H D]
time 145517ms: Time slice expired; process H preempted with 185ms to go [Q C F E E C H H D H D A]
time 145517ms: Process A completed I/O; added to ready queue [Q C F E E C H H D H D A A]
time 145521ms: Process C started using the CPU for 1852ms burst [Q F E E C H H D H D A A H]
time 147373ms: Process C completed a CPU burst; 79 bursts to go [Q F E E C H H D H D A A H]
time 147373ms: Process C switching out of CPU; will block on I/O until time 148158ms [Q F E E C H H D H D A A H]
time 147377ms: Process F started using the CPU for 21ms burst [Q E E C H H D H D A A H]
time 147398ms: Process F completed a CPU burst; 85 bursts to go [Q E E C H H D H D A A H]
time 147398ms: Process F switching out of CPU; will block on I/O until time 148524ms [Q E E C H H D H D A A H]
time 147402ms: Process E started using the CPU for 985ms burst [Q E C H H D H D A A H]
time 148158ms: Process C completed I/O; added to ready queue [Q E C H H D H D A A H C]
time 148387ms: Process E completed a CPU burst; 68 bursts to go [Q E C H H D H D A A H C]
time 148387ms: Process E switching out of CPU; will block on I/O until time 148499ms [Q E C H H D H D A A H C]
time 148391ms: Process E started using the CPU for 1497ms burst [Q C H H D H D A A H C]
time 148499ms: Process E completed I/O; added to ready queue [Q C H H D H D A A H C E]
time 148524ms: Process F completed I/O; added to ready queue [Q C H H D H D A A H C E F]
time 149888ms: Process E completed a CPU burst; 69 bursts to go [Q C H H D H D A A H C E F]
time 149888ms: Process E switching out of CPU; will block on I/O until time 150000ms [Q C H H D H D A A H C E F]
time 149892ms: Process C started using the CPU for 1852ms burst [Q H H D H D A A H C E F]
time 150000ms: Process E completed I/O; added to ready queue [Q H H D H D A A H C E F E]
time 151744ms: Process C completed a CPU burst; 79 bursts to go [Q H H D H D A A H C E F E]
time 151744ms: Process C switching out of CPU; will block on I/O until time 152151ms [Q H H D H D A A H C E F E]
time 151748ms: Process H started using the CPU for 2381ms burst [Q H D H D A A H C E F E]
time 152151ms: Process C completed I/O; added to ready queue [Q H D H D A A H C E F E C]
time 154129ms: Process H completed a CPU burst; 33 bursts to go [Q H D H D A A H C E F E C]
time 154129ms: Process H switching out of CPU; will block on I/O until time 155611ms [Q H D H D A A H C E F E C]
time 154133ms: Process H started using the CPU for 2381ms burst [Q D H D A A H C E F E C]
time 155611ms: Process H completed I/O; added to ready queue [Q D H D A A H C E F E C H]
time 156514ms: Process H completed a CPU burst; 33 bursts to go [Q D H D A A H C E F E C H]
time 156514ms: Process H switching out of CPU; will block on I/O until time 156858ms [Q D H D A A H C E F E C H]
time 156518ms: Process D started using the CPU with 282ms burst remaining [Q H D A A H C E F E C H]
time 156800ms: Process D completed a CPU burst; 43 bursts to go [Q H D A A H C E F E C H]
time 156800ms: Process D switching out of CPU; will block on I/O until time 158121ms [Q H D A A H C E F E C H]
time 156804ms: Process H started using the CPU with 333ms burst remaining [Q D A A H C E F E C H]
time 156858ms: Process H completed I/O; added to ready queue [Q D A A H C E F E C H H]
time 157137ms: Process H completed a CPU burst; 33 bursts to go [Q D A A H C E F E C H H]
time 157137ms: Process H switching out of CPU; will block on I/O until time 157481ms [Q D A A H C E F E C H H]
time 157141ms: Process D started using the CPU with 669ms burst remaining [Q A A H C E F E C H H]
time 157481ms: Process H completed I/O; added to ready queue [Q A A H C E F E C H H H]
time 157810ms: Process D completed a CPU burst; 42 bursts to go [Q A A H C E F E C H H H]
time 157810ms: Process D switching out of CPU; will block on I/O until time 159057ms [Q A A H C E F E C H H H]
time 157814ms: Process A started using the CPU for 313ms burst [Q A H C E F E C H H H]
time 158121ms: Process D completed I/O; added to ready queue [Q A H C E F E C H H H D]
time 158127ms: Process A completed a CPU burst; 69 bursts to go [Q A H C E F E C H H H D]
time 158127ms: Process A switching out of CPU; will block on I/O until time 158210ms [Q A H C E F E C H H H D]
time 158131ms: Process A started using the CPU for 313ms burst [Q H C E F E C H H H D]
time 158210ms: Process A completed I/O; added to ready queue [Q H C E F E C H H H D A]
time 158444ms: Process A completed a CPU burst; 69 bursts to go [Q H C E F E C H H H D A]
time 158444ms: Process A switching out of CPU; will block on I/O until time 158596ms [Q H C E F E C H H H D A]
time 158448ms: Process H started using the CPU with 185ms burst remaining [Q C E F E C H H H D A]
time 158596ms: Process A completed I/O; added to ready queue [Q C E F E C H H H D A A]
time 158633ms: Process H completed a CPU burst; 33 bursts to go [Q C E F E C H H H D A A]
time 158633ms: Process H switching out of CPU; will block on I/O until time 160315ms [Q C E F E C H H H D A A]
time 158637ms: Process C started using the CPU for 230ms burst [Q E F E C H H H D A A]
time 158867ms: Process C completed a CPU burst; 78 bursts to go [Q E F E C H H H D A A]
time 158867ms: Process C switching out of CPU; will block on I/O until time 159062ms [Q E F E C H H H D A A]
time 158871ms: Process E started using the CPU for 1145ms burst [Q F E C H H H D A A]
time 159057ms: Process D completed I/O; added to ready queue [Q F E C H H H D A A D]
time 159062ms: Process C completed I/O; added to ready queue [Q F E C H H H D A A D C]
time 160016ms: Process E completed a CPU burst; 67 bursts to go [Q F E C H H H D A A D C]
time 160016ms: Process E switching out of CPU; will block on I/O until time 160953ms [Q F E C H H H D A A D C]
time 160020ms: Process F started using the CPU for 1401ms burst [Q E C H H H D A A D C]
time 160315ms: Process H completed I/O; added to ready queue [Q E C H H H D A A D C H]
time 160953ms: Process E completed I/O; added to ready queue [Q E C H H H D A A D C H E]
time 161421ms: Process F completed a CPU burst; 84 bursts to go [Q E C H H H D A A D C H E]
time 161421ms: Process F switching out of CPU; will block on I/O until time 162454ms [Q E C H H H D A A D C H E]
time 161425ms: Process E started using the CPU for 985ms burst [Q C H H H D A A D C H E]
time 162410ms: Process E completed a CPU burst; 68 bursts to go [Q C H H H D A A D C H E]
time 162410ms: Process E switching out of CPU; will block on I/O until time 163347ms [Q C H H H D A A D C H E]
time 162414ms: Process C started using the CPU for 230ms burst [Q H H H D A A D C H E]
time 162454ms: Process F completed I/O; added to ready queue [Q H H H D A A D C H E F]
time 162644ms: Process C completed a CPU burst; 78 bursts to go [Q H H H D A A D C H E F]
time 162644ms: Process C switching out of CPU; will block on I/O until time 163429ms [Q H H H D A A D C H E F]
time 162648ms: Process H started using the CPU for 49ms burst [Q H H D A A D C H E F]
time 162697ms: Process H completed a CPU burst; 32 bursts to go [Q H H D A A D C H E F]
time 162697ms: Process H switching out of CPU; will block on I/O until time 163041ms [Q H H D A A D C H E F]
time 162701ms: Process H started using the CPU for 49ms burst [Q H D A A D C H E F]
time 162750ms: Process H completed a CPU burst; 32 bursts to go [Q H D A A D C H E F]
time 162750ms: Process H switching out of CPU; will block on I/O until time 164432ms [Q H D A A D C H E F]
time 162754ms: Process H started using the CPU for 49ms burst [Q D A A D C H E F]
time 162803ms: Process H completed a CPU burst; 32 bursts to go [Q D A A D C H E F]
time 162803ms: Process H switching out of CPU; will block on I/O until time 164485ms [Q D A A D C H E F]
time 162807ms: Process D started using the CPU for 2717ms burst [Q A A D C H E F]
time 165089ms: Time slice expired; process D preempted with 435ms to go [Q A A D C H E F H]
time 165089ms: Process H completed I/O; added to ready queue [Q A A D C H E F H H]
time 165091ms: Process E completed I/O; added to ready queue [Q A A D C H E F H H E]
time 165091ms: Process C terminated [Q A A D C H E F H H E D]
time 165093ms: Process H terminated [Q A A D C H E F H H E D]
time 165095ms: Process H terminated [Q A A D C H E F H H E D]
time 165099ms: Process A started using the CPU for 1135ms burst [Q A D C H E F H H E D]
time 166234ms: Process A completed a CPU burst; 68 bursts to go [Q A D C H E F H H E D]
time 166234ms: Process A switching out of CPU; will block on I/O until time 166386ms [Q A D C H E F H H E D]
time 166238ms: Process A started using the CPU for 1135ms burst [Q D C H E F H H E D]
time 166386ms: Process A completed I/O; added to ready queue [Q D C H E F H H E D A]
time 167373ms: Process A completed a CPU burst; 68 bursts to go [Q D C H E F H H E D A]
time 167373ms: Process A switching out of CPU; will block on I/O until time 167452ms [Q D C H E F H H E D A]
time 167377ms: Process D started using the CPU for 508ms burst [Q C H E F H H E D A]
time 167452ms: Process A completed I/O; added to ready queue [Q C H E F H H E D A A]
time 167885ms: Process D completed a CPU burst; 41 bursts to go [Q C H E F H H E D A A]
time 167885ms: Process D switching out of CPU; will block on I/O until time 168595ms [Q C H E F H H E D A A]
time 167889ms: Process C started using the CPU for 768ms burst [Q H E F H H E D A A]
time 168595ms: Process D completed I/O; added to ready queue [Q H E F H H E D A A D]
time 168657ms: Process C completed a CPU burst; 77 bursts to go [Q H E F H H E D A A D]
time 168657ms: Process C switching out of CPU; will block on I/O until time 169228ms [Q H E F H H E D A A D]
time 168661ms: Process H started using the CPU for 49ms burst [Q E F H H E D A A D]
time 168710ms: Process H completed a CPU burst; 32 bursts to go [Q E F H H E D A A D]
time 168710ms: Process H switching out of CPU; will block on I/O until time 169712ms [Q E F H H E D A A D]
time 168714ms: Process E started using the CPU for 593ms burst [Q F H H E D A A D]
time 169228ms: Process C completed I/O; added to ready queue [Q F H H E D A A D C]
time 169307ms: Process E completed a CPU burst; 66 bursts to go [Q F H H E D A A D C]
time 169307ms: Process E switching out of CPU; will block on I/O until time 169855ms [Q F H H E D A A D C]
time 169311ms: Process F started using the CPU for 215ms burst [Q H H E D A A D C]
time 169526ms: Process F completed a CPU burst; 83 bursts to go [Q H H E D A A D C]
time 169526ms: Process F switching out of CPU; will block on I/O until time 169727ms [Q H H E D A A D C]
time 169530ms: Process H started using the CPU for 1969ms burst [Q H E D A A D C]
time 169712ms: Process H completed I/O; added to ready queue [Q H E D A A D C H]
time 169727ms: Process F completed I/O; added to ready queue [Q H E D A A D C H F]
time 169855ms: Process E completed I/O; added to ready queue [Q H E D A A D C H F E]
time 171499ms: Process H completed a CPU burst; 31 bursts to go [Q H E D A A D C H F E]
time 171499ms: Process H switching out of CPU; will block on I/O until time 173181ms [Q H E D A A D C H F E]
time 171503ms: Process H started using the CPU for 1969ms burst [Q E D A A D C H F E]
time 173181ms: Process H completed I/O; added to ready queue [Q E D A A D C H F E H]
time 173472ms: Process H completed a CPU burst; 31 bursts to go [Q E D A A D C H F E H]
time 173472ms: Process H switching out of CPU; will block on I/O until time 174474ms [Q E D A A D C H F E H]
time 173476ms: Process E started using the CPU for 1145ms burst [Q D A A D C H F E H]
time 174474ms: Process H completed I/O; added to ready queue [Q D A A D C H F E H H]
time 174621ms: Process E completed a CPU burst; 67 bursts to go [Q D A A D C H F E H H]
time 174621ms: Process E switching out of CPU; will block on I/O until time 175169ms [Q D A A D C H F E H H]
time 174625ms: Process D started using the CPU with 435ms burst remaining [Q A A D C H F E H H]
time 175060ms: Process D completed a CPU burst; 42 bursts to go [Q A A D C H F E H H]
time 175060ms: Process D switching out of CPU; will block on I/O until time 175674ms [Q A A D C H F E H H]
time 175064ms: Process A started using the CPU for 1068ms burst [Q A D C H F E H H]
time 175169ms: Process E completed I/O; added to ready queue [Q A D C H F E H H E]
time 175674ms: Process D completed I/O; added to ready queue [Q A D C H F E H H E D]
time 176132ms: Process A completed a CPU burst; 67 bursts to go [Q A D C H F E H H E D]
time 176132ms: Process A switching out of CPU; will block on I/O until time 176211ms [Q A D C H F E H H E D]
time 176136ms: Process A started using the CPU for 1068ms burst [Q D C H F E H H E D]
time 176211ms: Process A completed I/O; added to ready queue [Q D C H F E H H E D A]
time 177204ms: Process A completed a CPU burst; 67 bursts to go [Q D C H F E H H E D A]
time 177204ms: Process A switching out of CPU; will block on I/O until time 177255ms [Q D C H F E H H E D A]
time 177208ms: Process D started using the CPU for 205ms burst [Q C H F E H H E D A]
time 177255ms: Process A completed I/O; added to ready queue [Q C H F E H H E D A A]
time 177413ms: Process D completed a CPU burst; 40 bursts to go [Q C H F E H H E D A A]
time 177413ms: Process D switching out of CPU; will block on I/O until time 178604ms [Q C H F E H H E D A A]
time 177417ms: Process C started using the CPU for 106ms burst [Q H F E H H E D A A]
time 177523ms: Process C completed a CPU burst; 76 bursts to go [Q H F E H H E D A A]
time 177523ms: Process C switching out of CPU; will block on I/O until time 179044ms [Q H F E H H E D A A]
time 177527ms: Process H started using the CPU for 1969ms burst [Q F E H H E D A A]
time 178604ms: Process D completed I/O; added to ready queue [Q F E H H E D A A D]
time 179044ms: Process C completed I/O; added to ready queue [Q F E H H E D A A D C]
time 179496ms: Process H completed a CPU burst; 31 bursts to go [Q F E H H E D A A D C]
time 179496ms: Process H switching out of CPU; will block on I/O until time 179947ms [Q F E H H E D A A D C]
time 179500ms: Process F started using the CPU for 531ms burst [Q E H H E D A A D C]
time 179947ms: Process H completed I/O; added to ready queue [Q E H H E D A A D C H]
time 180031ms: Process F completed a CPU burst; 82 bursts to go [Q E H H E D A A D C H]
time 180031ms: Process F switching out of CPU; will block on I/O until time 180764ms [Q E H H E D A A D C H]
time 180035ms: Process E started using the CPU for 1078ms burst [Q H H E D A A D C H]
time 180764ms: Process F completed I/O; added to ready queue [Q H H E D A A D C H F]
time 181113ms: Process E completed a CPU burst; 65 bursts to go [Q H H E D A A D C H F]
time 181113ms: Process E switching out of CPU; will block on I/O until time 181512ms [Q H H E D A A D C H F]
time 181117ms: Process H started using the CPU for 622ms burst [Q H E D A A D C H F]
time 181512ms: Process E completed I/O; added to ready queue [Q H E D A A D C H F E]
time 181739ms: Process H completed a CPU burst; 30 bursts to go [Q H E D A A D C H F E]
time 181739ms: Process H switching out of CPU; will block on I/O until time 182741ms [Q H E D A A D C H F E]
time 181743ms: Process H started using the CPU for 622ms burst [Q E D A A D C H F E]
time 182365ms: Process H completed a CPU burst; 30 bursts to go [Q E D A A D C H F E]
time 182365ms: Process H switching out of CPU; will block on I/O until time 182816ms [Q E D A A D C H F E]
time 182369ms: Process E started using the CPU for 593ms burst [Q D A A D C H F E]
time 182741ms: Process H completed I/O; added to ready queue [Q D A A D C H F E H]
time 182816ms: Process H completed I/O; added to ready queue [Q D A A D C H F E H H]
time 182962ms: Process E completed a CPU burst; 66 bursts to go [Q D A A D C H F E H H]
time 182962ms: Process E switching out of CPU; will block on I/O until time 183361ms [Q D A A D C H F E H H]
time 182966ms: Process D started using the CPU for 508ms burst [Q A A D C H F E H H]
time 183361ms: Process E completed I/O; added to ready queue [Q A A D C H F E H H E]
time 183474ms: Process D completed a CPU burst; 41 bursts to go [Q A A D C H F E H H E]
time 183474ms: Process D switching out of CPU; will block on I/O until time 184721ms [Q A A D C H F E H H E]
time 183478ms: Process A started using the CPU for 447ms burst [Q A D C H F E H H E]
time 183925ms: Process A completed a CPU burst; 66 bursts to go [Q A D C H F E H H E]
time 183925ms: Process A switching out of CPU; will block on I/O until time 183976ms [Q A D C H F E H H E]
time 183929ms: Process A started using the CPU for 447ms burst [Q D C H F E H H E]
time 183976ms: Process A completed I/O; added to ready queue [Q D C H F E H H E A]
time 184376ms: Process A completed a CPU burst; 66 bursts to go [Q D C H F E H H E A]
time 184376ms: Process A switching out of CPU; will block on I/O until time 185493ms [Q D C H F E H H E A]
time 184380ms: Process D started using the CPU for 1404ms burst [Q C H F E H H E A]
time 184721ms: Process D completed I/O; added to ready queue [Q C H F E H H E A D]
time 185493ms: Process A completed I/O; added to ready queue [Q C H F E H H E A D A]
time 185784ms: Process D completed a CPU burst; 39 bursts to go [Q C H F E H H E A D A]
time 185784ms: Process D switching out of CPU; will block on I/O until time 187086ms [Q C H F E H H E A D A]
time 185788ms: Process C started using the CPU for 1544ms burst [Q H F E H H E A D A]
time 187086ms: Process D completed I/O; added to ready queue [Q H F E H H E A D A D]
time 187332ms: Process C completed a CPU burst; 75 bursts to go [Q H F E H H E A D A D]
time 187332ms: Process C switching out of CPU; will block on I/O until time 187453ms [Q H F E H H E A D A D]
time 187336ms: Process H started using the CPU for 622ms burst [Q F E H H E A D A D]
time 187453ms: Process C completed I/O; added to ready queue [Q F E H H E A D A D C]
time 187958ms: Process H completed a CPU burst; 30 bursts to go [Q F E H H E A D A D C]
time 187958ms: Process H switching out of CPU; will block on I/O until time 188317ms [Q F E H H E A D A D C]
time 187962ms: Process F started using the CPU for 198ms burst [Q E H H E A D A D C]
time 188160ms: Process F completed a CPU burst; 81 bursts to go [Q E H H E A D A D C]
time 188160ms: Process F switching out of CPU; will block on I/O until time 191827ms [Q E H H E A D A D C]
time 188164ms: Process E started using the CPU for 1045ms burst [Q H H E A D A D C]
time 188317ms: Process H completed I/O; added to ready queue [Q H H E A D A D C H]
time 189209ms: Process E completed a CPU burst; 64 bursts to go [Q H H E A D A D C H]
time 189209ms: Process E switching out of CPU; will block on I/O until time 189851ms [Q H H E A D A D C H]
time 189213ms: Process H started using the CPU for 2420ms burst [Q H E A D A D C H]
time 189851ms: Process E completed I/O; added to ready queue [Q H E A D A D C H E]
time 191633ms: Process H completed a CPU burst; 29 bursts to go [Q H E A D A D C H E]
time 191633ms: Process H switching out of CPU; will block on I/O until time 192084ms [Q H E A D A D C H E]
time 191637ms: Process H started using the CPU for 2420ms burst [Q E A D A D C H E]
time 193875ms: Time slice expired; process H preempted with 182ms to go [Q E A D A D C H E F]
time 193875ms: Process F completed I/O; added to ready queue [Q E A D A D C H E F F]
time 193877ms: Process H completed I/O; added to ready queue [Q E A D A D C H E F F H]
time 193879ms: Process E started using the CPU for 1078ms burst [Q A D A D C H E F F H H]
time 194957ms: Process E completed a CPU burst; 65 bursts to go [Q A D A D C H E F F H H]
time 194957ms: Process E switching out of CPU; will block on I/O until time 195599ms [Q A D A D C H E F F H H]
time 194961ms: Process A started using the CPU for 200ms burst [Q D A D C H E F F H H]
time 195161ms: Process A completed a CPU burst; 65 bursts to go [Q D A D C H E F F H H]
time 195161ms: Process A switching out of CPU; will block on I/O until time 196278ms [Q D A D C H E F F H H]
time 195165ms: Process D started using the CPU for 205ms burst [Q A D C H E F F H H]
time 195370ms: Process D completed a CPU burst; 40 bursts to go [Q A D C H E F F H H]
time 195370ms: Process D switching out of CPU; will block on I/O until time 196080ms [Q A D C H E F F H H]
time 195374ms: Process A started using the CPU for 200ms burst [Q D C H E F F H H]
time 195574ms: Process A completed a CPU burst; 65 bursts to go [Q D C H E F F H H]
time 195574ms: Process A switching out of CPU; will block on I/O until time 196381ms [Q D C H E F F H H]
time 195578ms: Process D started using the CPU for 3202ms burst [Q C H E F F H H]
time 197647ms: Time slice expired; process D preempted with 1133ms to go [Q C H E F F H H E]
time 197649ms: Process D terminated [Q C H E F F H H E D]
time 197651ms: Process A terminated [Q C H E F F H H E D]
time 197653ms: Process A terminated [Q C H E F F H H E D]
time 197657ms: Process C started using the CPU for 147ms burst [Q H E F F H H E D]
time 197804ms: Process C completed a CPU burst; 74 bursts to go [Q H E F F H H E D]
time 197804ms: Process C switching out of CPU; will block on I/O until time 199348ms [Q H E F F H H E D]
time 197808ms: Process H started using the CPU for 2420ms burst [Q E F F H H E D]
time 198552ms: Process E completed I/O; added to ready queue [Q E F F H H E D E]
time 199348ms: Process C completed I/O; added to ready queue [Q E F F H H E D E C]
time 200228ms: Process H completed a CPU burst; 29 bursts to go [Q E F F H H E D E C]
time 200228ms: Process H switching out of CPU; will block on I/O until time 201191ms [Q E F F H H E D E C]
time 200232ms: Process E started using the CPU for 910ms burst [Q F F H H E D E C]
time 201142ms: Process E completed a CPU burst; 63 bursts to go [Q F F H H E D E C]
time 201142ms: Process E switching out of CPU; will block on I/O until time 204091ms [Q F F H H E D E C]
time 201146ms: Process F started using the CPU for 218ms burst [Q F H H E D E C]
time 201191ms: Process H completed I/O; added to ready queue [Q F H H E D E C H]
time 201364ms: Process F completed a CPU burst; 80 bursts to go [Q F H H E D E C H]
time 201364ms: Process F switching out of CPU; will block on I/O until time 203374ms [Q F H H E D E C H]
time 201368ms: Process F started using the CPU for 218ms burst [Q H H E D E C H]
time 201586ms: Process F completed a CPU burst; 80 bursts to go [Q H H E D E C H]
time 201586ms: Process F switching out of CPU; will block on I/O until time 203151ms [Q H H E D E C H]
time 201590ms: Process H started using the CPU for 1623ms burst [Q H E D E C H]
time 203151ms: Process F completed I/O; added to ready queue [Q H E D E C H F]
time 203213ms: Process H completed a CPU burst; 28 bursts to go [Q H E D E C H F]
time 203213ms: Process H switching out of CPU; will block on I/O until time 203572ms [Q H E D E C H F]
time 203217ms: Process H started using the CPU with 182ms burst remaining [Q E D E C H F]
time 203374ms: Process F completed I/O; added to ready queue [Q E D E C H F F]
time 203399ms: Process H completed a CPU burst; 29 bursts to go [Q E D E C H F F]
time 203399ms: Process H switching out of CPU; will block on I/O until time 203758ms [Q E D E C H F F]
time 203403ms: Process E started using the CPU for 1045ms burst [Q D E C H F F]
time 203572ms: Process H completed I/O; added to ready queue [Q D E C H F F H]
time 203758ms: Process H completed I/O; added to ready queue [Q D E C H F F H H]
time 204091ms: Process E completed I/O; added to ready queue [Q D E C H F F H H E]
time 204448ms: Process E completed a CPU burst; 64 bursts to go [Q D E C H F F H H E]
time 204448ms: Process E switching out of CPU; will block on I/O until time 207397ms [Q D E C H F F H H E]
time 204452ms: Process D started using the CPU with 1133ms burst remaining [Q E C H F F H H E]
time 205585ms: Process D completed a CPU burst; 38 bursts to go [Q E C H F F H H E]
time 205585ms: Process D switching out of CPU; will block on I/O until time 208168ms [Q E C H F F H H E]
time 205589ms: Process E started using the CPU for 1045ms burst [Q C H F F H H E]
time 206634ms: Process E completed a CPU burst; 64 bursts to go [Q C H F F H H E]
time 206634ms: Process E switching out of CPU; will block on I/O until time 206665ms [Q C H F F H H E]
time 206638ms: Process C started using the CPU for 2148ms burst [Q H F F H H E]
time 208713ms: Time slice expired; process C preempted with 73ms to go [Q H F F H H E E]
time 208713ms: Process E completed I/O; added to ready queue [Q H F F H H E E E]
time 208715ms: Process E completed I/O; added to ready queue [Q H F F H H E E E E]
time 208715ms: Process D terminated [Q H F F H H E E E E C]
time 208719ms: Process H started using the CPU for 1623ms burst [Q F F H H E E E E C]
time 210342ms: Process H completed a CPU burst; 28 bursts to go [Q F F H H E E E E C]
time 210342ms: Process H switching out of CPU; will block on I/O until time 211645ms [Q F F H H E E E E C]
time 210346ms: Process F started using the CPU for 914ms burst [Q F H H E E E E C]
time 211260ms: Process F completed a CPU burst; 79 bursts to go [Q F H H E E E E C]
time 211260ms: Process F switching out of CPU; will block on I/O until time 211335ms [Q F H H E E E E C]
time 211264ms: Process F started using the CPU for 914ms burst [Q H H E E E E C]
time 211335ms: Process F completed I/O; added to ready queue [Q H H E E E E C F]
time 211645ms: Process H completed I/O; added to ready queue [Q H H E E E E C F H]
time 212178ms: Process F completed a CPU burst; 79 bursts to go [Q H H E E E E C F H]
time 212178ms: Process F switching out of CPU; will block on I/O until time 213743ms [Q H H E E E E C F H]
time 212182ms: Process H started using the CPU for 202ms burst [Q H E E E E C F H]
time 212384ms: Process H completed a CPU burst; 27 bursts to go [Q H E E E E C F H]
time 212384ms: Process H switching out of CPU; will block on I/O until time 213347ms [Q H E E E E C F H]
time 212388ms: Process H started using the CPU for 1623ms burst [Q E E E E C F H]
time 213347ms: Process H completed I/O; added to ready queue [Q E E E E C F H H]
time 213743ms: Process F completed I/O; added to ready queue [Q E E E E C F H H F]
time 214011ms: Process H completed a CPU burst; 28 bursts to go [Q E E E E C F H H F]
time 214011ms: Process H switching out of CPU; will block on I/O until time 214974ms [Q E E E E C F H H F]
time 214015ms: Process E started using the CPU for 2671ms burst [Q E E E C F H H F]
time 214974ms: Process H completed I/O; added to ready queue [Q E E E C F H H F H]
time 216686ms: Process E completed a CPU burst; 62 bursts to go [Q E E E C F H H F H]
time 216686ms: Process E switching out of CPU; will block on I/O until time 216717ms [Q E E E C F H H F H]
time 216690ms: Process E started using the CPU for 910ms burst [Q E E C F H H F H]
time 216717ms: Process E completed I/O; added to ready queue [Q E E C F H H F H E]
time 217600ms: Process E completed a CPU burst; 63 bursts to go [Q E E C F H H F H E]
time 217600ms: Process E switching out of CPU; will block on I/O until time 217743ms [Q E E C F H H F H E]
time 217604ms: Process E started using the CPU for 910ms burst [Q E C F H H F H E]
time 217743ms: Process E completed I/O; added to ready queue [Q E C F H H F H E E]
time 218514ms: Process E completed a CPU burst; 63 bursts to go [Q E C F H H F H E E]
time 218514ms: Process E switching out of CPU; will block on I/O until time 219127ms [Q E C F H H F H E E]
time 218518ms: Process E started using the CPU for 910ms burst [Q C F H H F H E E]
time 219127ms: Process E completed I/O; added to ready queue [Q C F H H F H E E E]
time 219428ms: Process E completed a CPU burst; 63 bursts to go [Q C F H H F H E E E]
time 219428ms: Process E switching out of CPU; will block on I/O until time 219459ms [Q C F H H F H E E E]
time 219432ms: Process C started using the CPU with 73ms burst remaining [Q F H H F H E E E]
time 219459ms: Process E completed I/O; added to ready queue [Q F H H F H E E E E]
time 219505ms: Process C completed a CPU burst; 73 bursts to go [Q F H H F H E E E E]
time 219505ms: Process C switching out of CPU; will block on I/O until time 219644ms [Q F H H F H E E E E]
time 219509ms: Process F started using the CPU for 1276ms burst [Q H H F H E E E E]
time 219644ms: Process C completed I/O; added to ready queue [Q H H F H E E E E C]
time 220785ms: Process F completed a CPU burst; 78 bursts to go [Q H H F H E E E E C]
time 220785ms: Process F switching out of CPU; will block on I/O until time 221193ms [Q H H F H E E E E C]
time 220789ms: Process H started using the CPU for 202ms burst [Q H F H E E E E C]
time 220991ms: Process H completed a CPU burst; 27 bursts to go [Q H F H E E E E C]
time 220991ms: Process H switching out of CPU; will block on I/O until time 223388ms [Q H F H E E E E C]
time 220995ms: Process H started using the CPU for 244ms burst [Q F H E E E E C]
time 221193ms: Process F completed I/O; added to ready queue [Q F H E E E E C F]
time 221239ms: Process H completed a CPU burst; 26 bursts to go [Q F H E E E E C F]
time 221239ms: Process H switching out of CPU; will block on I/O until time 222542ms [Q F H E E E E C F]
time 221243ms: Process F started using the CPU for 1276ms burst [Q H E E E E C F]
time 222519ms: Process F completed a CPU burst; 78 bursts to go [Q H E E E E C F]
time 222519ms: Process F switching out of CPU; will block on I/O until time 222594ms [Q H E E E E C F]
time 222523ms: Process H started using the CPU for 202ms burst [Q E E E E C F]
time 222542ms: Process H completed I/O; added to ready queue [Q E E E E C F H]
time 222594ms: Process F completed I/O; added to ready queue [Q E E E E C F H F]
time 222725ms: Process H completed a CPU burst; 27 bursts to go [Q E E E E C F H F]
time 222725ms: Process H switching out of CPU; will block on I/O until time 224028ms [Q E E E E C F H F]
time 222729ms: Process E started using the CPU for 734ms burst [Q E E E C F H F]
time 223388ms: Process H completed I/O; added to ready queue [Q E E E C F H F H]
time 223463ms: Process E completed a CPU burst; 61 bursts to go [Q E E E C F H F H]
time 223463ms: Process E switching out of CPU; will block on I/O until time 223606ms [Q E E E C F H F H]
time 223467ms: Process E started using the CPU for 2671ms burst [Q E E C F H F H]
time 225654ms: Time slice expired; process E preempted with 484ms to go [Q E E C F H F H E]
time 225654ms: Process E completed I/O; added to ready queue [Q E E C F H F H E E]
time 225656ms: Process H completed I/O; added to ready queue [Q E E C F H F H E E H]
time 225658ms: Process E started using the CPU for 2671ms burst [Q E C F H F H E E H E]
time 227706ms: Time slice expired; process E preempted with 623ms to go [Q E C F H F H E E H E]
time 227710ms: Process E started using the CPU for 2671ms burst [Q C F H F H E E H E E]
time 229758ms: Time slice expired; process E preempted with 623ms to go [Q C F H F H E E H E E]
time 229762ms: Process C started using the CPU for 1935ms burst [Q F H F H E E H E E E]
time 231697ms: Process C completed a CPU burst; 72 bursts to go [Q F H F H E E H E E E]
time 231697ms: Process C switching out of CPU; will block on I/O until time 233109ms [Q F H F H E E H E E E]
time 231701ms: Process F started using the CPU for 907ms burst [Q H F H E E H E E E]
time 232608ms: Process F completed a CPU burst; 77 bursts to go [Q H F H E E H E E E]
time 232608ms: Process F switching out of CPU; will block on I/O until time 236081ms [Q H F H E E H E E E]
time 232612ms: Process H started using the CPU for 45ms burst [Q F H E E H E E E]
time 232657ms: Process H completed a CPU burst; 25 bursts to go [Q F H E E H E E E]
time 232657ms: Process H switching out of CPU; will block on I/O until time 235054ms [Q F H E E H E E E]
time 232661ms: Process F started using the CPU for 907ms burst [Q H E E H E E E]
time 233109ms: Process C completed I/O; added to ready queue [Q H E E H E E E C]
time 233568ms: Process F completed a CPU burst; 77 bursts to go [Q H E E H E E E C]
time 233568ms: Process F switching out of CPU; will block on I/O until time 233976ms [Q H E E H E E E C]
time 233572ms: Process H started using the CPU for 244ms burst [Q E E H E E E C]
time 233816ms: Process H completed a CPU burst; 26 bursts to go [Q E E H E E E C]
time 233816ms: Process H switching out of CPU; will block on I/O until time 235066ms [Q E E H E E E C]
time 233820ms: Process E started using the CPU for 215ms burst [Q E H E E E C]
time 233976ms: Process F completed I/O; added to ready queue [Q E H E E E C F]
time 234035ms: Process E completed a CPU burst; 60 bursts to go [Q E H E E E C F]
time 234035ms: Process E switching out of CPU; will block on I/O until time 234648ms [Q E H E E E C F]
time 234039ms: Process E started using the CPU for 215ms burst [Q H E E E C F]
time 234254ms: Process E completed a CPU burst; 60 bursts to go [Q H E E E C F]
time 234254ms: Process E switching out of CPU; will block on I/O until time 236219ms [Q H E E E C F]
time 234258ms: Process H started using the CPU for 244ms burst [Q E E E C F]
time 234502ms: Process H completed a CPU burst; 26 bursts to go [Q E E E C F]
time 234502ms: Process H switching out of CPU; will block on I/O until time 236899ms [Q E E E C F]
time 234506ms: Process E started using the CPU with 484ms burst remaining [Q E E C F]
time 234648ms: Process E completed I/O; added to ready queue [Q E E C F E]
time 234990ms: Process E completed a CPU burst; 62 bursts to go [Q E E C F E]
time 234990ms: Process E switching out of CPU; will block on I/O until time 235603ms [Q E E C F E]
time 234994ms: Process E started using the CPU with 623ms burst remaining [Q E C F E]
time 235054ms: Process H completed I/O; added to ready queue [Q E C F E H]
time 235066ms: Process H completed I/O; added to ready queue [Q E C F E H H]
time 235603ms: Process E completed I/O; added to ready queue [Q E C F E H H E]
time 235617ms: Process E completed a CPU burst; 62 bursts to go [Q E C F E H H E]
time 235617ms: Process E switching out of CPU; will block on I/O until time 237582ms [Q E C F E H H E]
time 235621ms: Process E started using the CPU with 623ms burst remaining [Q C F E H H E]
time 236081ms: Process F completed I/O; added to ready queue [Q C F E H H E F]
time 236219ms: Process E completed I/O; added to ready queue [Q C F E H H E F E]
time 236244ms: Process E completed a CPU burst; 62 bursts to go [Q C F E H H E F E]
time 236244ms: Process E switching out of CPU; will block on I/O until time 236387ms [Q C F E H H E F E]
time 236248ms: Process C started using the CPU for 142ms burst [Q F E H H E F E]
time 236387ms: Process E completed I/O; added to ready queue [Q F E H H E F E E]
time 236390ms: Process C completed a CPU burst; 71 bursts to go [Q F E H H E F E E]
time 236390ms: Process C switching out of CPU; will block on I/O until time 237159ms [Q F E H H E F E E]
time 236394ms: Process F started using the CPU for 1623ms burst [Q E H H E F E E]
time 236899ms: Process H completed I/O; added to ready queue [Q E H H E F E E H]
time 237159ms: Process C completed I/O; added to ready queue [Q E H H E F E E H C]
time 237582ms: Process E completed I/O; added to ready queue [Q E H H E F E E H C E]
time 238017ms: Process F completed a CPU burst; 76 bursts to go [Q E H H E F E E H C E]
time 238017ms: Process F switching out of CPU; will block on I/O until time 241490ms [Q E H H E F E E H C E]
time 238021ms: Process E started using the CPU for 1141ms burst [Q H H E F E E H C E]
time 239162ms: Process E completed a CPU burst; 59 bursts to go [Q H H E F E E H C E]
time 239162ms: Process E switching out of CPU; will block on I/O until time 241127ms [Q H H E F E E H C E]
time 239166ms: Process H started using the CPU for 1078ms burst [Q H E F E E H C E]
time 240244ms: Process H completed a CPU burst; 24 bursts to go [Q H E F E E H C E]
time 240244ms: Process H switching out of CPU; will block on I/O until time 241494ms [Q H E F E E H C E]
time 240248ms: Process H started using the CPU for 45ms burst [Q E F E E H C E]
time 240293ms: Process H completed a CPU burst; 25 bursts to go [Q E F E E H C E]
time 240293ms: Process H switching out of CPU; will block on I/O until time 242108ms [Q E F E E H C E]
time 240297ms: Process E started using the CPU for 734ms burst [Q F E E H C E]
time 241031ms: Process E completed a CPU burst; 61 bursts to go [Q F E E H C E]
time 241031ms: Process E switching out of CPU; will block on I/O until time 242996ms [Q F E E H C E]
time 241035ms: Process F started using the CPU for 1623ms burst [Q E E H C E]
time 241127ms: Process E completed I/O; added to ready queue [Q E E H C E E]
time 241490ms: Process F completed I/O; added to ready queue [Q E E H C E E F]
time 241494ms: Process H completed I/O; added to ready queue [Q E E H C E E F H]
time 242108ms: Process H completed I/O; added to ready queue [Q E E H C E E F H H]
time 242658ms: Process F completed a CPU burst; 76 bursts to go [Q E E H C E E F H H]
time 242658ms: Process F switching out of CPU; will block on I/O until time 243123ms [Q E E H C E E F H H]
time 242662ms: Process E started using the CPU for 1141ms burst [Q E H C E E F H H]
time 242996ms: Process E completed I/O; added to ready queue [Q E H C E E F H H E]
time 243123ms: Process F completed I/O; added to ready queue [Q E H C E E F H H E F]
time 243803ms: Process E completed a CPU burst; 59 bursts to go [Q E H C E E F H H E F]
time 243803ms: Process E switching out of CPU; will block on I/O until time 247514ms [Q E H C E E F H H E F]
time 243807ms: Process E started using the CPU for 734ms burst [Q H C E E F H H E F]
time 244541ms: Process E completed a CPU burst; 61 bursts to go [Q H C E E F H H E F]
time 244541ms: Process E switching out of CPU; will block on I/O until time 245154ms [Q H C E E F H H E F]
time 244545ms: Process H started using the CPU for 45ms burst [Q C E E F H H E F]
time 244590ms: Process H completed a CPU burst; 25 bursts to go [Q C E E F H H E F]
time 244590ms: Process H switching out of CPU; will block on I/O until time 245840ms [Q C E E F H H E F]
time 244594ms: Process C started using the CPU for 2295ms burst [Q E E F H H E F]
time 245154ms: Process E completed I/O; added to ready queue [Q E E F H H E F E]
time 245840ms: Process H completed I/O; added to ready queue [Q E E F H H E F E H]
time 246889ms: Process C completed a CPU burst; 70 bursts to go [Q E E F H H E F E H]
time 246889ms: Process C switching out of CPU; will block on I/O until time 248590ms [Q E E F H H E F E H]
time 246893ms: Process E started using the CPU for 734ms burst [Q E F H H E F E H]
time 247514ms: Process E completed I/O; added to ready queue [Q E F H H E F E H E]
time 247627ms: Process E completed a CPU burst; 61 bursts to go [Q E F H H E F E H E]
time 247627ms: Process E switching out of CPU; will block on I/O until time 251338ms [Q E F H H E F E H E]
time 247631ms: Process E started using the CPU for 197ms burst [Q F H H E F E H E]
time 247828ms: Process E completed a CPU burst; 58 bursts to go [Q F H H E F E H E]
time 247828ms: Process E switching out of CPU; will block on I/O until time 251539ms [Q F H H E F E H E]
time 247832ms: Process F started using the CPU for 766ms burst [Q H H E F E H E]
time 248590ms: Process C completed I/O; added to ready queue [Q H H E F E H E C]
time 248598ms: Process F completed a CPU burst; 75 bursts to go [Q H H E F E H E C]
time 248598ms: Process F switching out of CPU; will block on I/O until time 249063ms [Q H H E F E H E C]
time 248602ms: Process H started using the CPU for 1191ms burst [Q H E F E H E C]
time 249063ms: Process F completed I/O; added to ready queue [Q H E F E H E C F]
time 249793ms: Process H completed a CPU burst; 23 bursts to go [Q H E F E H E C F]
time 249793ms: Process H switching out of CPU; will block on I/O until time 251608ms [Q H E F E H E C F]
time 249797ms: Process H started using the CPU for 1078ms burst [Q E F E H E C F]
time 250875ms: Process H completed a CPU burst; 24 bursts to go [Q E F E H E C F]
time 250875ms: Process H switching out of CPU; will block on I/O until time 250977ms [Q E F E H E C F]
time 250879ms: Process E started using the CPU for 215ms burst [Q F E H E C F]
time 250977ms: Process H completed I/O; added to ready queue [Q F E H E C F H]
time 251094ms: Process E completed a CPU burst; 60 bursts to go [Q F E H E C F H]
time 251094ms: Process E switching out of CPU; will block on I/O until time 254805ms [Q F E H E C F H]
time 251098ms: Process F started using the CPU for 766ms burst [Q E H E C F H]
time 251338ms: Process E completed I/O; added to ready queue [Q E H E C F H E]
time 251539ms: Process E completed I/O; added to ready queue [Q E H E C F H E E]
time 251608ms: Process H completed I/O; added to ready queue [Q E H E C F H E E H]
time 251864ms: Process F completed a CPU burst; 75 bursts to go [Q E H E C F H E E H]
time 251864ms: Process F switching out of CPU; will block on I/O until time 252198ms [Q E H E C F H E E H]
time 251868ms: Process E started using the CPU for 215ms burst [Q H E C F H E E H]
time 252083ms: Process E completed a CPU burst; 60 bursts to go [Q H E C F H E E H]
time 252083ms: Process E switching out of CPU; will block on I/O until time 254048ms [Q H E C F H E E H]
time 252087ms: Process H started using the CPU for 1078ms burst [Q E C F H E E H]
time 252198ms: Process F completed I/O; added to ready queue [Q E C F H E E H F]
time 253165ms: Process H completed a CPU burst; 24 bursts to go [Q E C F H E E H F]
time 253165ms: Process H switching out of CPU; will block on I/O until time 254980ms [Q E C F H E E H F]
time 253169ms: Process E started using the CPU for 197ms burst [Q C F H E E H F]
time 253366ms: Process E completed a CPU burst; 58 bursts to go [Q C F H E E H F]
time 253366ms: Process E switching out of CPU; will block on I/O until time 254659ms [Q C F H E E H F]
time 253370ms: Process C started using the CPU for 43ms burst [Q F H E E H F]
time 253413ms: Process C completed a CPU burst; 69 bursts to go [Q F H E E H F]
time 253413ms: Process C switching out of CPU; will block on I/O until time 254622ms [Q F H E E H F]
time 253417ms: Process F started using the CPU for 2644ms burst [Q H E E H F]
time 254048ms: Process E completed I/O; added to ready queue [Q H E E H F E]
time 254622ms: Process C completed I/O; added to ready queue [Q H E E H F E C]
time 254659ms: Process E completed I/O; added to ready queue [Q H E E H F E C E]
time 254805ms: Process E completed I/O; added to ready queue [Q H E E H F E C E E]
time 254980ms: Process H completed I/O; added to ready queue [Q H E E H F E C E E H]
time 256061ms: Process F completed a CPU burst; 74 bursts to go [Q H E E H F E C E E H]
time 256061ms: Process F switching out of CPU; will block on I/O until time 256395ms [Q H E E H F E C E E H]
time 256065ms: Process H started using the CPU for 1191ms burst [Q E E H F E C E E H]
time 256395ms: Process F completed I/O; added to ready queue [Q E E H F E C E E H F]
time 257256ms: Process H completed a CPU burst; 23 bursts to go [Q E E H F E C E E H F]
time 257256ms: Process H switching out of CPU; will block on I/O until time 257652ms [Q E E H F E C E E H F]
time 257260ms: Process E started using the CPU for 215ms burst [Q E H F E C E E H F]
time 257475ms: Process E completed a CPU burst; 60 bursts to go [Q E H F E C E E H F]
time 257475ms: Process E switching out of CPU; will block on I/O until time 258768ms [Q E H F E C E E H F]
time 257479ms: Process E started using the CPU for 708ms burst [Q H F E C E E H F]
time 257652ms: Process H completed I/O; added to ready queue [Q H F E C E E H F H]
time 258187ms: Process E completed a CPU burst; 57 bursts to go [Q H F E C E E H F H]
time 258187ms: Process E switching out of CPU; will block on I/O until time 259480ms [Q H F E C E E H F H]
time 258191ms: Process H started using the CPU for 118ms burst [Q F E C E E H F H]
time 258309ms: Process H completed a CPU burst; 22 bursts to go [Q F E C E E H F H]
time 258309ms: Process H switching out of CPU; will block on I/O until time 258411ms [Q F E C E E H F H]
time 258313ms: Process F started using the CPU for 2644ms burst [Q E C E E H F H]
time 260459ms: Time slice expired; process F preempted with 498ms to go [Q E C E E H F H H]
time 260459ms: Process H completed I/O; added to ready queue [Q E C E E H F H H H]
time 260461ms: Process E completed I/O; added to ready queue [Q E C E E H F H H H E]
time 260461ms: Process E terminated [Q E C E E H F H H H E F]
time 260465ms: Process E started using the CPU for 1141ms burst [Q C E E H F H H H E F]
time 261606ms: Process E completed a CPU burst; 59 bursts to go [Q C E E H F H H H E F]
time 261606ms: Process E switching out of CPU; will block on I/O until time 265317ms [Q C E E H F H H H E F]
time 261610ms: Process C started using the CPU for 1236ms burst [Q E E H F H H H E F]
time 262846ms: Process C completed a CPU burst; 68 bursts to go [Q E E H F H H H E F]
time 262846ms: Process C switching out of CPU; will block on I/O until time 264141ms [Q E E H F H H H E F]
time 262850ms: Process E started using the CPU for 708ms burst [Q E H F H H H E F]
time 263558ms: Process E completed a CPU burst; 57 bursts to go [Q E H F H H H E F]
time 263558ms: Process E switching out of CPU; will block on I/O until time 264292ms [Q E H F H H H E F]
time 263562ms: Process E started using the CPU for 1141ms burst [Q H F H H H E F]
time 264141ms: Process C completed I/O; added to ready queue [Q H F H H H E F C]
time 264292ms: Process E completed I/O; added to ready queue [Q H F H H H E F C E]
time 264703ms: Process E completed a CPU burst; 59 bursts to go [Q H F H H H E F C E]
time 264703ms: Process E switching out of CPU; will block on I/O until time 265996ms [Q H F H H H E F C E]
time 264707ms: Process H started using the CPU for 1191ms burst [Q F H H H E F C E]
time 265317ms: Process E completed I/O; added to ready queue [Q F H H H E F C E E]
time 265898ms: Process H completed a CPU burst; 23 bursts to go [Q F H H H E F C E E]
time 265898ms: Process H switching out of CPU; will block on I/O until time 266000ms [Q F H H H E F C E E]
time 265902ms: Process F started using the CPU for 79ms burst [Q H H H E F C E E]
time 265981ms: Process F completed a CPU burst; 73 bursts to go [Q H H H E F C E E]
time 265981ms: Process F switching out of CPU; will block on I/O until time 267881ms [Q H H H E F C E E]
time 265985ms: Process H started using the CPU for 118ms burst [Q H H E F C E E]
time 265996ms: Process E completed I/O; added to ready queue [Q H H E F C E E E]
time 266000ms: Process H completed I/O; added to ready queue [Q H H E F C E E E H]
time 266103ms: Process H completed a CPU burst; 22 bursts to go [Q H H E F C E E E H]
time 266103ms: Process H switching out of CPU; will block on I/O until time 266651ms [Q H H E F C E E E H]
time 266107ms: Process H started using the CPU for 182ms burst [Q H E F C E E E H]
time 266289ms: Process H completed a CPU burst; 21 bursts to go [Q H E F C E E E H]
time 266289ms: Process H switching out of CPU; will block on I/O until time 266685ms [Q H E F C E E E H]
time 266293ms: Process H started using the CPU for 182ms burst [Q E F C E E E H]
time 266475ms: Process H completed a CPU burst; 21 bursts to go [Q E F C E E E H]
time 266475ms: Process H switching out of CPU; will block on I/O until time 267023ms [Q E F C E E E H]
time 266479ms: Process E started using the CPU for 1141ms burst [Q F C E E E H]
time 266651ms: Process H completed I/O; added to ready queue [Q F C E E E H H]
time 266685ms: Process H completed I/O; added to ready queue [Q F C E E E H H H]
time 267023ms: Process H completed I/O; added to ready queue [Q F C E E E H H H H]
time 267620ms: Process E completed a CPU burst; 59 bursts to go [Q F C E E E H H H H]
time 267620ms: Process E switching out of CPU; will block on I/O until time 268354ms [Q F C E E E H H H H]
time 267624ms: Process F started using the CPU with 498ms burst remaining [Q C E E E H H H H]
time 267881ms: Process F completed I/O; added to ready queue [Q C E E E H H H H F]
time 268122ms: Process F completed a CPU burst; 74 bursts to go [Q C E E E H H H H F]
time 268122ms: Process F switching out of CPU; will block on I/O until time 270022ms [Q C E E E H H H H F]
time 268126ms: Process C started using the CPU for 41ms burst [Q E E E H H H H F]
time 268167ms: Process C completed a CPU burst; 67 bursts to go [Q E E E H H H H F]
time 268167ms: Process C switching out of CPU; will block on I/O until time 269206ms [Q E E E H H H H F]
time 268171ms: Process E started using the CPU for 691ms burst [Q E E H H H H F]
time 268354ms: Process E completed I/O; added to ready queue [Q E E H H H H F E]
time 268862ms: Process E completed a CPU burst; 56 bursts to go [Q E E H H H H F E]
time 268862ms: Process E switching out of CPU; will block on I/O until time 270173ms [Q E E H H H H F E]
time 268866ms: Process E started using the CPU for 197ms burst [Q E H H H H F E]
time 269063ms: Process E completed a CPU burst; 58 bursts to go [Q E H H H H F E]
time 269063ms: Process E switching out of CPU; will block on I/O until time 270356ms [Q E H H H H F E]
time 269067ms: Process E started using the CPU for 197ms burst [Q H H H H F E]
time 269206ms: Process C completed I/O; added to ready queue [Q H H H H F E C]
time 269264ms: Process E completed a CPU burst; 58 bursts to go [Q H H H H F E C]
time 269264ms: Process E switching out of CPU; will block on I/O until time 269998ms [Q H H H H F E C]
time 269268ms: Process H started using the CPU for 118ms burst [Q H H H F E C]
time 269386ms: Process H completed a CPU burst; 22 bursts to go [Q H H H F E C]
time 269386ms: Process H switching out of CPU; will block on I/O until time 269782ms [Q H H H F E C]
time 269390ms: Process H started using the CPU for 182ms burst [Q H H F E C]
time 269572ms: Process H completed a CPU burst; 21 bursts to go [Q H H F E C]
time 269572ms: Process H switching out of CPU; will block on I/O until time 270867ms [Q H H F E C]
time 269576ms: Process H started using the CPU for 1827ms burst [Q H F E C]
time 269782ms: Process H completed I/O; added to ready queue [Q H F E C H]
time 269998ms: Process E completed I/O; added to ready queue [Q H F E C H E]
time 270022ms: Process F completed I/O; added to ready queue [Q H F E C H E F]
time 270173ms: Process E completed I/O; added to ready queue [Q H F E C H E F E]
time 270356ms: Process E completed I/O; added to ready queue [Q H F E C H E F E E]
time 270867ms: Process H completed I/O; added to ready queue [Q H F E C H E F E E H]
time 271403ms: Process H completed a CPU burst; 20 bursts to go [Q H F E C H E F E E H]
time 271403ms: Process H switching out of CPU; will block on I/O until time 271951ms [Q H F E C H E F E E H]
time 271407ms: Process H started using the CPU for 1827ms burst [Q F E C H E F E E H]
time 271951ms: Process H completed I/O; added to ready queue [Q F E C H E F E E H H]
time 273234ms: Process H completed a CPU burst; 20 bursts to go [Q F E C H E F E E H H]
time 273234ms: Process H switching out of CPU; will block on I/O until time 274529ms [Q F E C H E F E E H H]
time 273238ms: Process F started using the CPU for 23ms burst [Q E C H E F E E H H]
time 273261ms: Process F completed a CPU burst; 72 bursts to go [Q E C H E F E E H H]
time 273261ms: Process F switching out of CPU; will block on I/O until time 273647ms [Q E C H E F E E H H]
time 273265ms: Process E started using the CPU for 197ms burst [Q C H E F E E H H]
time 273462ms: Process E completed a CPU burst; 58 bursts to go [Q C H E F E E H H]
time 273462ms: Process E switching out of CPU; will block on I/O until time 274773ms [Q C H E F E E H H]
time 273466ms: Process C started using the CPU for 626ms burst [Q H E F E E H H]
time 273647ms: Process F completed I/O; added to ready queue [Q H E F E E H H F]
time 274092ms: Process C completed a CPU burst; 66 bursts to go [Q H E F E E H H F]
time 274092ms: Process C switching out of CPU; will block on I/O until time 274355ms [Q H E F E E H H F]
time 274096ms: Process H started using the CPU for 182ms burst [Q E F E E H H F]
time 274278ms: Process H completed a CPU burst; 21 bursts to go [Q E F E E H H F]
time 274278ms: Process H switching out of CPU; will block on I/O until time 274826ms [Q E F E E H H F]
time 274282ms: Process E started using the CPU for 708ms burst [Q F E E H H F]
time 274355ms: Process C completed I/O; added to ready queue [Q F E E H H F C]
time 274529ms: Process H completed I/O; added to ready queue [Q F E E H H F C H]
time 274773ms: Process E completed I/O; added to ready queue [Q F E E H H F C H E]
time 274826ms: Process H completed I/O; added to ready queue [Q F E E H H F C H E H]
time 274990ms: Process E completed a CPU burst; 57 bursts to go [Q F E E H H F C H E H]
time 274990ms: Process E switching out of CPU; will block on I/O until time 276301ms [Q F E E H H F C H E H]
time 274994ms: Process F started using the CPU for 79ms burst [Q E E H H F C H E H]
time 275073ms: Process F completed a CPU burst; 73 bursts to go [Q E E H H F C H E H]
time 275073ms: Process F switching out of CPU; will block on I/O until time 275459ms [Q E E H H F C H E H]
time 275077ms: Process E started using the CPU for 98ms burst [Q E H H F C H E H]
time 275175ms: Process E completed a CPU burst; 55 bursts to go [Q E H H F C H E H]
