<<<<<<< HEAD
=======
Process A [NEW] (arrival time 9 ms) 16 CPU bursts
Process B [NEW] (arrival time 18 ms) 21 CPU bursts
time 0ms: Simulator started for FCFS [Q <empty>]
time 9ms: Process A arrived; added to ready queue [Q A]
time 11ms: Process A started using the CPU for 56ms burst [Q <empty>]
time 18ms: Process B arrived; added to ready queue [Q B]
49 < 49 > time: 49
time 67ms: Process A completed a CPU burst; 15 bursts to go [Q B]
time 67ms: Process A switching out of CPU; will block on I/O until time 92ms [Q B]
time 71ms: Process B started using the CPU for 106ms burst [Q <empty>]
time 92ms: Process A completed I/O; added to ready queue [Q A]
85 < 85 > time: 85
time 177ms: Process B completed a CPU burst; 20 bursts to go [Q A]
time 177ms: Process B switching out of CPU; will block on I/O until time 335ms [Q A]
time 181ms: Process A started using the CPU for 60ms burst [Q <empty>]
time 241ms: Process A completed a CPU burst; 14 bursts to go [Q <empty>]
time 241ms: Process A switching out of CPU; will block on I/O until time 396ms [Q <empty>]
time 335ms: Process B completed I/O; added to ready queue [Q B]
time 337ms: Process B started using the CPU for 198ms burst [Q <empty>]
time 396ms: Process A completed I/O; added to ready queue [Q A]
139 < 85 139 > time: 224
time 535ms: Process B completed a CPU burst; 19 bursts to go [Q A]
time 535ms: Process B switching out of CPU; will block on I/O until time 650ms [Q A]
time 539ms: Process A started using the CPU for 39ms burst [Q <empty>]
time 578ms: Process A completed a CPU burst; 13 bursts to go [Q <empty>]
time 578ms: Process A switching out of CPU; will block on I/O until time 630ms [Q <empty>]
time 630ms: Process A completed I/O; added to ready queue [Q A]
time 632ms: Process A started using the CPU for 47ms burst [Q <empty>]
time 650ms: Process B completed I/O; added to ready queue [Q B]
29 < 49 29 > time: 78
time 679ms: Process A completed a CPU burst; 12 bursts to go [Q B]
time 679ms: Process A switching out of CPU; will block on I/O until time 683ms [Q B]
time 683ms: Process B started using the CPU for 208ms burst [Q <empty>]
time 683ms: Process A completed I/O; added to ready queue [Q A]
208 < 85 139 208 > time: 432
time 891ms: Process B completed a CPU burst; 18 bursts to go [Q A]
time 891ms: Process B switching out of CPU; will block on I/O until time 1055ms [Q A]
time 895ms: Process A started using the CPU for 137ms burst [Q <empty>]
time 1032ms: Process A completed a CPU burst; 11 bursts to go [Q <empty>]
time 1032ms: Process A switching out of CPU; will block on I/O until time 1058ms [Q <empty>]
time 1055ms: Process B completed I/O; added to ready queue [Q B]
time 1057ms: Process B started using the CPU for 50ms burst [Q <empty>]
time 1058ms: Process A completed I/O; added to ready queue [Q A]
49 < 85 139 208 49 > time: 481
time 1107ms: Process B completed a CPU burst; 17 bursts to go [Q A]
time 1107ms: Process B switching out of CPU; will block on I/O until time 1155ms [Q A]
time 1111ms: Process A started using the CPU for 64ms burst [Q <empty>]
time 1155ms: Process B completed I/O; added to ready queue [Q B]
20 < 49 29 20 > time: 98
time 1175ms: Process A completed a CPU burst; 10 bursts to go [Q B]
time 1175ms: Process A switching out of CPU; will block on I/O until time 1192ms [Q B]
time 1179ms: Process B started using the CPU for 82ms burst [Q <empty>]
time 1192ms: Process A completed I/O; added to ready queue [Q A]
69 < 85 139 208 49 69 > time: 550
time 1261ms: Process B completed a CPU burst; 16 bursts to go [Q A]
time 1261ms: Process B switching out of CPU; will block on I/O until time 1279ms [Q A]
time 1265ms: Process A started using the CPU for 68ms burst [Q <empty>]
time 1279ms: Process B completed I/O; added to ready queue [Q B]
54 < 49 29 20 54 > time: 152
time 1333ms: Process A completed a CPU burst; 9 bursts to go [Q B]
time 1333ms: Process A switching out of CPU; will block on I/O until time 1399ms [Q B]
time 1337ms: Process B started using the CPU for 7ms burst [Q <empty>]
time 1344ms: Process B completed a CPU burst; 15 bursts to go [Q <empty>]
time 1344ms: Process B switching out of CPU; will block on I/O until time 1376ms [Q <empty>]
time 1376ms: Process B completed I/O; added to ready queue [Q B]
time 1378ms: Process B started using the CPU for 52ms burst [Q <empty>]
time 1399ms: Process A completed I/O; added to ready queue [Q A]
31 < 85 139 208 49 69 31 > time: 581
time 1430ms: Process B completed a CPU burst; 14 bursts to go [Q A]
time 1430ms: Process B switching out of CPU; will block on I/O until time 1444ms [Q A]
time 1434ms: Process A started using the CPU for 113ms burst [Q <empty>]
time 1444ms: Process B completed I/O; added to ready queue [Q B]
103 < 49 29 20 54 103 > time: 255
time 1547ms: Process A completed a CPU burst; 8 bursts to go [Q B]
time 1547ms: Process A switching out of CPU; will block on I/O until time 1565ms [Q B]
time 1551ms: Process B started using the CPU for 228ms burst [Q <empty>]
time 1565ms: Process A completed I/O; added to ready queue [Q A]
214 < 85 139 208 49 69 31 214 > time: 795
time 1779ms: Process B completed a CPU burst; 13 bursts to go [Q A]
time 1779ms: Process B switching out of CPU; will block on I/O until time 1858ms [Q A]
time 1783ms: Process A started using the CPU for 11ms burst [Q <empty>]
time 1794ms: Process A completed a CPU burst; 7 bursts to go [Q <empty>]
time 1794ms: Process A switching out of CPU; will block on I/O until time 1958ms [Q <empty>]
time 1858ms: Process B completed I/O; added to ready queue [Q B]
time 1860ms: Process B started using the CPU for 138ms burst [Q <empty>]
time 1958ms: Process A completed I/O; added to ready queue [Q A]
40 < 85 139 208 49 69 31 214 40 > time: 835
time 1998ms: Process B completed a CPU burst; 12 bursts to go [Q A]
time 1998ms: Process B switching out of CPU; will block on I/O until time 2082ms [Q A]
time 2002ms: Process A started using the CPU for 24ms burst [Q <empty>]
time 2026ms: Process A completed a CPU burst; 6 bursts to go [Q <empty>]
time 2026ms: Process A switching out of CPU; will block on I/O until time 2145ms [Q <empty>]
time 2082ms: Process B completed I/O; added to ready queue [Q B]
time 2084ms: Process B started using the CPU for 67ms burst [Q <empty>]
time 2145ms: Process A completed I/O; added to ready queue [Q A]
6 < 85 139 208 49 69 31 214 40 6 > time: 841
time 2151ms: Process B completed a CPU burst; 11 bursts to go [Q A]
time 2151ms: Process B switching out of CPU; will block on I/O until time 2160ms [Q A]
time 2155ms: Process A started using the CPU for 76ms burst [Q <empty>]
time 2160ms: Process B completed I/O; added to ready queue [Q B]
71 < 49 29 20 54 103 71 > time: 326
time 2231ms: Process A completed a CPU burst; 5 bursts to go [Q B]
time 2231ms: Process A switching out of CPU; will block on I/O until time 2261ms [Q B]
time 2235ms: Process B started using the CPU for 120ms burst [Q <empty>]
time 2261ms: Process A completed I/O; added to ready queue [Q A]
94 < 85 139 208 49 69 31 214 40 6 94 > time: 935
time 2355ms: Process B completed a CPU burst; 10 bursts to go [Q A]
time 2355ms: Process B switching out of CPU; will block on I/O until time 2370ms [Q A]
time 2359ms: Process A started using the CPU for 122ms burst [Q <empty>]
time 2370ms: Process B completed I/O; added to ready queue [Q B]
111 < 49 29 20 54 103 71 111 > time: 437
time 2481ms: Process A completed a CPU burst; 4 bursts to go [Q B]
time 2481ms: Process A switching out of CPU; will block on I/O until time 2516ms [Q B]
time 2485ms: Process B started using the CPU for 49ms burst [Q <empty>]
time 2516ms: Process A completed I/O; added to ready queue [Q A]
18 < 85 139 208 49 69 31 214 40 6 94 18 > time: 953
time 2534ms: Process B completed a CPU burst; 9 bursts to go [Q A]
time 2534ms: Process B switching out of CPU; will block on I/O until time 2578ms [Q A]
time 2538ms: Process A started using the CPU for 9ms burst [Q <empty>]
time 2547ms: Process A completed a CPU burst; 3 bursts to go [Q <empty>]
time 2547ms: Process A switching out of CPU; will block on I/O until time 2617ms [Q <empty>]
time 2578ms: Process B completed I/O; added to ready queue [Q B]
time 2580ms: Process B started using the CPU for 134ms burst [Q <empty>]
time 2617ms: Process A completed I/O; added to ready queue [Q A]
97 < 85 139 208 49 69 31 214 40 6 94 18 97 > time: 1050
time 2714ms: Process B completed a CPU burst; 8 bursts to go [Q A]
time 2714ms: Process B switching out of CPU; will block on I/O until time 2748ms [Q A]
time 2718ms: Process A started using the CPU for 62ms burst [Q <empty>]
time 2748ms: Process B completed I/O; added to ready queue [Q B]
32 < 49 29 20 54 103 71 111 32 > time: 469
time 2780ms: Process A completed a CPU burst; 2 bursts to go [Q B]
time 2780ms: Process A switching out of CPU; will block on I/O until time 2859ms [Q B]
time 2784ms: Process B started using the CPU for 144ms burst [Q <empty>]
time 2859ms: Process A completed I/O; added to ready queue [Q A]
69 < 85 139 208 49 69 31 214 40 6 94 18 97 69 > time: 1119
time 2928ms: Process B completed a CPU burst; 7 bursts to go [Q A]
time 2928ms: Process B switching out of CPU; will block on I/O until time 3009ms [Q A]
time 2932ms: Process A started using the CPU for 200ms burst [Q <empty>]
time 3009ms: Process B completed I/O; added to ready queue [Q B]
123 < 49 29 20 54 103 71 111 32 123 > time: 592
time 3132ms: Process A completed a CPU burst; 1 burst to go [Q B]
time 3132ms: Process A switching out of CPU; will block on I/O until time 3145ms [Q B]
time 3136ms: Process B started using the CPU for 183ms burst [Q <empty>]
time 3145ms: Process A completed I/O; added to ready queue [Q A]
174 < 85 139 208 49 69 31 214 40 6 94 18 97 69 174 > time: 1293
time 3319ms: Process B completed a CPU burst; 6 bursts to go [Q A]
time 3319ms: Process B switching out of CPU; will block on I/O until time 3327ms [Q A]
time 3323ms: Process A started using the CPU for 197ms burst [Q <empty>]
time 3327ms: Process B completed I/O; added to ready queue [Q B]
193 < 49 29 20 54 103 71 111 32 123 193 > time: 785
time 3520ms: Process A terminated [Q B]
time 3524ms: Process B started using the CPU for 219ms burst [Q <empty>]
time 3743ms: Process B completed a CPU burst; 5 bursts to go [Q <empty>]
time 3743ms: Process B switching out of CPU; will block on I/O until time 3768ms [Q <empty>]
time 3768ms: Process B completed I/O; added to ready queue [Q B]
time 3770ms: Process B started using the CPU for 64ms burst [Q <empty>]
time 3834ms: Process B completed a CPU burst; 4 bursts to go [Q <empty>]
time 3834ms: Process B switching out of CPU; will block on I/O until time 3916ms [Q <empty>]
time 3916ms: Process B completed I/O; added to ready queue [Q B]
time 3918ms: Process B started using the CPU for 33ms burst [Q <empty>]
time 3951ms: Process B completed a CPU burst; 3 bursts to go [Q <empty>]
time 3951ms: Process B switching out of CPU; will block on I/O until time 4027ms [Q <empty>]
time 4027ms: Process B completed I/O; added to ready queue [Q B]
time 4029ms: Process B started using the CPU for 63ms burst [Q <empty>]
time 4092ms: Process B completed a CPU burst; 2 bursts to go [Q <empty>]
time 4092ms: Process B switching out of CPU; will block on I/O until time 4325ms [Q <empty>]
time 4325ms: Process B completed I/O; added to ready queue [Q B]
time 4327ms: Process B started using the CPU for 170ms burst [Q <empty>]
time 4497ms: Process B completed a CPU burst; 1 burst to go [Q <empty>]
time 4497ms: Process B switching out of CPU; will block on I/O until time 4556ms [Q <empty>]
time 4556ms: Process B completed I/O; added to ready queue [Q B]
time 4558ms: Process B started using the CPU for 212ms burst [Q <empty>]
time 4770ms: Process B terminated [Q <empty>]
time 4772ms: Simulator ended for FCFS [Q <empty>]

Process A [NEW] (arrival time 9 ms) 16 CPU bursts
Process B [NEW] (arrival time 18 ms) 21 CPU bursts
time 0ms: Simulator started for FCFS [Q <empty>]
time 9ms: Process A arrived; added to ready queue [Q A]
time 11ms: Process A started using the CPU for 56ms burst [Q <empty>]
time 18ms: Process B arrived; added to ready queue [Q B]
time 67ms: Process A completed a CPU burst; 15 bursts to go [Q B]
time 67ms: Process A switching out of CPU; will block on I/O until time 92ms [Q B]
time 71ms: Process B started using the CPU for 106ms burst [Q <empty>]
time 92ms: Process A completed I/O; added to ready queue [Q A]
time 177ms: Process B completed a CPU burst; 20 bursts to go [Q A]
time 177ms: Process B switching out of CPU; will block on I/O until time 335ms [Q A]
time 181ms: Process A started using the CPU for 60ms burst [Q <empty>]
time 241ms: Process A completed a CPU burst; 14 bursts to go [Q <empty>]
time 241ms: Process A switching out of CPU; will block on I/O until time 396ms [Q <empty>]
time 335ms: Process B completed I/O; added to ready queue [Q B]
time 337ms: Process B started using the CPU for 198ms burst [Q <empty>]
time 396ms: Process A completed I/O; added to ready queue [Q A]
time 535ms: Process B completed a CPU burst; 19 bursts to go [Q A]
time 535ms: Process B switching out of CPU; will block on I/O until time 650ms [Q A]
time 539ms: Process A started using the CPU for 39ms burst [Q <empty>]
time 578ms: Process A completed a CPU burst; 13 bursts to go [Q <empty>]
time 578ms: Process A switching out of CPU; will block on I/O until time 630ms [Q <empty>]
time 630ms: Process A completed I/O; added to ready queue [Q A]
time 632ms: Process A started using the CPU for 47ms burst [Q <empty>]
time 650ms: Process B completed I/O; added to ready queue [Q B]
time 679ms: Process A completed a CPU burst; 12 bursts to go [Q B]
time 679ms: Process A switching out of CPU; will block on I/O until time 683ms [Q B]
time 683ms: Process B started using the CPU for 208ms burst [Q <empty>]
time 683ms: Process A completed I/O; added to ready queue [Q A]
time 891ms: Process B completed a CPU burst; 18 bursts to go [Q A]
time 891ms: Process B switching out of CPU; will block on I/O until time 1055ms [Q A]
time 895ms: Process A started using the CPU for 137ms burst [Q <empty>]
time 1032ms: Process A completed a CPU burst; 11 bursts to go [Q <empty>]
time 1032ms: Process A switching out of CPU; will block on I/O until time 1058ms [Q <empty>]
time 1055ms: Process B completed I/O; added to ready queue [Q B]
time 1057ms: Process B started using the CPU for 50ms burst [Q <empty>]
time 1058ms: Process A completed I/O; added to ready queue [Q A]
time 1107ms: Process B completed a CPU burst; 17 bursts to go [Q A]
time 1107ms: Process B switching out of CPU; will block on I/O until time 1155ms [Q A]
time 1111ms: Process A started using the CPU for 64ms burst [Q <empty>]
time 1155ms: Process B completed I/O; added to ready queue [Q B]
time 1175ms: Process A completed a CPU burst; 10 bursts to go [Q B]
time 1175ms: Process A switching out of CPU; will block on I/O until time 1192ms [Q B]
time 1179ms: Process B started using the CPU for 82ms burst [Q <empty>]
time 1192ms: Process A completed I/O; added to ready queue [Q A]
time 1261ms: Process B completed a CPU burst; 16 bursts to go [Q A]
time 1261ms: Process B switching out of CPU; will block on I/O until time 1279ms [Q A]
time 1265ms: Process A started using the CPU for 68ms burst [Q <empty>]
time 1279ms: Process B completed I/O; added to ready queue [Q B]
time 1333ms: Process A completed a CPU burst; 9 bursts to go [Q B]
time 1333ms: Process A switching out of CPU; will block on I/O until time 1399ms [Q B]
time 1337ms: Process B started using the CPU for 7ms burst [Q <empty>]
time 1344ms: Process B completed a CPU burst; 15 bursts to go [Q <empty>]
time 1344ms: Process B switching out of CPU; will block on I/O until time 1376ms [Q <empty>]
time 1376ms: Process B completed I/O; added to ready queue [Q B]
time 1378ms: Process B started using the CPU for 52ms burst [Q <empty>]
time 1399ms: Process A completed I/O; added to ready queue [Q A]
time 1430ms: Process B completed a CPU burst; 14 bursts to go [Q A]
time 1430ms: Process B switching out of CPU; will block on I/O until time 1444ms [Q A]
time 1434ms: Process A started using the CPU for 113ms burst [Q <empty>]
time 1444ms: Process B completed I/O; added to ready queue [Q B]
time 1547ms: Process A completed a CPU burst; 8 bursts to go [Q B]
time 1547ms: Process A switching out of CPU; will block on I/O until time 1565ms [Q B]
time 1551ms: Process B started using the CPU for 228ms burst [Q <empty>]
time 1565ms: Process A completed I/O; added to ready queue [Q A]
time 1779ms: Process B completed a CPU burst; 13 bursts to go [Q A]
time 1779ms: Process B switching out of CPU; will block on I/O until time 1858ms [Q A]
time 1783ms: Process A started using the CPU for 11ms burst [Q <empty>]
time 1794ms: Process A completed a CPU burst; 7 bursts to go [Q <empty>]
time 1794ms: Process A switching out of CPU; will block on I/O until time 1958ms [Q <empty>]
time 1858ms: Process B completed I/O; added to ready queue [Q B]
time 1860ms: Process B started using the CPU for 138ms burst [Q <empty>]
time 1958ms: Process A completed I/O; added to ready queue [Q A]
time 1998ms: Process B completed a CPU burst; 12 bursts to go [Q A]
time 1998ms: Process B switching out of CPU; will block on I/O until time 2082ms [Q A]
time 2002ms: Process A started using the CPU for 24ms burst [Q <empty>]
time 2026ms: Process A completed a CPU burst; 6 bursts to go [Q <empty>]
time 2026ms: Process A switching out of CPU; will block on I/O until time 2145ms [Q <empty>]
time 2082ms: Process B completed I/O; added to ready queue [Q B]
time 2084ms: Process B started using the CPU for 67ms burst [Q <empty>]
time 2145ms: Process A completed I/O; added to ready queue [Q A]
time 2151ms: Process B completed a CPU burst; 11 bursts to go [Q A]
time 2151ms: Process B switching out of CPU; will block on I/O until time 2160ms [Q A]
time 2155ms: Process A started using the CPU for 76ms burst [Q <empty>]
time 2160ms: Process B completed I/O; added to ready queue [Q B]
time 2231ms: Process A completed a CPU burst; 5 bursts to go [Q B]
time 2231ms: Process A switching out of CPU; will block on I/O until time 2261ms [Q B]
time 2235ms: Process B started using the CPU for 120ms burst [Q <empty>]
time 2261ms: Process A completed I/O; added to ready queue [Q A]
time 2355ms: Process B completed a CPU burst; 10 bursts to go [Q A]
time 2355ms: Process B switching out of CPU; will block on I/O until time 2370ms [Q A]
time 2359ms: Process A started using the CPU for 122ms burst [Q <empty>]
time 2370ms: Process B completed I/O; added to ready queue [Q B]
time 2481ms: Process A completed a CPU burst; 4 bursts to go [Q B]
time 2481ms: Process A switching out of CPU; will block on I/O until time 2516ms [Q B]
time 2485ms: Process B started using the CPU for 49ms burst [Q <empty>]
time 2516ms: Process A completed I/O; added to ready queue [Q A]
time 2534ms: Process B completed a CPU burst; 9 bursts to go [Q A]
time 2534ms: Process B switching out of CPU; will block on I/O until time 2578ms [Q A]
time 2538ms: Process A started using the CPU for 9ms burst [Q <empty>]
time 2547ms: Process A completed a CPU burst; 3 bursts to go [Q <empty>]
time 2547ms: Process A switching out of CPU; will block on I/O until time 2617ms [Q <empty>]
time 2578ms: Process B completed I/O; added to ready queue [Q B]
time 2580ms: Process B started using the CPU for 134ms burst [Q <empty>]
time 2617ms: Process A completed I/O; added to ready queue [Q A]
time 2714ms: Process B completed a CPU burst; 8 bursts to go [Q A]
time 2714ms: Process B switching out of CPU; will block on I/O until time 2748ms [Q A]
time 2718ms: Process A started using the CPU for 62ms burst [Q <empty>]
time 2748ms: Process B completed I/O; added to ready queue [Q B]
time 2780ms: Process A completed a CPU burst; 2 bursts to go [Q B]
time 2780ms: Process A switching out of CPU; will block on I/O until time 2859ms [Q B]
time 2784ms: Process B started using the CPU for 144ms burst [Q <empty>]
time 2859ms: Process A completed I/O; added to ready queue [Q A]
time 2928ms: Process B completed a CPU burst; 7 bursts to go [Q A]
time 2928ms: Process B switching out of CPU; will block on I/O until time 3009ms [Q A]
time 2932ms: Process A started using the CPU for 200ms burst [Q <empty>]
time 3009ms: Process B completed I/O; added to ready queue [Q B]
time 3132ms: Process A completed a CPU burst; 1 burst to go [Q B]
time 3132ms: Process A switching out of CPU; will block on I/O until time 3145ms [Q B]
time 3136ms: Process B started using the CPU for 183ms burst [Q <empty>]
time 3145ms: Process A completed I/O; added to ready queue [Q A]
time 3319ms: Process B completed a CPU burst; 6 bursts to go [Q A]
time 3319ms: Process B switching out of CPU; will block on I/O until time 3327ms [Q A]
time 3323ms: Process A started using the CPU for 197ms burst [Q <empty>]
time 3327ms: Process B completed I/O; added to ready queue [Q B]
time 3520ms: Process A terminated [Q B]
time 3524ms: Process B started using the CPU for 219ms burst [Q <empty>]
time 3743ms: Process B completed a CPU burst; 5 bursts to go [Q <empty>]
time 3743ms: Process B switching out of CPU; will block on I/O until time 3768ms [Q <empty>]
time 3768ms: Process B completed I/O; added to ready queue [Q B]
time 3770ms: Process B started using the CPU for 64ms burst [Q <empty>]
time 3834ms: Process B completed a CPU burst; 4 bursts to go [Q <empty>]
time 3834ms: Process B switching out of CPU; will block on I/O until time 3916ms [Q <empty>]
time 3916ms: Process B completed I/O; added to ready queue [Q B]
time 3918ms: Process B started using the CPU for 33ms burst [Q <empty>]
time 3951ms: Process B completed a CPU burst; 3 bursts to go [Q <empty>]
time 3951ms: Process B switching out of CPU; will block on I/O until time 4027ms [Q <empty>]
time 4027ms: Process B completed I/O; added to ready queue [Q B]
time 4029ms: Process B started using the CPU for 63ms burst [Q <empty>]
time 4092ms: Process B completed a CPU burst; 2 bursts to go [Q <empty>]
time 4092ms: Process B switching out of CPU; will block on I/O until time 4325ms [Q <empty>]
time 4325ms: Process B completed I/O; added to ready queue [Q B]
time 4327ms: Process B started using the CPU for 170ms burst [Q <empty>]
time 4497ms: Process B completed a CPU burst; 1 burst to go [Q <empty>]
time 4497ms: Process B switching out of CPU; will block on I/O until time 4556ms [Q <empty>]
time 4556ms: Process B completed I/O; added to ready queue [Q B]
time 4558ms: Process B started using the CPU for 212ms burst [Q <empty>]
time 4770ms: Process B terminated [Q <empty>]
time 4772ms: Simulator ended for FCFS [Q <empty>]

>>>>>>> e34f3dab6853b319b01dc2285e41a2ec9846f4b6
